{
 "cells": [
  {
   "cell_type": "markdown",
   "id": "ac8f130d",
   "metadata": {},
   "source": [
    "### Install Require Python Libraries"
   ]
  },
  {
   "cell_type": "code",
   "execution_count": 1,
   "id": "221e0c5c",
   "metadata": {},
   "outputs": [
    {
     "name": "stdout",
     "output_type": "stream",
     "text": [
      "Collecting streamlit (from -r requirements.txt (line 1))\n",
      "  Downloading streamlit-1.48.1-py3-none-any.whl.metadata (9.5 kB)\n",
      "Collecting pandas (from -r requirements.txt (line 2))\n",
      "  Downloading pandas-2.3.2-cp313-cp313-macosx_11_0_arm64.whl.metadata (91 kB)\n",
      "Collecting numpy (from -r requirements.txt (line 3))\n",
      "  Using cached numpy-2.3.2-cp313-cp313-macosx_14_0_arm64.whl.metadata (62 kB)\n",
      "Collecting seaborn (from -r requirements.txt (line 4))\n",
      "  Using cached seaborn-0.13.2-py3-none-any.whl.metadata (5.4 kB)\n",
      "Collecting matplotlib (from -r requirements.txt (line 5))\n",
      "  Using cached matplotlib-3.10.5-cp313-cp313-macosx_11_0_arm64.whl.metadata (11 kB)\n",
      "Collecting scikit-learn (from -r requirements.txt (line 6))\n",
      "  Using cached scikit_learn-1.7.1-cp313-cp313-macosx_12_0_arm64.whl.metadata (11 kB)\n",
      "Collecting geopy (from -r requirements.txt (line 7))\n",
      "  Using cached geopy-2.4.1-py3-none-any.whl.metadata (6.8 kB)\n",
      "Collecting xgboost (from -r requirements.txt (line 8))\n",
      "  Downloading xgboost-3.0.4-py3-none-macosx_12_0_arm64.whl.metadata (2.1 kB)\n",
      "Collecting lightgbm (from -r requirements.txt (line 9))\n",
      "  Using cached lightgbm-4.6.0-py3-none-macosx_12_0_arm64.whl.metadata (17 kB)\n",
      "Collecting catboost (from -r requirements.txt (line 10))\n",
      "  Using cached catboost-1.2.8-cp313-cp313-macosx_11_0_universal2.whl.metadata (1.4 kB)\n",
      "Collecting requests (from -r requirements.txt (line 11))\n",
      "  Downloading requests-2.32.5-py3-none-any.whl.metadata (4.9 kB)\n",
      "Collecting altair!=5.4.0,!=5.4.1,<6,>=4.0 (from streamlit->-r requirements.txt (line 1))\n",
      "  Using cached altair-5.5.0-py3-none-any.whl.metadata (11 kB)\n",
      "Collecting blinker<2,>=1.5.0 (from streamlit->-r requirements.txt (line 1))\n",
      "  Using cached blinker-1.9.0-py3-none-any.whl.metadata (1.6 kB)\n",
      "Collecting cachetools<7,>=4.0 (from streamlit->-r requirements.txt (line 1))\n",
      "  Using cached cachetools-6.1.0-py3-none-any.whl.metadata (5.4 kB)\n",
      "Collecting click<9,>=7.0 (from streamlit->-r requirements.txt (line 1))\n",
      "  Using cached click-8.2.1-py3-none-any.whl.metadata (2.5 kB)\n",
      "Requirement already satisfied: packaging<26,>=20 in ./pehenv/lib/python3.13/site-packages (from streamlit->-r requirements.txt (line 1)) (25.0)\n",
      "Collecting pillow<12,>=7.1.0 (from streamlit->-r requirements.txt (line 1))\n",
      "  Using cached pillow-11.3.0-cp313-cp313-macosx_11_0_arm64.whl.metadata (9.0 kB)\n",
      "Collecting protobuf<7,>=3.20 (from streamlit->-r requirements.txt (line 1))\n",
      "  Downloading protobuf-6.32.0-cp39-abi3-macosx_10_9_universal2.whl.metadata (593 bytes)\n",
      "Collecting pyarrow>=7.0 (from streamlit->-r requirements.txt (line 1))\n",
      "  Using cached pyarrow-21.0.0-cp313-cp313-macosx_12_0_arm64.whl.metadata (3.3 kB)\n",
      "Collecting tenacity<10,>=8.1.0 (from streamlit->-r requirements.txt (line 1))\n",
      "  Using cached tenacity-9.1.2-py3-none-any.whl.metadata (1.2 kB)\n",
      "Collecting toml<2,>=0.10.1 (from streamlit->-r requirements.txt (line 1))\n",
      "  Using cached toml-0.10.2-py2.py3-none-any.whl.metadata (7.1 kB)\n",
      "Collecting typing-extensions<5,>=4.4.0 (from streamlit->-r requirements.txt (line 1))\n",
      "  Using cached typing_extensions-4.14.1-py3-none-any.whl.metadata (3.0 kB)\n",
      "Collecting gitpython!=3.1.19,<4,>=3.0.7 (from streamlit->-r requirements.txt (line 1))\n",
      "  Using cached gitpython-3.1.45-py3-none-any.whl.metadata (13 kB)\n",
      "Collecting pydeck<1,>=0.8.0b4 (from streamlit->-r requirements.txt (line 1))\n",
      "  Using cached pydeck-0.9.1-py2.py3-none-any.whl.metadata (4.1 kB)\n",
      "Requirement already satisfied: tornado!=6.5.0,<7,>=6.0.3 in ./pehenv/lib/python3.13/site-packages (from streamlit->-r requirements.txt (line 1)) (6.5.2)\n",
      "Requirement already satisfied: python-dateutil>=2.8.2 in ./pehenv/lib/python3.13/site-packages (from pandas->-r requirements.txt (line 2)) (2.9.0.post0)\n",
      "Collecting pytz>=2020.1 (from pandas->-r requirements.txt (line 2))\n",
      "  Using cached pytz-2025.2-py2.py3-none-any.whl.metadata (22 kB)\n",
      "Collecting tzdata>=2022.7 (from pandas->-r requirements.txt (line 2))\n",
      "  Using cached tzdata-2025.2-py2.py3-none-any.whl.metadata (1.4 kB)\n",
      "Collecting contourpy>=1.0.1 (from matplotlib->-r requirements.txt (line 5))\n",
      "  Using cached contourpy-1.3.3-cp313-cp313-macosx_11_0_arm64.whl.metadata (5.5 kB)\n",
      "Collecting cycler>=0.10 (from matplotlib->-r requirements.txt (line 5))\n",
      "  Using cached cycler-0.12.1-py3-none-any.whl.metadata (3.8 kB)\n",
      "Collecting fonttools>=4.22.0 (from matplotlib->-r requirements.txt (line 5))\n",
      "  Downloading fonttools-4.59.1-cp313-cp313-macosx_10_13_universal2.whl.metadata (108 kB)\n",
      "Collecting kiwisolver>=1.3.1 (from matplotlib->-r requirements.txt (line 5))\n",
      "  Downloading kiwisolver-1.4.9-cp313-cp313-macosx_11_0_arm64.whl.metadata (6.3 kB)\n",
      "Collecting pyparsing>=2.3.1 (from matplotlib->-r requirements.txt (line 5))\n",
      "  Using cached pyparsing-3.2.3-py3-none-any.whl.metadata (5.0 kB)\n",
      "Collecting scipy>=1.8.0 (from scikit-learn->-r requirements.txt (line 6))\n",
      "  Using cached scipy-1.16.1-cp313-cp313-macosx_14_0_arm64.whl.metadata (61 kB)\n",
      "Collecting joblib>=1.2.0 (from scikit-learn->-r requirements.txt (line 6))\n",
      "  Using cached joblib-1.5.1-py3-none-any.whl.metadata (5.6 kB)\n",
      "Collecting threadpoolctl>=3.1.0 (from scikit-learn->-r requirements.txt (line 6))\n",
      "  Using cached threadpoolctl-3.6.0-py3-none-any.whl.metadata (13 kB)\n",
      "Collecting geographiclib<3,>=1.52 (from geopy->-r requirements.txt (line 7))\n",
      "  Using cached geographiclib-2.0-py3-none-any.whl.metadata (1.4 kB)\n",
      "Collecting graphviz (from catboost->-r requirements.txt (line 10))\n",
      "  Using cached graphviz-0.21-py3-none-any.whl.metadata (12 kB)\n",
      "Collecting plotly (from catboost->-r requirements.txt (line 10))\n",
      "  Downloading plotly-6.3.0-py3-none-any.whl.metadata (8.5 kB)\n",
      "Requirement already satisfied: six in ./pehenv/lib/python3.13/site-packages (from catboost->-r requirements.txt (line 10)) (1.17.0)\n",
      "Collecting charset_normalizer<4,>=2 (from requests->-r requirements.txt (line 11))\n",
      "  Downloading charset_normalizer-3.4.3-cp313-cp313-macosx_10_13_universal2.whl.metadata (36 kB)\n",
      "Collecting idna<4,>=2.5 (from requests->-r requirements.txt (line 11))\n",
      "  Using cached idna-3.10-py3-none-any.whl.metadata (10 kB)\n",
      "Collecting urllib3<3,>=1.21.1 (from requests->-r requirements.txt (line 11))\n",
      "  Using cached urllib3-2.5.0-py3-none-any.whl.metadata (6.5 kB)\n",
      "Collecting certifi>=2017.4.17 (from requests->-r requirements.txt (line 11))\n",
      "  Using cached certifi-2025.8.3-py3-none-any.whl.metadata (2.4 kB)\n",
      "Collecting jinja2 (from altair!=5.4.0,!=5.4.1,<6,>=4.0->streamlit->-r requirements.txt (line 1))\n",
      "  Using cached jinja2-3.1.6-py3-none-any.whl.metadata (2.9 kB)\n",
      "Collecting jsonschema>=3.0 (from altair!=5.4.0,!=5.4.1,<6,>=4.0->streamlit->-r requirements.txt (line 1))\n",
      "  Downloading jsonschema-4.25.1-py3-none-any.whl.metadata (7.6 kB)\n",
      "Collecting narwhals>=1.14.2 (from altair!=5.4.0,!=5.4.1,<6,>=4.0->streamlit->-r requirements.txt (line 1))\n",
      "  Downloading narwhals-2.1.2-py3-none-any.whl.metadata (11 kB)\n",
      "Collecting gitdb<5,>=4.0.1 (from gitpython!=3.1.19,<4,>=3.0.7->streamlit->-r requirements.txt (line 1))\n",
      "  Using cached gitdb-4.0.12-py3-none-any.whl.metadata (1.2 kB)\n",
      "Collecting smmap<6,>=3.0.1 (from gitdb<5,>=4.0.1->gitpython!=3.1.19,<4,>=3.0.7->streamlit->-r requirements.txt (line 1))\n",
      "  Using cached smmap-5.0.2-py3-none-any.whl.metadata (4.3 kB)\n",
      "Collecting MarkupSafe>=2.0 (from jinja2->altair!=5.4.0,!=5.4.1,<6,>=4.0->streamlit->-r requirements.txt (line 1))\n",
      "  Using cached MarkupSafe-3.0.2-cp313-cp313-macosx_11_0_arm64.whl.metadata (4.0 kB)\n",
      "Collecting attrs>=22.2.0 (from jsonschema>=3.0->altair!=5.4.0,!=5.4.1,<6,>=4.0->streamlit->-r requirements.txt (line 1))\n",
      "  Using cached attrs-25.3.0-py3-none-any.whl.metadata (10 kB)\n",
      "Collecting jsonschema-specifications>=2023.03.6 (from jsonschema>=3.0->altair!=5.4.0,!=5.4.1,<6,>=4.0->streamlit->-r requirements.txt (line 1))\n",
      "  Using cached jsonschema_specifications-2025.4.1-py3-none-any.whl.metadata (2.9 kB)\n",
      "Collecting referencing>=0.28.4 (from jsonschema>=3.0->altair!=5.4.0,!=5.4.1,<6,>=4.0->streamlit->-r requirements.txt (line 1))\n",
      "  Using cached referencing-0.36.2-py3-none-any.whl.metadata (2.8 kB)\n",
      "Collecting rpds-py>=0.7.1 (from jsonschema>=3.0->altair!=5.4.0,!=5.4.1,<6,>=4.0->streamlit->-r requirements.txt (line 1))\n",
      "  Using cached rpds_py-0.27.0-cp313-cp313-macosx_11_0_arm64.whl.metadata (4.2 kB)\n",
      "Downloading streamlit-1.48.1-py3-none-any.whl (9.9 MB)\n",
      "\u001b[2K   \u001b[90m━━━━━━━━━━━━━━━━━━━━━━━━━━━━━━━━━━━━━━━━\u001b[0m \u001b[32m9.9/9.9 MB\u001b[0m \u001b[31m29.6 MB/s\u001b[0m eta \u001b[36m0:00:00\u001b[0ma \u001b[36m0:00:01\u001b[0m\n",
      "\u001b[?25hDownloading pandas-2.3.2-cp313-cp313-macosx_11_0_arm64.whl (10.7 MB)\n",
      "\u001b[2K   \u001b[90m━━━━━━━━━━━━━━━━━━━━━━━━━━━━━━━━━━━━━━━━\u001b[0m \u001b[32m10.7/10.7 MB\u001b[0m \u001b[31m29.2 MB/s\u001b[0m eta \u001b[36m0:00:00\u001b[0m \u001b[36m0:00:01\u001b[0m\n",
      "\u001b[?25hUsing cached numpy-2.3.2-cp313-cp313-macosx_14_0_arm64.whl (5.1 MB)\n",
      "Using cached seaborn-0.13.2-py3-none-any.whl (294 kB)\n",
      "Using cached matplotlib-3.10.5-cp313-cp313-macosx_11_0_arm64.whl (8.1 MB)\n",
      "Using cached scikit_learn-1.7.1-cp313-cp313-macosx_12_0_arm64.whl (8.6 MB)\n",
      "Using cached geopy-2.4.1-py3-none-any.whl (125 kB)\n",
      "Downloading xgboost-3.0.4-py3-none-macosx_12_0_arm64.whl (2.0 MB)\n",
      "\u001b[2K   \u001b[90m━━━━━━━━━━━━━━━━━━━━━━━━━━━━━━━━━━━━━━━━\u001b[0m \u001b[32m2.0/2.0 MB\u001b[0m \u001b[31m23.9 MB/s\u001b[0m eta \u001b[36m0:00:00\u001b[0m\n",
      "\u001b[?25hUsing cached lightgbm-4.6.0-py3-none-macosx_12_0_arm64.whl (1.6 MB)\n",
      "Using cached catboost-1.2.8-cp313-cp313-macosx_11_0_universal2.whl (27.8 MB)\n",
      "Downloading requests-2.32.5-py3-none-any.whl (64 kB)\n",
      "Using cached altair-5.5.0-py3-none-any.whl (731 kB)\n",
      "Using cached blinker-1.9.0-py3-none-any.whl (8.5 kB)\n",
      "Using cached cachetools-6.1.0-py3-none-any.whl (11 kB)\n",
      "Using cached certifi-2025.8.3-py3-none-any.whl (161 kB)\n",
      "Downloading charset_normalizer-3.4.3-cp313-cp313-macosx_10_13_universal2.whl (205 kB)\n",
      "Using cached click-8.2.1-py3-none-any.whl (102 kB)\n",
      "Using cached contourpy-1.3.3-cp313-cp313-macosx_11_0_arm64.whl (274 kB)\n",
      "Using cached cycler-0.12.1-py3-none-any.whl (8.3 kB)\n",
      "Downloading fonttools-4.59.1-cp313-cp313-macosx_10_13_universal2.whl (2.8 MB)\n",
      "\u001b[2K   \u001b[90m━━━━━━━━━━━━━━━━━━━━━━━━━━━━━━━━━━━━━━━━\u001b[0m \u001b[32m2.8/2.8 MB\u001b[0m \u001b[31m28.4 MB/s\u001b[0m eta \u001b[36m0:00:00\u001b[0m\n",
      "\u001b[?25hUsing cached geographiclib-2.0-py3-none-any.whl (40 kB)\n",
      "Using cached gitpython-3.1.45-py3-none-any.whl (208 kB)\n",
      "Using cached idna-3.10-py3-none-any.whl (70 kB)\n",
      "Using cached joblib-1.5.1-py3-none-any.whl (307 kB)\n",
      "Downloading kiwisolver-1.4.9-cp313-cp313-macosx_11_0_arm64.whl (64 kB)\n",
      "Using cached pillow-11.3.0-cp313-cp313-macosx_11_0_arm64.whl (4.7 MB)\n",
      "Downloading protobuf-6.32.0-cp39-abi3-macosx_10_9_universal2.whl (426 kB)\n",
      "Using cached pyarrow-21.0.0-cp313-cp313-macosx_12_0_arm64.whl (31.2 MB)\n",
      "Using cached pydeck-0.9.1-py2.py3-none-any.whl (6.9 MB)\n",
      "Using cached pyparsing-3.2.3-py3-none-any.whl (111 kB)\n",
      "Using cached pytz-2025.2-py2.py3-none-any.whl (509 kB)\n",
      "Using cached scipy-1.16.1-cp313-cp313-macosx_14_0_arm64.whl (20.8 MB)\n",
      "Using cached tenacity-9.1.2-py3-none-any.whl (28 kB)\n",
      "Using cached threadpoolctl-3.6.0-py3-none-any.whl (18 kB)\n",
      "Using cached toml-0.10.2-py2.py3-none-any.whl (16 kB)\n",
      "Using cached typing_extensions-4.14.1-py3-none-any.whl (43 kB)\n",
      "Using cached tzdata-2025.2-py2.py3-none-any.whl (347 kB)\n",
      "Using cached urllib3-2.5.0-py3-none-any.whl (129 kB)\n",
      "Using cached graphviz-0.21-py3-none-any.whl (47 kB)\n",
      "Downloading plotly-6.3.0-py3-none-any.whl (9.8 MB)\n",
      "\u001b[2K   \u001b[90m━━━━━━━━━━━━━━━━━━━━━━━━━━━━━━━━━━━━━━━━\u001b[0m \u001b[32m9.8/9.8 MB\u001b[0m \u001b[31m29.2 MB/s\u001b[0m eta \u001b[36m0:00:00\u001b[0ma \u001b[36m0:00:01\u001b[0m\n",
      "\u001b[?25hUsing cached gitdb-4.0.12-py3-none-any.whl (62 kB)\n",
      "Using cached jinja2-3.1.6-py3-none-any.whl (134 kB)\n",
      "Downloading jsonschema-4.25.1-py3-none-any.whl (90 kB)\n",
      "Downloading narwhals-2.1.2-py3-none-any.whl (392 kB)\n",
      "Using cached attrs-25.3.0-py3-none-any.whl (63 kB)\n",
      "Using cached jsonschema_specifications-2025.4.1-py3-none-any.whl (18 kB)\n",
      "Using cached MarkupSafe-3.0.2-cp313-cp313-macosx_11_0_arm64.whl (12 kB)\n",
      "Using cached referencing-0.36.2-py3-none-any.whl (26 kB)\n",
      "Using cached rpds_py-0.27.0-cp313-cp313-macosx_11_0_arm64.whl (347 kB)\n",
      "Using cached smmap-5.0.2-py3-none-any.whl (24 kB)\n",
      "Installing collected packages: pytz, urllib3, tzdata, typing-extensions, toml, threadpoolctl, tenacity, smmap, rpds-py, pyparsing, pyarrow, protobuf, pillow, numpy, narwhals, MarkupSafe, kiwisolver, joblib, idna, graphviz, geographiclib, fonttools, cycler, click, charset_normalizer, certifi, cachetools, blinker, attrs, scipy, requests, referencing, plotly, pandas, jinja2, gitdb, geopy, contourpy, xgboost, scikit-learn, pydeck, matplotlib, lightgbm, jsonschema-specifications, gitpython, seaborn, jsonschema, catboost, altair, streamlit\n",
      "Successfully installed MarkupSafe-3.0.2 altair-5.5.0 attrs-25.3.0 blinker-1.9.0 cachetools-6.1.0 catboost-1.2.8 certifi-2025.8.3 charset_normalizer-3.4.3 click-8.2.1 contourpy-1.3.3 cycler-0.12.1 fonttools-4.59.1 geographiclib-2.0 geopy-2.4.1 gitdb-4.0.12 gitpython-3.1.45 graphviz-0.21 idna-3.10 jinja2-3.1.6 joblib-1.5.1 jsonschema-4.25.1 jsonschema-specifications-2025.4.1 kiwisolver-1.4.9 lightgbm-4.6.0 matplotlib-3.10.5 narwhals-2.1.2 numpy-2.3.2 pandas-2.3.2 pillow-11.3.0 plotly-6.3.0 protobuf-6.32.0 pyarrow-21.0.0 pydeck-0.9.1 pyparsing-3.2.3 pytz-2025.2 referencing-0.36.2 requests-2.32.5 rpds-py-0.27.0 scikit-learn-1.7.1 scipy-1.16.1 seaborn-0.13.2 smmap-5.0.2 streamlit-1.48.1 tenacity-9.1.2 threadpoolctl-3.6.0 toml-0.10.2 typing-extensions-4.14.1 tzdata-2025.2 urllib3-2.5.0 xgboost-3.0.4\n",
      "\n",
      "\u001b[1m[\u001b[0m\u001b[34;49mnotice\u001b[0m\u001b[1;39;49m]\u001b[0m\u001b[39;49m A new release of pip is available: \u001b[0m\u001b[31;49m25.0.1\u001b[0m\u001b[39;49m -> \u001b[0m\u001b[32;49m25.2\u001b[0m\n",
      "\u001b[1m[\u001b[0m\u001b[34;49mnotice\u001b[0m\u001b[1;39;49m]\u001b[0m\u001b[39;49m To update, run: \u001b[0m\u001b[32;49mpip install --upgrade pip\u001b[0m\n"
     ]
    }
   ],
   "source": [
    "!pip install -r requirements.txt"
   ]
  },
  {
   "cell_type": "markdown",
   "id": "7eb72f61",
   "metadata": {},
   "source": [
    "### Run the App"
   ]
  },
  {
   "cell_type": "code",
   "execution_count": 3,
   "id": "99ee3f47",
   "metadata": {},
   "outputs": [
    {
     "name": "stdout",
     "output_type": "stream",
     "text": [
      "\u001b[0m\n",
      "\u001b[34m\u001b[1m  You can now view your Streamlit app in your browser.\u001b[0m\n",
      "\u001b[0m\n",
      "\u001b[34m  Local URL: \u001b[0m\u001b[1mhttp://localhost:8501\u001b[0m\n",
      "\u001b[34m  Network URL: \u001b[0m\u001b[1mhttp://192.168.1.157:8501\u001b[0m\n",
      "\u001b[0m\n",
      "\u001b[34m\u001b[1m  For better performance, install the Watchdog module:\u001b[0m\n",
      "\n",
      "  $ xcode-select --install\n",
      "  $ pip install watchdog\n",
      "            \u001b[0m\n",
      "\u001b[1G\u001b[0K⠙\u001b[1G\u001b[0K⠹\u001b[1G\u001b[0K⠸\u001b[1G\u001b[0K⠼\u001b[1G\u001b[0K⠴\u001b[1G\u001b[0Kyour url is: https://fuzzy-goats-melt.loca.lt\n",
      "2025-08-21 10:41:13.784 Uncaught app execution\n",
      "Traceback (most recent call last):\n",
      "  File \"/Users/nayzawlin/Desktop/langara/ARC/PEH/PEH-cohort/pehenv/lib/python3.13/site-packages/streamlit/runtime/scriptrunner/exec_code.py\", line 128, in exec_func_with_error_handling\n",
      "    result = func()\n",
      "  File \"/Users/nayzawlin/Desktop/langara/ARC/PEH/PEH-cohort/pehenv/lib/python3.13/site-packages/streamlit/runtime/scriptrunner/script_runner.py\", line 669, in code_to_exec\n",
      "    exec(code, module.__dict__)  # noqa: S102\n",
      "    ~~~~^^^^^^^^^^^^^^^^^^^^^^^\n",
      "  File \"/Users/nayzawlin/Desktop/langara/ARC/PEH/PEH-cohort/bc_addresses_analysis.py\", line 422, in <module>\n",
      "    df[\"fullAddress\"] = df_tmp.fillna(\"\").agg(lambda x: \", \".join([v for v in x if v]), axis=1).str.strip()\n",
      "                        ^^^^^^^^^^^^^^^^^^^^^^^^^^^^^^^^^^^^^^^^^^^^^^^^^^^^^^^^^^^^^^^^^^^^^^^^^^^\n",
      "  File \"/Users/nayzawlin/Desktop/langara/ARC/PEH/PEH-cohort/pehenv/lib/python3.13/site-packages/pandas/core/generic.py\", line 6318, in __getattr__\n",
      "    return object.__getattribute__(self, name)\n",
      "           ~~~~~~~~~~~~~~~~~~~~~~~^^^^^^^^^^^^\n",
      "  File \"/Users/nayzawlin/Desktop/langara/ARC/PEH/PEH-cohort/pehenv/lib/python3.13/site-packages/pandas/core/accessor.py\", line 224, in __get__\n",
      "    accessor_obj = self._accessor(obj)\n",
      "  File \"/Users/nayzawlin/Desktop/langara/ARC/PEH/PEH-cohort/pehenv/lib/python3.13/site-packages/pandas/core/strings/accessor.py\", line 194, in __init__\n",
      "    self._inferred_dtype = self._validate(data)\n",
      "                           ~~~~~~~~~~~~~~^^^^^^\n",
      "  File \"/Users/nayzawlin/Desktop/langara/ARC/PEH/PEH-cohort/pehenv/lib/python3.13/site-packages/pandas/core/strings/accessor.py\", line 248, in _validate\n",
      "    raise AttributeError(\"Can only use .str accessor with string values!\")\n",
      "AttributeError: Can only use .str accessor with string values!. Did you mean: 'std'?\n",
      "2025-08-21 11:19:19.653 Uncaught app execution\n",
      "Traceback (most recent call last):\n",
      "  File \"/Users/nayzawlin/Desktop/langara/ARC/PEH/PEH-cohort/pehenv/lib/python3.13/site-packages/streamlit/runtime/scriptrunner/exec_code.py\", line 128, in exec_func_with_error_handling\n",
      "    result = func()\n",
      "  File \"/Users/nayzawlin/Desktop/langara/ARC/PEH/PEH-cohort/pehenv/lib/python3.13/site-packages/streamlit/runtime/scriptrunner/script_runner.py\", line 669, in code_to_exec\n",
      "    exec(code, module.__dict__)  # noqa: S102\n",
      "    ~~~~^^^^^^^^^^^^^^^^^^^^^^^\n",
      "  File \"/Users/nayzawlin/Desktop/langara/ARC/PEH/PEH-cohort/bc_addresses_analysis.py\", line 413, in <module>\n",
      "    st.dataframe(final_df.head())\n",
      "    ~~~~~~~~~~~~^^^^^^^^^^^^^^^^^\n",
      "  File \"/Users/nayzawlin/Desktop/langara/ARC/PEH/PEH-cohort/pehenv/lib/python3.13/site-packages/streamlit/runtime/metrics_util.py\", line 443, in wrapped_func\n",
      "    result = non_optional_func(*args, **kwargs)\n",
      "  File \"/Users/nayzawlin/Desktop/langara/ARC/PEH/PEH-cohort/pehenv/lib/python3.13/site-packages/streamlit/elements/arrow.py\", line 624, in dataframe\n",
      "    proto.data = dataframe_util.convert_pandas_df_to_arrow_bytes(data_df)\n",
      "                 ~~~~~~~~~~~~~~~~~~~~~~~~~~~~~~~~~~~~~~~~~~~~~~~^^^^^^^^^\n",
      "  File \"/Users/nayzawlin/Desktop/langara/ARC/PEH/PEH-cohort/pehenv/lib/python3.13/site-packages/streamlit/dataframe_util.py\", line 821, in convert_pandas_df_to_arrow_bytes\n",
      "    table = pa.Table.from_pandas(df)\n",
      "  File \"pyarrow/table.pxi\", line 4795, in pyarrow.lib.Table.from_pandas\n",
      "  File \"/Users/nayzawlin/Desktop/langara/ARC/PEH/PEH-cohort/pehenv/lib/python3.13/site-packages/pyarrow/pandas_compat.py\", line 594, in dataframe_to_arrays\n",
      "    convert_fields) = _get_columns_to_convert(df, schema, preserve_index,\n",
      "                      ~~~~~~~~~~~~~~~~~~~~~~~^^^^^^^^^^^^^^^^^^^^^^^^^^^^\n",
      "                                              columns)\n",
      "                                              ^^^^^^^^\n",
      "  File \"/Users/nayzawlin/Desktop/langara/ARC/PEH/PEH-cohort/pehenv/lib/python3.13/site-packages/pyarrow/pandas_compat.py\", line 374, in _get_columns_to_convert\n",
      "    raise ValueError(\n",
      "        f'Duplicate column names found: {list(df.columns)}'\n",
      "    )\n",
      "ValueError: Duplicate column names found: ['ClientID', 'PostalCode', 'City', 'StreetAddress1', 'StreetAddress2', 'SubBuilding', 'BuildingNumber', 'Street', 'StreetType', 'CityName', 'ProvinceCode', 'PostalCode', 'CountryName']\n",
      "2025-08-21 11:21:09.022 Uncaught app execution\n",
      "Traceback (most recent call last):\n",
      "  File \"/Users/nayzawlin/Desktop/langara/ARC/PEH/PEH-cohort/pehenv/lib/python3.13/site-packages/streamlit/runtime/scriptrunner/exec_code.py\", line 128, in exec_func_with_error_handling\n",
      "    result = func()\n",
      "  File \"/Users/nayzawlin/Desktop/langara/ARC/PEH/PEH-cohort/pehenv/lib/python3.13/site-packages/streamlit/runtime/scriptrunner/script_runner.py\", line 669, in code_to_exec\n",
      "    exec(code, module.__dict__)  # noqa: S102\n",
      "    ~~~~^^^^^^^^^^^^^^^^^^^^^^^\n",
      "  File \"/Users/nayzawlin/Desktop/langara/ARC/PEH/PEH-cohort/bc_addresses_analysis.py\", line 413, in <module>\n",
      "    st.dataframe(final_df.head())\n",
      "    ~~~~~~~~~~~~^^^^^^^^^^^^^^^^^\n",
      "  File \"/Users/nayzawlin/Desktop/langara/ARC/PEH/PEH-cohort/pehenv/lib/python3.13/site-packages/streamlit/runtime/metrics_util.py\", line 443, in wrapped_func\n",
      "    result = non_optional_func(*args, **kwargs)\n",
      "  File \"/Users/nayzawlin/Desktop/langara/ARC/PEH/PEH-cohort/pehenv/lib/python3.13/site-packages/streamlit/elements/arrow.py\", line 624, in dataframe\n",
      "    proto.data = dataframe_util.convert_pandas_df_to_arrow_bytes(data_df)\n",
      "                 ~~~~~~~~~~~~~~~~~~~~~~~~~~~~~~~~~~~~~~~~~~~~~~~^^^^^^^^^\n",
      "  File \"/Users/nayzawlin/Desktop/langara/ARC/PEH/PEH-cohort/pehenv/lib/python3.13/site-packages/streamlit/dataframe_util.py\", line 821, in convert_pandas_df_to_arrow_bytes\n",
      "    table = pa.Table.from_pandas(df)\n",
      "  File \"pyarrow/table.pxi\", line 4795, in pyarrow.lib.Table.from_pandas\n",
      "  File \"/Users/nayzawlin/Desktop/langara/ARC/PEH/PEH-cohort/pehenv/lib/python3.13/site-packages/pyarrow/pandas_compat.py\", line 594, in dataframe_to_arrays\n",
      "    convert_fields) = _get_columns_to_convert(df, schema, preserve_index,\n",
      "                      ~~~~~~~~~~~~~~~~~~~~~~~^^^^^^^^^^^^^^^^^^^^^^^^^^^^\n",
      "                                              columns)\n",
      "                                              ^^^^^^^^\n",
      "  File \"/Users/nayzawlin/Desktop/langara/ARC/PEH/PEH-cohort/pehenv/lib/python3.13/site-packages/pyarrow/pandas_compat.py\", line 374, in _get_columns_to_convert\n",
      "    raise ValueError(\n",
      "        f'Duplicate column names found: {list(df.columns)}'\n",
      "    )\n",
      "ValueError: Duplicate column names found: ['ClientID', 'PostalCode', 'City', 'StreetAddress1', 'StreetAddress2', 'SubBuilding', 'BuildingNumber', 'Street', 'StreetType', 'CityName', 'ProvinceCode', 'PostalCode', 'CountryName']\n",
      "2025-08-21 11:22:58.472 Uncaught app execution\n",
      "Traceback (most recent call last):\n",
      "  File \"/Users/nayzawlin/Desktop/langara/ARC/PEH/PEH-cohort/pehenv/lib/python3.13/site-packages/streamlit/runtime/scriptrunner/exec_code.py\", line 128, in exec_func_with_error_handling\n",
      "    result = func()\n",
      "  File \"/Users/nayzawlin/Desktop/langara/ARC/PEH/PEH-cohort/pehenv/lib/python3.13/site-packages/streamlit/runtime/scriptrunner/script_runner.py\", line 669, in code_to_exec\n",
      "    exec(code, module.__dict__)  # noqa: S102\n",
      "    ~~~~^^^^^^^^^^^^^^^^^^^^^^^\n",
      "  File \"/Users/nayzawlin/Desktop/langara/ARC/PEH/PEH-cohort/bc_addresses_analysis.py\", line 413, in <module>\n",
      "    st.dataframe(final_df.head())\n",
      "    ~~~~~~~~~~~~^^^^^^^^^^^^^^^^^\n",
      "  File \"/Users/nayzawlin/Desktop/langara/ARC/PEH/PEH-cohort/pehenv/lib/python3.13/site-packages/streamlit/runtime/metrics_util.py\", line 443, in wrapped_func\n",
      "    result = non_optional_func(*args, **kwargs)\n",
      "  File \"/Users/nayzawlin/Desktop/langara/ARC/PEH/PEH-cohort/pehenv/lib/python3.13/site-packages/streamlit/elements/arrow.py\", line 624, in dataframe\n",
      "    proto.data = dataframe_util.convert_pandas_df_to_arrow_bytes(data_df)\n",
      "                 ~~~~~~~~~~~~~~~~~~~~~~~~~~~~~~~~~~~~~~~~~~~~~~~^^^^^^^^^\n",
      "  File \"/Users/nayzawlin/Desktop/langara/ARC/PEH/PEH-cohort/pehenv/lib/python3.13/site-packages/streamlit/dataframe_util.py\", line 821, in convert_pandas_df_to_arrow_bytes\n",
      "    table = pa.Table.from_pandas(df)\n",
      "  File \"pyarrow/table.pxi\", line 4795, in pyarrow.lib.Table.from_pandas\n",
      "  File \"/Users/nayzawlin/Desktop/langara/ARC/PEH/PEH-cohort/pehenv/lib/python3.13/site-packages/pyarrow/pandas_compat.py\", line 594, in dataframe_to_arrays\n",
      "    convert_fields) = _get_columns_to_convert(df, schema, preserve_index,\n",
      "                      ~~~~~~~~~~~~~~~~~~~~~~~^^^^^^^^^^^^^^^^^^^^^^^^^^^^\n",
      "                                              columns)\n",
      "                                              ^^^^^^^^\n",
      "  File \"/Users/nayzawlin/Desktop/langara/ARC/PEH/PEH-cohort/pehenv/lib/python3.13/site-packages/pyarrow/pandas_compat.py\", line 374, in _get_columns_to_convert\n",
      "    raise ValueError(\n",
      "        f'Duplicate column names found: {list(df.columns)}'\n",
      "    )\n",
      "ValueError: Duplicate column names found: ['ClientID', 'PostalCode', 'City', 'StreetAddress1', 'StreetAddress2', 'SubBuilding', 'BuildingNumber', 'Street', 'StreetType', 'CityName', 'ProvinceCode', 'PostalCode', 'CountryName']\n",
      "2025-08-21 11:23:32.857 Uncaught app execution\n",
      "Traceback (most recent call last):\n",
      "  File \"/Users/nayzawlin/Desktop/langara/ARC/PEH/PEH-cohort/pehenv/lib/python3.13/site-packages/streamlit/runtime/scriptrunner/exec_code.py\", line 128, in exec_func_with_error_handling\n",
      "    result = func()\n",
      "  File \"/Users/nayzawlin/Desktop/langara/ARC/PEH/PEH-cohort/pehenv/lib/python3.13/site-packages/streamlit/runtime/scriptrunner/script_runner.py\", line 669, in code_to_exec\n",
      "    exec(code, module.__dict__)  # noqa: S102\n",
      "    ~~~~^^^^^^^^^^^^^^^^^^^^^^^\n",
      "  File \"/Users/nayzawlin/Desktop/langara/ARC/PEH/PEH-cohort/bc_addresses_analysis.py\", line 413, in <module>\n",
      "    st.dataframe(final_df.head())\n",
      "    ~~~~~~~~~~~~^^^^^^^^^^^^^^^^^\n",
      "  File \"/Users/nayzawlin/Desktop/langara/ARC/PEH/PEH-cohort/pehenv/lib/python3.13/site-packages/streamlit/runtime/metrics_util.py\", line 443, in wrapped_func\n",
      "    result = non_optional_func(*args, **kwargs)\n",
      "  File \"/Users/nayzawlin/Desktop/langara/ARC/PEH/PEH-cohort/pehenv/lib/python3.13/site-packages/streamlit/elements/arrow.py\", line 624, in dataframe\n",
      "    proto.data = dataframe_util.convert_pandas_df_to_arrow_bytes(data_df)\n",
      "                 ~~~~~~~~~~~~~~~~~~~~~~~~~~~~~~~~~~~~~~~~~~~~~~~^^^^^^^^^\n",
      "  File \"/Users/nayzawlin/Desktop/langara/ARC/PEH/PEH-cohort/pehenv/lib/python3.13/site-packages/streamlit/dataframe_util.py\", line 821, in convert_pandas_df_to_arrow_bytes\n",
      "    table = pa.Table.from_pandas(df)\n",
      "  File \"pyarrow/table.pxi\", line 4795, in pyarrow.lib.Table.from_pandas\n",
      "  File \"/Users/nayzawlin/Desktop/langara/ARC/PEH/PEH-cohort/pehenv/lib/python3.13/site-packages/pyarrow/pandas_compat.py\", line 594, in dataframe_to_arrays\n",
      "    convert_fields) = _get_columns_to_convert(df, schema, preserve_index,\n",
      "                      ~~~~~~~~~~~~~~~~~~~~~~~^^^^^^^^^^^^^^^^^^^^^^^^^^^^\n",
      "                                              columns)\n",
      "                                              ^^^^^^^^\n",
      "  File \"/Users/nayzawlin/Desktop/langara/ARC/PEH/PEH-cohort/pehenv/lib/python3.13/site-packages/pyarrow/pandas_compat.py\", line 374, in _get_columns_to_convert\n",
      "    raise ValueError(\n",
      "        f'Duplicate column names found: {list(df.columns)}'\n",
      "    )\n",
      "ValueError: Duplicate column names found: ['ClientID', 'PostalCode', 'City', 'StreetAddress1', 'StreetAddress2', 'SubBuilding', 'BuildingNumber', 'Street', 'StreetType', 'CityName', 'ProvinceCode', 'PostalCode', 'CountryName']\n",
      "2025-08-21 12:12:04.168 Uncaught app execution\n",
      "Traceback (most recent call last):\n",
      "  File \"/Users/nayzawlin/Desktop/langara/ARC/PEH/PEH-cohort/pehenv/lib/python3.13/site-packages/streamlit/runtime/scriptrunner/exec_code.py\", line 128, in exec_func_with_error_handling\n",
      "    result = func()\n",
      "  File \"/Users/nayzawlin/Desktop/langara/ARC/PEH/PEH-cohort/pehenv/lib/python3.13/site-packages/streamlit/runtime/scriptrunner/script_runner.py\", line 669, in code_to_exec\n",
      "    exec(code, module.__dict__)  # noqa: S102\n",
      "    ~~~~^^^^^^^^^^^^^^^^^^^^^^^\n",
      "  File \"/Users/nayzawlin/Desktop/langara/ARC/PEH/PEH-cohort/bc_addresses_analysis.py\", line 758, in <module>\n",
      "    temp_df[\"row_has_missing\"] = temp_df[incomplete_fields].isnull().any(axis=1)\n",
      "                                 ~~~~~~~^^^^^^^^^^^^^^^^^^^\n",
      "  File \"/Users/nayzawlin/Desktop/langara/ARC/PEH/PEH-cohort/pehenv/lib/python3.13/site-packages/pandas/core/frame.py\", line 4113, in __getitem__\n",
      "    indexer = self.columns._get_indexer_strict(key, \"columns\")[1]\n",
      "              ~~~~~~~~~~~~~~~~~~~~~~~~~~~~~~~~^^^^^^^^^^^^^^^^\n",
      "  File \"/Users/nayzawlin/Desktop/langara/ARC/PEH/PEH-cohort/pehenv/lib/python3.13/site-packages/pandas/core/indexes/base.py\", line 6212, in _get_indexer_strict\n",
      "    self._raise_if_missing(keyarr, indexer, axis_name)\n",
      "    ~~~~~~~~~~~~~~~~~~~~~~^^^^^^^^^^^^^^^^^^^^^^^^^^^^\n",
      "  File \"/Users/nayzawlin/Desktop/langara/ARC/PEH/PEH-cohort/pehenv/lib/python3.13/site-packages/pandas/core/indexes/base.py\", line 6264, in _raise_if_missing\n",
      "    raise KeyError(f\"{not_found} not in index\")\n",
      "KeyError: \"['Street', 'StreetType', 'CityName'] not in index\"\n",
      "2025-08-21 12:12:10.581 Uncaught app execution\n",
      "Traceback (most recent call last):\n",
      "  File \"/Users/nayzawlin/Desktop/langara/ARC/PEH/PEH-cohort/pehenv/lib/python3.13/site-packages/pandas/core/indexes/base.py\", line 3812, in get_loc\n",
      "    return self._engine.get_loc(casted_key)\n",
      "           ~~~~~~~~~~~~~~~~~~~~^^^^^^^^^^^^\n",
      "  File \"pandas/_libs/index.pyx\", line 167, in pandas._libs.index.IndexEngine.get_loc\n",
      "  File \"pandas/_libs/index.pyx\", line 196, in pandas._libs.index.IndexEngine.get_loc\n",
      "  File \"pandas/_libs/hashtable_class_helper.pxi\", line 7088, in pandas._libs.hashtable.PyObjectHashTable.get_item\n",
      "  File \"pandas/_libs/hashtable_class_helper.pxi\", line 7096, in pandas._libs.hashtable.PyObjectHashTable.get_item\n",
      "KeyError: 'Street'\n",
      "\n",
      "The above exception was the direct cause of the following exception:\n",
      "\n",
      "Traceback (most recent call last):\n",
      "  File \"/Users/nayzawlin/Desktop/langara/ARC/PEH/PEH-cohort/pehenv/lib/python3.13/site-packages/streamlit/runtime/scriptrunner/exec_code.py\", line 128, in exec_func_with_error_handling\n",
      "    result = func()\n",
      "  File \"/Users/nayzawlin/Desktop/langara/ARC/PEH/PEH-cohort/pehenv/lib/python3.13/site-packages/streamlit/runtime/scriptrunner/script_runner.py\", line 669, in code_to_exec\n",
      "    exec(code, module.__dict__)  # noqa: S102\n",
      "    ~~~~^^^^^^^^^^^^^^^^^^^^^^^\n",
      "  File \"/Users/nayzawlin/Desktop/langara/ARC/PEH/PEH-cohort/bc_addresses_analysis.py\", line 772, in <module>\n",
      "    temp_df[\"address_class\"] = temp_df[\"Street\"].apply(classify_address)\n",
      "                               ~~~~~~~^^^^^^^^^^\n",
      "  File \"/Users/nayzawlin/Desktop/langara/ARC/PEH/PEH-cohort/pehenv/lib/python3.13/site-packages/pandas/core/frame.py\", line 4107, in __getitem__\n",
      "    indexer = self.columns.get_loc(key)\n",
      "  File \"/Users/nayzawlin/Desktop/langara/ARC/PEH/PEH-cohort/pehenv/lib/python3.13/site-packages/pandas/core/indexes/base.py\", line 3819, in get_loc\n",
      "    raise KeyError(key) from err\n",
      "KeyError: 'Street'\n",
      "2025-08-21 12:12:16.744 Uncaught app execution\n",
      "Traceback (most recent call last):\n",
      "  File \"/Users/nayzawlin/Desktop/langara/ARC/PEH/PEH-cohort/pehenv/lib/python3.13/site-packages/streamlit/runtime/scriptrunner/exec_code.py\", line 128, in exec_func_with_error_handling\n",
      "    result = func()\n",
      "  File \"/Users/nayzawlin/Desktop/langara/ARC/PEH/PEH-cohort/pehenv/lib/python3.13/site-packages/streamlit/runtime/scriptrunner/script_runner.py\", line 669, in code_to_exec\n",
      "    exec(code, module.__dict__)  # noqa: S102\n",
      "    ~~~~^^^^^^^^^^^^^^^^^^^^^^^\n",
      "  File \"/Users/nayzawlin/Desktop/langara/ARC/PEH/PEH-cohort/bc_addresses_analysis.py\", line 818, in <module>\n",
      "    temp_df['FullAddressKey'] = temp_df[address_columns].fillna('').apply(\n",
      "                                ~~~~~~~^^^^^^^^^^^^^^^^^\n",
      "  File \"/Users/nayzawlin/Desktop/langara/ARC/PEH/PEH-cohort/pehenv/lib/python3.13/site-packages/pandas/core/frame.py\", line 4113, in __getitem__\n",
      "    indexer = self.columns._get_indexer_strict(key, \"columns\")[1]\n",
      "              ~~~~~~~~~~~~~~~~~~~~~~~~~~~~~~~~^^^^^^^^^^^^^^^^\n",
      "  File \"/Users/nayzawlin/Desktop/langara/ARC/PEH/PEH-cohort/pehenv/lib/python3.13/site-packages/pandas/core/indexes/base.py\", line 6212, in _get_indexer_strict\n",
      "    self._raise_if_missing(keyarr, indexer, axis_name)\n",
      "    ~~~~~~~~~~~~~~~~~~~~~~^^^^^^^^^^^^^^^^^^^^^^^^^^^^\n",
      "  File \"/Users/nayzawlin/Desktop/langara/ARC/PEH/PEH-cohort/pehenv/lib/python3.13/site-packages/pandas/core/indexes/base.py\", line 6264, in _raise_if_missing\n",
      "    raise KeyError(f\"{not_found} not in index\")\n",
      "KeyError: \"['BuildingNumber', 'Street', 'StreetType', 'CityName'] not in index\"\n",
      "2025-08-21 12:13:27.924 Uncaught app execution\n",
      "Traceback (most recent call last):\n",
      "  File \"/Users/nayzawlin/Desktop/langara/ARC/PEH/PEH-cohort/pehenv/lib/python3.13/site-packages/streamlit/runtime/scriptrunner/exec_code.py\", line 128, in exec_func_with_error_handling\n",
      "    result = func()\n",
      "  File \"/Users/nayzawlin/Desktop/langara/ARC/PEH/PEH-cohort/pehenv/lib/python3.13/site-packages/streamlit/runtime/scriptrunner/script_runner.py\", line 669, in code_to_exec\n",
      "    exec(code, module.__dict__)  # noqa: S102\n",
      "    ~~~~^^^^^^^^^^^^^^^^^^^^^^^\n",
      "  File \"/Users/nayzawlin/Desktop/langara/ARC/PEH/PEH-cohort/bc_addresses_analysis.py\", line 818, in <module>\n",
      "    temp_df['FullAddressKey'] = temp_df[address_columns].fillna('').apply(\n",
      "                                ~~~~~~~^^^^^^^^^^^^^^^^^\n",
      "  File \"/Users/nayzawlin/Desktop/langara/ARC/PEH/PEH-cohort/pehenv/lib/python3.13/site-packages/pandas/core/frame.py\", line 4113, in __getitem__\n",
      "    indexer = self.columns._get_indexer_strict(key, \"columns\")[1]\n",
      "              ~~~~~~~~~~~~~~~~~~~~~~~~~~~~~~~~^^^^^^^^^^^^^^^^\n",
      "  File \"/Users/nayzawlin/Desktop/langara/ARC/PEH/PEH-cohort/pehenv/lib/python3.13/site-packages/pandas/core/indexes/base.py\", line 6212, in _get_indexer_strict\n",
      "    self._raise_if_missing(keyarr, indexer, axis_name)\n",
      "    ~~~~~~~~~~~~~~~~~~~~~~^^^^^^^^^^^^^^^^^^^^^^^^^^^^\n",
      "  File \"/Users/nayzawlin/Desktop/langara/ARC/PEH/PEH-cohort/pehenv/lib/python3.13/site-packages/pandas/core/indexes/base.py\", line 6264, in _raise_if_missing\n",
      "    raise KeyError(f\"{not_found} not in index\")\n",
      "KeyError: \"['BuildingNumber', 'Street', 'StreetType', 'CityName'] not in index\"\n",
      "2025-08-21 12:15:31.230 Uncaught app execution\n",
      "Traceback (most recent call last):\n",
      "  File \"/Users/nayzawlin/Desktop/langara/ARC/PEH/PEH-cohort/pehenv/lib/python3.13/site-packages/streamlit/runtime/scriptrunner/exec_code.py\", line 128, in exec_func_with_error_handling\n",
      "    result = func()\n",
      "  File \"/Users/nayzawlin/Desktop/langara/ARC/PEH/PEH-cohort/pehenv/lib/python3.13/site-packages/streamlit/runtime/scriptrunner/script_runner.py\", line 669, in code_to_exec\n",
      "    exec(code, module.__dict__)  # noqa: S102\n",
      "    ~~~~^^^^^^^^^^^^^^^^^^^^^^^\n",
      "  File \"/Users/nayzawlin/Desktop/langara/ARC/PEH/PEH-cohort/bc_addresses_analysis.py\", line 758, in <module>\n",
      "    temp_df[\"row_has_missing\"] = temp_df[incomplete_fields].isnull().any(axis=1)\n",
      "                                 ~~~~~~~^^^^^^^^^^^^^^^^^^^\n",
      "  File \"/Users/nayzawlin/Desktop/langara/ARC/PEH/PEH-cohort/pehenv/lib/python3.13/site-packages/pandas/core/frame.py\", line 4113, in __getitem__\n",
      "    indexer = self.columns._get_indexer_strict(key, \"columns\")[1]\n",
      "              ~~~~~~~~~~~~~~~~~~~~~~~~~~~~~~~~^^^^^^^^^^^^^^^^\n",
      "  File \"/Users/nayzawlin/Desktop/langara/ARC/PEH/PEH-cohort/pehenv/lib/python3.13/site-packages/pandas/core/indexes/base.py\", line 6212, in _get_indexer_strict\n",
      "    self._raise_if_missing(keyarr, indexer, axis_name)\n",
      "    ~~~~~~~~~~~~~~~~~~~~~~^^^^^^^^^^^^^^^^^^^^^^^^^^^^\n",
      "  File \"/Users/nayzawlin/Desktop/langara/ARC/PEH/PEH-cohort/pehenv/lib/python3.13/site-packages/pandas/core/indexes/base.py\", line 6264, in _raise_if_missing\n",
      "    raise KeyError(f\"{not_found} not in index\")\n",
      "KeyError: \"['Street', 'StreetType', 'CityName'] not in index\"\n",
      "2025-08-21 13:01:04.954 Uncaught app execution\n",
      "Traceback (most recent call last):\n",
      "  File \"/Users/nayzawlin/Desktop/langara/ARC/PEH/PEH-cohort/pehenv/lib/python3.13/site-packages/streamlit/runtime/scriptrunner/exec_code.py\", line 128, in exec_func_with_error_handling\n",
      "    result = func()\n",
      "  File \"/Users/nayzawlin/Desktop/langara/ARC/PEH/PEH-cohort/pehenv/lib/python3.13/site-packages/streamlit/runtime/scriptrunner/script_runner.py\", line 669, in code_to_exec\n",
      "    exec(code, module.__dict__)  # noqa: S102\n",
      "    ~~~~^^^^^^^^^^^^^^^^^^^^^^^\n",
      "  File \"/Users/nayzawlin/Desktop/langara/ARC/PEH/PEH-cohort/bc_addresses_analysis.py\", line 799, in <module>\n",
      "    temp_df[\"row_has_missing\"] = temp_df[incomplete_fields].isnull().any(axis=1)\n",
      "                                 ~~~~~~~^^^^^^^^^^^^^^^^^^^\n",
      "  File \"/Users/nayzawlin/Desktop/langara/ARC/PEH/PEH-cohort/pehenv/lib/python3.13/site-packages/pandas/core/frame.py\", line 4113, in __getitem__\n",
      "    indexer = self.columns._get_indexer_strict(key, \"columns\")[1]\n",
      "              ~~~~~~~~~~~~~~~~~~~~~~~~~~~~~~~~^^^^^^^^^^^^^^^^\n",
      "  File \"/Users/nayzawlin/Desktop/langara/ARC/PEH/PEH-cohort/pehenv/lib/python3.13/site-packages/pandas/core/indexes/base.py\", line 6212, in _get_indexer_strict\n",
      "    self._raise_if_missing(keyarr, indexer, axis_name)\n",
      "    ~~~~~~~~~~~~~~~~~~~~~~^^^^^^^^^^^^^^^^^^^^^^^^^^^^\n",
      "  File \"/Users/nayzawlin/Desktop/langara/ARC/PEH/PEH-cohort/pehenv/lib/python3.13/site-packages/pandas/core/indexes/base.py\", line 6264, in _raise_if_missing\n",
      "    raise KeyError(f\"{not_found} not in index\")\n",
      "KeyError: \"['Street', 'StreetType', 'CityName'] not in index\"\n",
      "2025-08-21 13:01:50.132 Uncaught app execution\n",
      "Traceback (most recent call last):\n",
      "  File \"/Users/nayzawlin/Desktop/langara/ARC/PEH/PEH-cohort/pehenv/lib/python3.13/site-packages/streamlit/runtime/scriptrunner/exec_code.py\", line 128, in exec_func_with_error_handling\n",
      "    result = func()\n",
      "  File \"/Users/nayzawlin/Desktop/langara/ARC/PEH/PEH-cohort/pehenv/lib/python3.13/site-packages/streamlit/runtime/scriptrunner/script_runner.py\", line 669, in code_to_exec\n",
      "    exec(code, module.__dict__)  # noqa: S102\n",
      "    ~~~~^^^^^^^^^^^^^^^^^^^^^^^\n",
      "  File \"/Users/nayzawlin/Desktop/langara/ARC/PEH/PEH-cohort/bc_addresses_analysis.py\", line 799, in <module>\n",
      "    temp_df[\"row_has_missing\"] = temp_df[incomplete_fields].isnull().any(axis=1)\n",
      "                                 ~~~~~~~^^^^^^^^^^^^^^^^^^^\n",
      "  File \"/Users/nayzawlin/Desktop/langara/ARC/PEH/PEH-cohort/pehenv/lib/python3.13/site-packages/pandas/core/frame.py\", line 4113, in __getitem__\n",
      "    indexer = self.columns._get_indexer_strict(key, \"columns\")[1]\n",
      "              ~~~~~~~~~~~~~~~~~~~~~~~~~~~~~~~~^^^^^^^^^^^^^^^^\n",
      "  File \"/Users/nayzawlin/Desktop/langara/ARC/PEH/PEH-cohort/pehenv/lib/python3.13/site-packages/pandas/core/indexes/base.py\", line 6212, in _get_indexer_strict\n",
      "    self._raise_if_missing(keyarr, indexer, axis_name)\n",
      "    ~~~~~~~~~~~~~~~~~~~~~~^^^^^^^^^^^^^^^^^^^^^^^^^^^^\n",
      "  File \"/Users/nayzawlin/Desktop/langara/ARC/PEH/PEH-cohort/pehenv/lib/python3.13/site-packages/pandas/core/indexes/base.py\", line 6264, in _raise_if_missing\n",
      "    raise KeyError(f\"{not_found} not in index\")\n",
      "KeyError: \"['E_CityName'] not in index\"\n",
      "2025-08-21 13:02:57.919 Uncaught app execution\n",
      "Traceback (most recent call last):\n",
      "  File \"/Users/nayzawlin/Desktop/langara/ARC/PEH/PEH-cohort/pehenv/lib/python3.13/site-packages/streamlit/runtime/scriptrunner/exec_code.py\", line 128, in exec_func_with_error_handling\n",
      "    result = func()\n",
      "  File \"/Users/nayzawlin/Desktop/langara/ARC/PEH/PEH-cohort/pehenv/lib/python3.13/site-packages/streamlit/runtime/scriptrunner/script_runner.py\", line 669, in code_to_exec\n",
      "    exec(code, module.__dict__)  # noqa: S102\n",
      "    ~~~~^^^^^^^^^^^^^^^^^^^^^^^\n",
      "  File \"/Users/nayzawlin/Desktop/langara/ARC/PEH/PEH-cohort/bc_addresses_analysis.py\", line 849, in <module>\n",
      "    temp_df[\"MoveDistance(KM)\"] = temp_df.groupby(\"ClientID\").apply(compute_move_distances).reset_index(level=0, drop=True).round(1)\n",
      "                                  ~~~~~~~~~~~~~~~~~~~~~~~~~~~~~~~~~^^^^^^^^^^^^^^^^^^^^^^^^\n",
      "  File \"/Users/nayzawlin/Desktop/langara/ARC/PEH/PEH-cohort/pehenv/lib/python3.13/site-packages/pandas/core/groupby/groupby.py\", line 1825, in apply\n",
      "    result = self._python_apply_general(f, self._selected_obj)\n",
      "  File \"/Users/nayzawlin/Desktop/langara/ARC/PEH/PEH-cohort/pehenv/lib/python3.13/site-packages/pandas/core/groupby/groupby.py\", line 1886, in _python_apply_general\n",
      "    values, mutated = self._grouper.apply_groupwise(f, data, self.axis)\n",
      "                      ~~~~~~~~~~~~~~~~~~~~~~~~~~~~~^^^^^^^^^^^^^^^^^^^^\n",
      "  File \"/Users/nayzawlin/Desktop/langara/ARC/PEH/PEH-cohort/pehenv/lib/python3.13/site-packages/pandas/core/groupby/ops.py\", line 919, in apply_groupwise\n",
      "    res = f(group)\n",
      "  File \"/Users/nayzawlin/Desktop/langara/ARC/PEH/PEH-cohort/bc_addresses_analysis.py\", line 839, in compute_move_distances\n",
      "    group = group.sort_values(\"StartDateID\")\n",
      "  File \"/Users/nayzawlin/Desktop/langara/ARC/PEH/PEH-cohort/pehenv/lib/python3.13/site-packages/pandas/core/frame.py\", line 7196, in sort_values\n",
      "    k = self._get_label_or_level_values(by[0], axis=axis)\n",
      "  File \"/Users/nayzawlin/Desktop/langara/ARC/PEH/PEH-cohort/pehenv/lib/python3.13/site-packages/pandas/core/generic.py\", line 1911, in _get_label_or_level_values\n",
      "    raise KeyError(key)\n",
      "KeyError: 'StartDateID'\n",
      "2025-08-21 13:03:22.291 Uncaught app execution\n",
      "Traceback (most recent call last):\n",
      "  File \"/Users/nayzawlin/Desktop/langara/ARC/PEH/PEH-cohort/pehenv/lib/python3.13/site-packages/streamlit/runtime/scriptrunner/exec_code.py\", line 128, in exec_func_with_error_handling\n",
      "    result = func()\n",
      "  File \"/Users/nayzawlin/Desktop/langara/ARC/PEH/PEH-cohort/pehenv/lib/python3.13/site-packages/streamlit/runtime/scriptrunner/script_runner.py\", line 669, in code_to_exec\n",
      "    exec(code, module.__dict__)  # noqa: S102\n",
      "    ~~~~^^^^^^^^^^^^^^^^^^^^^^^\n",
      "  File \"/Users/nayzawlin/Desktop/langara/ARC/PEH/PEH-cohort/bc_addresses_analysis.py\", line 849, in <module>\n",
      "    temp_df[\"MoveDistance(KM)\"] = temp_df.groupby(\"ClientID\").apply(compute_move_distances).reset_index(level=0, drop=True).round(1)\n",
      "                                  ~~~~~~~~~~~~~~~~~~~~~~~~~~~~~~~~~^^^^^^^^^^^^^^^^^^^^^^^^\n",
      "  File \"/Users/nayzawlin/Desktop/langara/ARC/PEH/PEH-cohort/pehenv/lib/python3.13/site-packages/pandas/core/groupby/groupby.py\", line 1825, in apply\n",
      "    result = self._python_apply_general(f, self._selected_obj)\n",
      "  File \"/Users/nayzawlin/Desktop/langara/ARC/PEH/PEH-cohort/pehenv/lib/python3.13/site-packages/pandas/core/groupby/groupby.py\", line 1886, in _python_apply_general\n",
      "    values, mutated = self._grouper.apply_groupwise(f, data, self.axis)\n",
      "                      ~~~~~~~~~~~~~~~~~~~~~~~~~~~~~^^^^^^^^^^^^^^^^^^^^\n",
      "  File \"/Users/nayzawlin/Desktop/langara/ARC/PEH/PEH-cohort/pehenv/lib/python3.13/site-packages/pandas/core/groupby/ops.py\", line 919, in apply_groupwise\n",
      "    res = f(group)\n",
      "  File \"/Users/nayzawlin/Desktop/langara/ARC/PEH/PEH-cohort/bc_addresses_analysis.py\", line 839, in compute_move_distances\n",
      "    group = group.sort_values(\"StartDateID\")\n",
      "  File \"/Users/nayzawlin/Desktop/langara/ARC/PEH/PEH-cohort/pehenv/lib/python3.13/site-packages/pandas/core/frame.py\", line 7196, in sort_values\n",
      "    k = self._get_label_or_level_values(by[0], axis=axis)\n",
      "  File \"/Users/nayzawlin/Desktop/langara/ARC/PEH/PEH-cohort/pehenv/lib/python3.13/site-packages/pandas/core/generic.py\", line 1911, in _get_label_or_level_values\n",
      "    raise KeyError(key)\n",
      "KeyError: 'StartDateID'\n",
      "2025-08-21 13:03:34.038 Uncaught app execution\n",
      "Traceback (most recent call last):\n",
      "  File \"/Users/nayzawlin/Desktop/langara/ARC/PEH/PEH-cohort/pehenv/lib/python3.13/site-packages/streamlit/runtime/scriptrunner/exec_code.py\", line 128, in exec_func_with_error_handling\n",
      "    result = func()\n",
      "  File \"/Users/nayzawlin/Desktop/langara/ARC/PEH/PEH-cohort/pehenv/lib/python3.13/site-packages/streamlit/runtime/scriptrunner/script_runner.py\", line 669, in code_to_exec\n",
      "    exec(code, module.__dict__)  # noqa: S102\n",
      "    ~~~~^^^^^^^^^^^^^^^^^^^^^^^\n",
      "  File \"/Users/nayzawlin/Desktop/langara/ARC/PEH/PEH-cohort/bc_addresses_analysis.py\", line 849, in <module>\n",
      "    temp_df[\"MoveDistance(KM)\"] = temp_df.groupby(\"ClientID\").apply(compute_move_distances).reset_index(level=0, drop=True).round(1)\n",
      "                                  ~~~~~~~~~~~~~~~~~~~~~~~~~~~~~~~~~^^^^^^^^^^^^^^^^^^^^^^^^\n",
      "  File \"/Users/nayzawlin/Desktop/langara/ARC/PEH/PEH-cohort/pehenv/lib/python3.13/site-packages/pandas/core/groupby/groupby.py\", line 1825, in apply\n",
      "    result = self._python_apply_general(f, self._selected_obj)\n",
      "  File \"/Users/nayzawlin/Desktop/langara/ARC/PEH/PEH-cohort/pehenv/lib/python3.13/site-packages/pandas/core/groupby/groupby.py\", line 1886, in _python_apply_general\n",
      "    values, mutated = self._grouper.apply_groupwise(f, data, self.axis)\n",
      "                      ~~~~~~~~~~~~~~~~~~~~~~~~~~~~~^^^^^^^^^^^^^^^^^^^^\n",
      "  File \"/Users/nayzawlin/Desktop/langara/ARC/PEH/PEH-cohort/pehenv/lib/python3.13/site-packages/pandas/core/groupby/ops.py\", line 919, in apply_groupwise\n",
      "    res = f(group)\n",
      "  File \"/Users/nayzawlin/Desktop/langara/ARC/PEH/PEH-cohort/bc_addresses_analysis.py\", line 839, in compute_move_distances\n",
      "    group = group.sort_values(\"StartDateID\")\n",
      "  File \"/Users/nayzawlin/Desktop/langara/ARC/PEH/PEH-cohort/pehenv/lib/python3.13/site-packages/pandas/core/frame.py\", line 7196, in sort_values\n",
      "    k = self._get_label_or_level_values(by[0], axis=axis)\n",
      "  File \"/Users/nayzawlin/Desktop/langara/ARC/PEH/PEH-cohort/pehenv/lib/python3.13/site-packages/pandas/core/generic.py\", line 1911, in _get_label_or_level_values\n",
      "    raise KeyError(key)\n",
      "KeyError: 'StartDateID'\n",
      "2025-08-21 13:07:23.209 Uncaught app execution\n",
      "Traceback (most recent call last):\n",
      "  File \"/Users/nayzawlin/Desktop/langara/ARC/PEH/PEH-cohort/pehenv/lib/python3.13/site-packages/streamlit/runtime/scriptrunner/exec_code.py\", line 128, in exec_func_with_error_handling\n",
      "    result = func()\n",
      "  File \"/Users/nayzawlin/Desktop/langara/ARC/PEH/PEH-cohort/pehenv/lib/python3.13/site-packages/streamlit/runtime/scriptrunner/script_runner.py\", line 669, in code_to_exec\n",
      "    exec(code, module.__dict__)  # noqa: S102\n",
      "    ~~~~^^^^^^^^^^^^^^^^^^^^^^^\n",
      "  File \"/Users/nayzawlin/Desktop/langara/ARC/PEH/PEH-cohort/bc_addresses_analysis.py\", line 799, in <module>\n",
      "    temp_df[\"row_has_missing\"] = temp_df[incomplete_fields].isnull().any(axis=1)\n",
      "                                 ~~~~~~~^^^^^^^^^^^^^^^^^^^\n",
      "  File \"/Users/nayzawlin/Desktop/langara/ARC/PEH/PEH-cohort/pehenv/lib/python3.13/site-packages/pandas/core/frame.py\", line 4113, in __getitem__\n",
      "    indexer = self.columns._get_indexer_strict(key, \"columns\")[1]\n",
      "              ~~~~~~~~~~~~~~~~~~~~~~~~~~~~~~~~^^^^^^^^^^^^^^^^\n",
      "  File \"/Users/nayzawlin/Desktop/langara/ARC/PEH/PEH-cohort/pehenv/lib/python3.13/site-packages/pandas/core/indexes/base.py\", line 6212, in _get_indexer_strict\n",
      "    self._raise_if_missing(keyarr, indexer, axis_name)\n",
      "    ~~~~~~~~~~~~~~~~~~~~~~^^^^^^^^^^^^^^^^^^^^^^^^^^^^\n",
      "  File \"/Users/nayzawlin/Desktop/langara/ARC/PEH/PEH-cohort/pehenv/lib/python3.13/site-packages/pandas/core/indexes/base.py\", line 6261, in _raise_if_missing\n",
      "    raise KeyError(f\"None of [{key}] are in the [{axis_name}]\")\n",
      "KeyError: \"None of [Index(['E_Street', 'E_StreetType', 'E_PostalCode', 'E_City'], dtype='object')] are in the [columns]\"\n",
      "2025-08-21 13:12:52.000 Uncaught app execution\n",
      "Traceback (most recent call last):\n",
      "  File \"/Users/nayzawlin/Desktop/langara/ARC/PEH/PEH-cohort/pehenv/lib/python3.13/site-packages/streamlit/runtime/scriptrunner/exec_code.py\", line 128, in exec_func_with_error_handling\n",
      "    result = func()\n",
      "  File \"/Users/nayzawlin/Desktop/langara/ARC/PEH/PEH-cohort/pehenv/lib/python3.13/site-packages/streamlit/runtime/scriptrunner/script_runner.py\", line 669, in code_to_exec\n",
      "    exec(code, module.__dict__)  # noqa: S102\n",
      "    ~~~~^^^^^^^^^^^^^^^^^^^^^^^\n",
      "  File \"/Users/nayzawlin/Desktop/langara/ARC/PEH/PEH-cohort/bc_addresses_analysis.py\", line 910, in <module>\n",
      "    temp_df['FullAddressKey'] = temp_df[address_columns].fillna('').apply(\n",
      "                                ~~~~~~~^^^^^^^^^^^^^^^^^\n",
      "  File \"/Users/nayzawlin/Desktop/langara/ARC/PEH/PEH-cohort/pehenv/lib/python3.13/site-packages/pandas/core/frame.py\", line 4113, in __getitem__\n",
      "    indexer = self.columns._get_indexer_strict(key, \"columns\")[1]\n",
      "              ~~~~~~~~~~~~~~~~~~~~~~~~~~~~~~~~^^^^^^^^^^^^^^^^\n",
      "  File \"/Users/nayzawlin/Desktop/langara/ARC/PEH/PEH-cohort/pehenv/lib/python3.13/site-packages/pandas/core/indexes/base.py\", line 6212, in _get_indexer_strict\n",
      "    self._raise_if_missing(keyarr, indexer, axis_name)\n",
      "    ~~~~~~~~~~~~~~~~~~~~~~^^^^^^^^^^^^^^^^^^^^^^^^^^^^\n",
      "  File \"/Users/nayzawlin/Desktop/langara/ARC/PEH/PEH-cohort/pehenv/lib/python3.13/site-packages/pandas/core/indexes/base.py\", line 6264, in _raise_if_missing\n",
      "    raise KeyError(f\"{not_found} not in index\")\n",
      "KeyError: \"['BuildingNumber', 'Street', 'StreetType', 'CityName'] not in index\"\n",
      "2025-08-21 13:28:51.378 Uncaught app execution\n",
      "Traceback (most recent call last):\n",
      "  File \"/Users/nayzawlin/Desktop/langara/ARC/PEH/PEH-cohort/pehenv/lib/python3.13/site-packages/streamlit/runtime/scriptrunner/exec_code.py\", line 128, in exec_func_with_error_handling\n",
      "    result = func()\n",
      "  File \"/Users/nayzawlin/Desktop/langara/ARC/PEH/PEH-cohort/pehenv/lib/python3.13/site-packages/streamlit/runtime/scriptrunner/script_runner.py\", line 669, in code_to_exec\n",
      "    exec(code, module.__dict__)  # noqa: S102\n",
      "    ~~~~^^^^^^^^^^^^^^^^^^^^^^^\n",
      "  File \"/Users/nayzawlin/Desktop/langara/ARC/PEH/PEH-cohort/bc_addresses_analysis.py\", line 810, in <module>\n",
      "    temp_df[\"row_has_missing\"] = temp_df[incomplete_fields].isnull().any(axis=1)\n",
      "                                 ~~~~~~~^^^^^^^^^^^^^^^^^^^\n",
      "  File \"/Users/nayzawlin/Desktop/langara/ARC/PEH/PEH-cohort/pehenv/lib/python3.13/site-packages/pandas/core/frame.py\", line 4113, in __getitem__\n",
      "    indexer = self.columns._get_indexer_strict(key, \"columns\")[1]\n",
      "              ~~~~~~~~~~~~~~~~~~~~~~~~~~~~~~~~^^^^^^^^^^^^^^^^\n",
      "  File \"/Users/nayzawlin/Desktop/langara/ARC/PEH/PEH-cohort/pehenv/lib/python3.13/site-packages/pandas/core/indexes/base.py\", line 6212, in _get_indexer_strict\n",
      "    self._raise_if_missing(keyarr, indexer, axis_name)\n",
      "    ~~~~~~~~~~~~~~~~~~~~~~^^^^^^^^^^^^^^^^^^^^^^^^^^^^\n",
      "  File \"/Users/nayzawlin/Desktop/langara/ARC/PEH/PEH-cohort/pehenv/lib/python3.13/site-packages/pandas/core/indexes/base.py\", line 6261, in _raise_if_missing\n",
      "    raise KeyError(f\"None of [{key}] are in the [{axis_name}]\")\n",
      "KeyError: \"None of [Index(['E_Street', 'E_StreetType', 'E_PostalCode', 'E_City'], dtype='object')] are in the [columns]\"\n",
      "2025-08-21 13:28:54.947 Uncaught app execution\n",
      "Traceback (most recent call last):\n",
      "  File \"/Users/nayzawlin/Desktop/langara/ARC/PEH/PEH-cohort/pehenv/lib/python3.13/site-packages/pandas/core/indexes/base.py\", line 3812, in get_loc\n",
      "    return self._engine.get_loc(casted_key)\n",
      "           ~~~~~~~~~~~~~~~~~~~~^^^^^^^^^^^^\n",
      "  File \"pandas/_libs/index.pyx\", line 167, in pandas._libs.index.IndexEngine.get_loc\n",
      "  File \"pandas/_libs/index.pyx\", line 196, in pandas._libs.index.IndexEngine.get_loc\n",
      "  File \"pandas/_libs/hashtable_class_helper.pxi\", line 7088, in pandas._libs.hashtable.PyObjectHashTable.get_item\n",
      "  File \"pandas/_libs/hashtable_class_helper.pxi\", line 7096, in pandas._libs.hashtable.PyObjectHashTable.get_item\n",
      "KeyError: 'E_Street'\n",
      "\n",
      "The above exception was the direct cause of the following exception:\n",
      "\n",
      "Traceback (most recent call last):\n",
      "  File \"/Users/nayzawlin/Desktop/langara/ARC/PEH/PEH-cohort/pehenv/lib/python3.13/site-packages/streamlit/runtime/scriptrunner/exec_code.py\", line 128, in exec_func_with_error_handling\n",
      "    result = func()\n",
      "  File \"/Users/nayzawlin/Desktop/langara/ARC/PEH/PEH-cohort/pehenv/lib/python3.13/site-packages/streamlit/runtime/scriptrunner/script_runner.py\", line 669, in code_to_exec\n",
      "    exec(code, module.__dict__)  # noqa: S102\n",
      "    ~~~~^^^^^^^^^^^^^^^^^^^^^^^\n",
      "  File \"/Users/nayzawlin/Desktop/langara/ARC/PEH/PEH-cohort/bc_addresses_analysis.py\", line 828, in <module>\n",
      "    temp_df[\"address_class\"] = temp_df[\"E_Street\"].apply(classify_address)\n",
      "                               ~~~~~~~^^^^^^^^^^^^\n",
      "  File \"/Users/nayzawlin/Desktop/langara/ARC/PEH/PEH-cohort/pehenv/lib/python3.13/site-packages/pandas/core/frame.py\", line 4107, in __getitem__\n",
      "    indexer = self.columns.get_loc(key)\n",
      "  File \"/Users/nayzawlin/Desktop/langara/ARC/PEH/PEH-cohort/pehenv/lib/python3.13/site-packages/pandas/core/indexes/base.py\", line 3819, in get_loc\n",
      "    raise KeyError(key) from err\n",
      "KeyError: 'E_Street'\n",
      "2025-08-21 13:28:58.223 Uncaught app execution\n",
      "Traceback (most recent call last):\n",
      "  File \"/Users/nayzawlin/Desktop/langara/ARC/PEH/PEH-cohort/pehenv/lib/python3.13/site-packages/pandas/core/indexes/base.py\", line 3812, in get_loc\n",
      "    return self._engine.get_loc(casted_key)\n",
      "           ~~~~~~~~~~~~~~~~~~~~^^^^^^^^^^^^\n",
      "  File \"pandas/_libs/index.pyx\", line 167, in pandas._libs.index.IndexEngine.get_loc\n",
      "  File \"pandas/_libs/index.pyx\", line 196, in pandas._libs.index.IndexEngine.get_loc\n",
      "  File \"pandas/_libs/hashtable_class_helper.pxi\", line 7088, in pandas._libs.hashtable.PyObjectHashTable.get_item\n",
      "  File \"pandas/_libs/hashtable_class_helper.pxi\", line 7096, in pandas._libs.hashtable.PyObjectHashTable.get_item\n",
      "KeyError: 'E_Street'\n",
      "\n",
      "The above exception was the direct cause of the following exception:\n",
      "\n",
      "Traceback (most recent call last):\n",
      "  File \"/Users/nayzawlin/Desktop/langara/ARC/PEH/PEH-cohort/pehenv/lib/python3.13/site-packages/streamlit/runtime/scriptrunner/exec_code.py\", line 128, in exec_func_with_error_handling\n",
      "    result = func()\n",
      "  File \"/Users/nayzawlin/Desktop/langara/ARC/PEH/PEH-cohort/pehenv/lib/python3.13/site-packages/streamlit/runtime/scriptrunner/script_runner.py\", line 669, in code_to_exec\n",
      "    exec(code, module.__dict__)  # noqa: S102\n",
      "    ~~~~^^^^^^^^^^^^^^^^^^^^^^^\n",
      "  File \"/Users/nayzawlin/Desktop/langara/ARC/PEH/PEH-cohort/bc_addresses_analysis.py\", line 828, in <module>\n",
      "    temp_df[\"address_class\"] = temp_df[\"E_Street\"].apply(classify_address)\n",
      "                               ~~~~~~~^^^^^^^^^^^^\n",
      "  File \"/Users/nayzawlin/Desktop/langara/ARC/PEH/PEH-cohort/pehenv/lib/python3.13/site-packages/pandas/core/frame.py\", line 4107, in __getitem__\n",
      "    indexer = self.columns.get_loc(key)\n",
      "  File \"/Users/nayzawlin/Desktop/langara/ARC/PEH/PEH-cohort/pehenv/lib/python3.13/site-packages/pandas/core/indexes/base.py\", line 3819, in get_loc\n",
      "    raise KeyError(key) from err\n",
      "KeyError: 'E_Street'\n",
      "2025-08-21 13:28:58.625 Uncaught app execution\n",
      "Traceback (most recent call last):\n",
      "  File \"/Users/nayzawlin/Desktop/langara/ARC/PEH/PEH-cohort/pehenv/lib/python3.13/site-packages/streamlit/runtime/scriptrunner/exec_code.py\", line 128, in exec_func_with_error_handling\n",
      "    result = func()\n",
      "  File \"/Users/nayzawlin/Desktop/langara/ARC/PEH/PEH-cohort/pehenv/lib/python3.13/site-packages/streamlit/runtime/scriptrunner/script_runner.py\", line 669, in code_to_exec\n",
      "    exec(code, module.__dict__)  # noqa: S102\n",
      "    ~~~~^^^^^^^^^^^^^^^^^^^^^^^\n",
      "  File \"/Users/nayzawlin/Desktop/langara/ARC/PEH/PEH-cohort/bc_addresses_analysis.py\", line 800, in <module>\n",
      "    temp_df = temp_df.merge(move_freq, on=\"ClientID\", how=\"left\")\n",
      "  File \"/Users/nayzawlin/Desktop/langara/ARC/PEH/PEH-cohort/pehenv/lib/python3.13/site-packages/pandas/core/frame.py\", line 10839, in merge\n",
      "    return merge(\n",
      "        self,\n",
      "    ...<11 lines>...\n",
      "        validate=validate,\n",
      "    )\n",
      "  File \"/Users/nayzawlin/Desktop/langara/ARC/PEH/PEH-cohort/pehenv/lib/python3.13/site-packages/pandas/core/reshape/merge.py\", line 184, in merge\n",
      "    return op.get_result(copy=copy)\n",
      "           ~~~~~~~~~~~~~^^^^^^^^^^^\n",
      "  File \"/Users/nayzawlin/Desktop/langara/ARC/PEH/PEH-cohort/pehenv/lib/python3.13/site-packages/pandas/core/reshape/merge.py\", line 888, in get_result\n",
      "    result = self._reindex_and_concat(\n",
      "        join_index, left_indexer, right_indexer, copy=copy\n",
      "    )\n",
      "  File \"/Users/nayzawlin/Desktop/langara/ARC/PEH/PEH-cohort/pehenv/lib/python3.13/site-packages/pandas/core/reshape/merge.py\", line 840, in _reindex_and_concat\n",
      "    llabels, rlabels = _items_overlap_with_suffix(\n",
      "                       ~~~~~~~~~~~~~~~~~~~~~~~~~~^\n",
      "        self.left._info_axis, self.right._info_axis, self.suffixes\n",
      "        ^^^^^^^^^^^^^^^^^^^^^^^^^^^^^^^^^^^^^^^^^^^^^^^^^^^^^^^^^^\n",
      "    )\n",
      "    ^\n",
      "  File \"/Users/nayzawlin/Desktop/langara/ARC/PEH/PEH-cohort/pehenv/lib/python3.13/site-packages/pandas/core/reshape/merge.py\", line 2757, in _items_overlap_with_suffix\n",
      "    raise MergeError(\n",
      "    ...<2 lines>...\n",
      "    )\n",
      "pandas.errors.MergeError: Passing 'suffixes' which cause duplicate columns {'MoveFrequency_x'} is not allowed.\n",
      "2025-08-21 13:29:02.530 Uncaught app execution\n",
      "Traceback (most recent call last):\n",
      "  File \"/Users/nayzawlin/Desktop/langara/ARC/PEH/PEH-cohort/pehenv/lib/python3.13/site-packages/pandas/core/indexes/base.py\", line 3812, in get_loc\n",
      "    return self._engine.get_loc(casted_key)\n",
      "           ~~~~~~~~~~~~~~~~~~~~^^^^^^^^^^^^\n",
      "  File \"pandas/_libs/index.pyx\", line 167, in pandas._libs.index.IndexEngine.get_loc\n",
      "  File \"pandas/_libs/index.pyx\", line 196, in pandas._libs.index.IndexEngine.get_loc\n",
      "  File \"pandas/_libs/hashtable_class_helper.pxi\", line 7088, in pandas._libs.hashtable.PyObjectHashTable.get_item\n",
      "  File \"pandas/_libs/hashtable_class_helper.pxi\", line 7096, in pandas._libs.hashtable.PyObjectHashTable.get_item\n",
      "KeyError: 'PatientsAtAddress'\n",
      "\n",
      "The above exception was the direct cause of the following exception:\n",
      "\n",
      "Traceback (most recent call last):\n",
      "  File \"/Users/nayzawlin/Desktop/langara/ARC/PEH/PEH-cohort/pehenv/lib/python3.13/site-packages/streamlit/runtime/scriptrunner/exec_code.py\", line 128, in exec_func_with_error_handling\n",
      "    result = func()\n",
      "  File \"/Users/nayzawlin/Desktop/langara/ARC/PEH/PEH-cohort/pehenv/lib/python3.13/site-packages/streamlit/runtime/scriptrunner/script_runner.py\", line 669, in code_to_exec\n",
      "    exec(code, module.__dict__)  # noqa: S102\n",
      "    ~~~~^^^^^^^^^^^^^^^^^^^^^^^\n",
      "  File \"/Users/nayzawlin/Desktop/langara/ARC/PEH/PEH-cohort/bc_addresses_analysis.py\", line 982, in <module>\n",
      "    max_patients = temp_df_address['PatientsAtAddress'].max()\n",
      "                   ~~~~~~~~~~~~~~~^^^^^^^^^^^^^^^^^^^^^\n",
      "  File \"/Users/nayzawlin/Desktop/langara/ARC/PEH/PEH-cohort/pehenv/lib/python3.13/site-packages/pandas/core/frame.py\", line 4107, in __getitem__\n",
      "    indexer = self.columns.get_loc(key)\n",
      "  File \"/Users/nayzawlin/Desktop/langara/ARC/PEH/PEH-cohort/pehenv/lib/python3.13/site-packages/pandas/core/indexes/base.py\", line 3819, in get_loc\n",
      "    raise KeyError(key) from err\n",
      "KeyError: 'PatientsAtAddress'\n",
      "2025-08-21 13:29:09.090 Uncaught app execution\n",
      "Traceback (most recent call last):\n",
      "  File \"/Users/nayzawlin/Desktop/langara/ARC/PEH/PEH-cohort/pehenv/lib/python3.13/site-packages/streamlit/runtime/scriptrunner/exec_code.py\", line 128, in exec_func_with_error_handling\n",
      "    result = func()\n",
      "  File \"/Users/nayzawlin/Desktop/langara/ARC/PEH/PEH-cohort/pehenv/lib/python3.13/site-packages/streamlit/runtime/scriptrunner/script_runner.py\", line 669, in code_to_exec\n",
      "    exec(code, module.__dict__)  # noqa: S102\n",
      "    ~~~~^^^^^^^^^^^^^^^^^^^^^^^\n",
      "  File \"/Users/nayzawlin/Desktop/langara/ARC/PEH/PEH-cohort/bc_addresses_analysis.py\", line 800, in <module>\n",
      "    temp_df = temp_df.merge(move_freq, on=\"ClientID\", how=\"left\")\n",
      "  File \"/Users/nayzawlin/Desktop/langara/ARC/PEH/PEH-cohort/pehenv/lib/python3.13/site-packages/pandas/core/frame.py\", line 10839, in merge\n",
      "    return merge(\n",
      "        self,\n",
      "    ...<11 lines>...\n",
      "        validate=validate,\n",
      "    )\n",
      "  File \"/Users/nayzawlin/Desktop/langara/ARC/PEH/PEH-cohort/pehenv/lib/python3.13/site-packages/pandas/core/reshape/merge.py\", line 184, in merge\n",
      "    return op.get_result(copy=copy)\n",
      "           ~~~~~~~~~~~~~^^^^^^^^^^^\n",
      "  File \"/Users/nayzawlin/Desktop/langara/ARC/PEH/PEH-cohort/pehenv/lib/python3.13/site-packages/pandas/core/reshape/merge.py\", line 888, in get_result\n",
      "    result = self._reindex_and_concat(\n",
      "        join_index, left_indexer, right_indexer, copy=copy\n",
      "    )\n",
      "  File \"/Users/nayzawlin/Desktop/langara/ARC/PEH/PEH-cohort/pehenv/lib/python3.13/site-packages/pandas/core/reshape/merge.py\", line 840, in _reindex_and_concat\n",
      "    llabels, rlabels = _items_overlap_with_suffix(\n",
      "                       ~~~~~~~~~~~~~~~~~~~~~~~~~~^\n",
      "        self.left._info_axis, self.right._info_axis, self.suffixes\n",
      "        ^^^^^^^^^^^^^^^^^^^^^^^^^^^^^^^^^^^^^^^^^^^^^^^^^^^^^^^^^^\n",
      "    )\n",
      "    ^\n",
      "  File \"/Users/nayzawlin/Desktop/langara/ARC/PEH/PEH-cohort/pehenv/lib/python3.13/site-packages/pandas/core/reshape/merge.py\", line 2757, in _items_overlap_with_suffix\n",
      "    raise MergeError(\n",
      "    ...<2 lines>...\n",
      "    )\n",
      "pandas.errors.MergeError: Passing 'suffixes' which cause duplicate columns {'MoveFrequency_x'} is not allowed.\n",
      "2025-08-21 13:31:33.405 Uncaught app execution\n",
      "Traceback (most recent call last):\n",
      "  File \"/Users/nayzawlin/Desktop/langara/ARC/PEH/PEH-cohort/pehenv/lib/python3.13/site-packages/streamlit/runtime/scriptrunner/exec_code.py\", line 128, in exec_func_with_error_handling\n",
      "    result = func()\n",
      "  File \"/Users/nayzawlin/Desktop/langara/ARC/PEH/PEH-cohort/pehenv/lib/python3.13/site-packages/streamlit/runtime/scriptrunner/script_runner.py\", line 669, in code_to_exec\n",
      "    exec(code, module.__dict__)  # noqa: S102\n",
      "    ~~~~^^^^^^^^^^^^^^^^^^^^^^^\n",
      "  File \"/Users/nayzawlin/Desktop/langara/ARC/PEH/PEH-cohort/bc_addresses_analysis.py\", line 800, in <module>\n",
      "    temp_df = temp_df.merge(move_freq, on=\"ClientID\", how=\"left\")\n",
      "  File \"/Users/nayzawlin/Desktop/langara/ARC/PEH/PEH-cohort/pehenv/lib/python3.13/site-packages/pandas/core/frame.py\", line 10839, in merge\n",
      "    return merge(\n",
      "        self,\n",
      "    ...<11 lines>...\n",
      "        validate=validate,\n",
      "    )\n",
      "  File \"/Users/nayzawlin/Desktop/langara/ARC/PEH/PEH-cohort/pehenv/lib/python3.13/site-packages/pandas/core/reshape/merge.py\", line 184, in merge\n",
      "    return op.get_result(copy=copy)\n",
      "           ~~~~~~~~~~~~~^^^^^^^^^^^\n",
      "  File \"/Users/nayzawlin/Desktop/langara/ARC/PEH/PEH-cohort/pehenv/lib/python3.13/site-packages/pandas/core/reshape/merge.py\", line 888, in get_result\n",
      "    result = self._reindex_and_concat(\n",
      "        join_index, left_indexer, right_indexer, copy=copy\n",
      "    )\n",
      "  File \"/Users/nayzawlin/Desktop/langara/ARC/PEH/PEH-cohort/pehenv/lib/python3.13/site-packages/pandas/core/reshape/merge.py\", line 840, in _reindex_and_concat\n",
      "    llabels, rlabels = _items_overlap_with_suffix(\n",
      "                       ~~~~~~~~~~~~~~~~~~~~~~~~~~^\n",
      "        self.left._info_axis, self.right._info_axis, self.suffixes\n",
      "        ^^^^^^^^^^^^^^^^^^^^^^^^^^^^^^^^^^^^^^^^^^^^^^^^^^^^^^^^^^\n",
      "    )\n",
      "    ^\n",
      "  File \"/Users/nayzawlin/Desktop/langara/ARC/PEH/PEH-cohort/pehenv/lib/python3.13/site-packages/pandas/core/reshape/merge.py\", line 2757, in _items_overlap_with_suffix\n",
      "    raise MergeError(\n",
      "    ...<2 lines>...\n",
      "    )\n",
      "pandas.errors.MergeError: Passing 'suffixes' which cause duplicate columns {'MoveFrequency_x'} is not allowed.\n",
      "2025-08-21 14:07:54.107 Uncaught app execution\n",
      "Traceback (most recent call last):\n",
      "  File \"/Users/nayzawlin/Desktop/langara/ARC/PEH/PEH-cohort/pehenv/lib/python3.13/site-packages/streamlit/runtime/scriptrunner/exec_code.py\", line 128, in exec_func_with_error_handling\n",
      "    result = func()\n",
      "  File \"/Users/nayzawlin/Desktop/langara/ARC/PEH/PEH-cohort/pehenv/lib/python3.13/site-packages/streamlit/runtime/scriptrunner/script_runner.py\", line 669, in code_to_exec\n",
      "    exec(code, module.__dict__)  # noqa: S102\n",
      "    ~~~~^^^^^^^^^^^^^^^^^^^^^^^\n",
      "  File \"/Users/nayzawlin/Desktop/langara/ARC/PEH/PEH-cohort/bc_addresses_analysis.py\", line 818, in <module>\n",
      "    temp_df[\"row_has_missing\"] = temp_df[incomplete_fields].isnull().any(axis=1)\n",
      "                                 ~~~~~~~^^^^^^^^^^^^^^^^^^^\n",
      "  File \"/Users/nayzawlin/Desktop/langara/ARC/PEH/PEH-cohort/pehenv/lib/python3.13/site-packages/pandas/core/frame.py\", line 4113, in __getitem__\n",
      "    indexer = self.columns._get_indexer_strict(key, \"columns\")[1]\n",
      "              ~~~~~~~~~~~~~~~~~~~~~~~~~~~~~~~~^^^^^^^^^^^^^^^^\n",
      "  File \"/Users/nayzawlin/Desktop/langara/ARC/PEH/PEH-cohort/pehenv/lib/python3.13/site-packages/pandas/core/indexes/base.py\", line 6212, in _get_indexer_strict\n",
      "    self._raise_if_missing(keyarr, indexer, axis_name)\n",
      "    ~~~~~~~~~~~~~~~~~~~~~~^^^^^^^^^^^^^^^^^^^^^^^^^^^^\n",
      "  File \"/Users/nayzawlin/Desktop/langara/ARC/PEH/PEH-cohort/pehenv/lib/python3.13/site-packages/pandas/core/indexes/base.py\", line 6261, in _raise_if_missing\n",
      "    raise KeyError(f\"None of [{key}] are in the [{axis_name}]\")\n",
      "KeyError: \"None of [Index(['E_Street', 'E_StreetType', 'E_PostalCode', 'E_City'], dtype='object')] are in the [columns]\"\n",
      "2025-08-21 14:09:15.342 Uncaught app execution\n",
      "Traceback (most recent call last):\n",
      "  File \"/Users/nayzawlin/Desktop/langara/ARC/PEH/PEH-cohort/pehenv/lib/python3.13/site-packages/streamlit/runtime/scriptrunner/exec_code.py\", line 128, in exec_func_with_error_handling\n",
      "    result = func()\n",
      "  File \"/Users/nayzawlin/Desktop/langara/ARC/PEH/PEH-cohort/pehenv/lib/python3.13/site-packages/streamlit/runtime/scriptrunner/script_runner.py\", line 669, in code_to_exec\n",
      "    exec(code, module.__dict__)  # noqa: S102\n",
      "    ~~~~^^^^^^^^^^^^^^^^^^^^^^^\n",
      "  File \"/Users/nayzawlin/Desktop/langara/ARC/PEH/PEH-cohort/bc_addresses_analysis.py\", line 818, in <module>\n",
      "    temp_df[\"row_has_missing\"] = temp_df[incomplete_fields].isnull().any(axis=1)\n",
      "                                 ~~~~~~~^^^^^^^^^^^^^^^^^^^\n",
      "  File \"/Users/nayzawlin/Desktop/langara/ARC/PEH/PEH-cohort/pehenv/lib/python3.13/site-packages/pandas/core/frame.py\", line 4113, in __getitem__\n",
      "    indexer = self.columns._get_indexer_strict(key, \"columns\")[1]\n",
      "              ~~~~~~~~~~~~~~~~~~~~~~~~~~~~~~~~^^^^^^^^^^^^^^^^\n",
      "  File \"/Users/nayzawlin/Desktop/langara/ARC/PEH/PEH-cohort/pehenv/lib/python3.13/site-packages/pandas/core/indexes/base.py\", line 6212, in _get_indexer_strict\n",
      "    self._raise_if_missing(keyarr, indexer, axis_name)\n",
      "    ~~~~~~~~~~~~~~~~~~~~~~^^^^^^^^^^^^^^^^^^^^^^^^^^^^\n",
      "  File \"/Users/nayzawlin/Desktop/langara/ARC/PEH/PEH-cohort/pehenv/lib/python3.13/site-packages/pandas/core/indexes/base.py\", line 6261, in _raise_if_missing\n",
      "    raise KeyError(f\"None of [{key}] are in the [{axis_name}]\")\n",
      "KeyError: \"None of [Index(['E_Street', 'E_StreetType', 'E_PostalCode', 'E_City'], dtype='object')] are in the [columns]\"\n",
      "2025-08-21 15:10:17.765 Serialization of dataframe to Arrow table was unsuccessful. Applying automatic fixes for column types to make the dataframe Arrow-compatible.\n",
      "Traceback (most recent call last):\n",
      "  File \"/Users/nayzawlin/Desktop/langara/ARC/PEH/PEH-cohort/pehenv/lib/python3.13/site-packages/streamlit/dataframe_util.py\", line 821, in convert_pandas_df_to_arrow_bytes\n",
      "    table = pa.Table.from_pandas(df)\n",
      "  File \"pyarrow/table.pxi\", line 4795, in pyarrow.lib.Table.from_pandas\n",
      "  File \"/Users/nayzawlin/Desktop/langara/ARC/PEH/PEH-cohort/pehenv/lib/python3.13/site-packages/pyarrow/pandas_compat.py\", line 637, in dataframe_to_arrays\n",
      "    arrays = [convert_column(c, f)\n",
      "              ~~~~~~~~~~~~~~^^^^^^\n",
      "  File \"/Users/nayzawlin/Desktop/langara/ARC/PEH/PEH-cohort/pehenv/lib/python3.13/site-packages/pyarrow/pandas_compat.py\", line 625, in convert_column\n",
      "    raise e\n",
      "  File \"/Users/nayzawlin/Desktop/langara/ARC/PEH/PEH-cohort/pehenv/lib/python3.13/site-packages/pyarrow/pandas_compat.py\", line 619, in convert_column\n",
      "    result = pa.array(col, type=type_, from_pandas=True, safe=safe)\n",
      "  File \"pyarrow/array.pxi\", line 365, in pyarrow.lib.array\n",
      "  File \"pyarrow/array.pxi\", line 91, in pyarrow.lib._ndarray_to_array\n",
      "  File \"pyarrow/error.pxi\", line 92, in pyarrow.lib.check_status\n",
      "pyarrow.lib.ArrowInvalid: (\"Could not convert dtype('int64') with type numpy.dtypes.Int64DType: did not recognize Python value type when inferring an Arrow data type\", 'Conversion failed for column 0 with type object')\n",
      "2025-08-21 15:10:23.237 Serialization of dataframe to Arrow table was unsuccessful. Applying automatic fixes for column types to make the dataframe Arrow-compatible.\n",
      "Traceback (most recent call last):\n",
      "  File \"/Users/nayzawlin/Desktop/langara/ARC/PEH/PEH-cohort/pehenv/lib/python3.13/site-packages/streamlit/dataframe_util.py\", line 821, in convert_pandas_df_to_arrow_bytes\n",
      "    table = pa.Table.from_pandas(df)\n",
      "  File \"pyarrow/table.pxi\", line 4795, in pyarrow.lib.Table.from_pandas\n",
      "  File \"/Users/nayzawlin/Desktop/langara/ARC/PEH/PEH-cohort/pehenv/lib/python3.13/site-packages/pyarrow/pandas_compat.py\", line 637, in dataframe_to_arrays\n",
      "    arrays = [convert_column(c, f)\n",
      "              ~~~~~~~~~~~~~~^^^^^^\n",
      "  File \"/Users/nayzawlin/Desktop/langara/ARC/PEH/PEH-cohort/pehenv/lib/python3.13/site-packages/pyarrow/pandas_compat.py\", line 625, in convert_column\n",
      "    raise e\n",
      "  File \"/Users/nayzawlin/Desktop/langara/ARC/PEH/PEH-cohort/pehenv/lib/python3.13/site-packages/pyarrow/pandas_compat.py\", line 619, in convert_column\n",
      "    result = pa.array(col, type=type_, from_pandas=True, safe=safe)\n",
      "  File \"pyarrow/array.pxi\", line 365, in pyarrow.lib.array\n",
      "  File \"pyarrow/array.pxi\", line 91, in pyarrow.lib._ndarray_to_array\n",
      "  File \"pyarrow/error.pxi\", line 92, in pyarrow.lib.check_status\n",
      "pyarrow.lib.ArrowInvalid: (\"Could not convert dtype('int64') with type numpy.dtypes.Int64DType: did not recognize Python value type when inferring an Arrow data type\", 'Conversion failed for column 0 with type object')\n",
      "2025-08-21 15:10:24.085 Serialization of dataframe to Arrow table was unsuccessful. Applying automatic fixes for column types to make the dataframe Arrow-compatible.\n",
      "Traceback (most recent call last):\n",
      "  File \"/Users/nayzawlin/Desktop/langara/ARC/PEH/PEH-cohort/pehenv/lib/python3.13/site-packages/streamlit/dataframe_util.py\", line 821, in convert_pandas_df_to_arrow_bytes\n",
      "    table = pa.Table.from_pandas(df)\n",
      "  File \"pyarrow/table.pxi\", line 4795, in pyarrow.lib.Table.from_pandas\n",
      "  File \"/Users/nayzawlin/Desktop/langara/ARC/PEH/PEH-cohort/pehenv/lib/python3.13/site-packages/pyarrow/pandas_compat.py\", line 637, in dataframe_to_arrays\n",
      "    arrays = [convert_column(c, f)\n",
      "              ~~~~~~~~~~~~~~^^^^^^\n",
      "  File \"/Users/nayzawlin/Desktop/langara/ARC/PEH/PEH-cohort/pehenv/lib/python3.13/site-packages/pyarrow/pandas_compat.py\", line 625, in convert_column\n",
      "    raise e\n",
      "  File \"/Users/nayzawlin/Desktop/langara/ARC/PEH/PEH-cohort/pehenv/lib/python3.13/site-packages/pyarrow/pandas_compat.py\", line 619, in convert_column\n",
      "    result = pa.array(col, type=type_, from_pandas=True, safe=safe)\n",
      "  File \"pyarrow/array.pxi\", line 365, in pyarrow.lib.array\n",
      "  File \"pyarrow/array.pxi\", line 91, in pyarrow.lib._ndarray_to_array\n",
      "  File \"pyarrow/error.pxi\", line 92, in pyarrow.lib.check_status\n",
      "pyarrow.lib.ArrowInvalid: (\"Could not convert dtype('int64') with type numpy.dtypes.Int64DType: did not recognize Python value type when inferring an Arrow data type\", 'Conversion failed for column 0 with type object')\n",
      "2025-08-21 15:10:24.696 Serialization of dataframe to Arrow table was unsuccessful. Applying automatic fixes for column types to make the dataframe Arrow-compatible.\n",
      "Traceback (most recent call last):\n",
      "  File \"/Users/nayzawlin/Desktop/langara/ARC/PEH/PEH-cohort/pehenv/lib/python3.13/site-packages/streamlit/dataframe_util.py\", line 821, in convert_pandas_df_to_arrow_bytes\n",
      "    table = pa.Table.from_pandas(df)\n",
      "  File \"pyarrow/table.pxi\", line 4795, in pyarrow.lib.Table.from_pandas\n",
      "  File \"/Users/nayzawlin/Desktop/langara/ARC/PEH/PEH-cohort/pehenv/lib/python3.13/site-packages/pyarrow/pandas_compat.py\", line 637, in dataframe_to_arrays\n",
      "    arrays = [convert_column(c, f)\n",
      "              ~~~~~~~~~~~~~~^^^^^^\n",
      "  File \"/Users/nayzawlin/Desktop/langara/ARC/PEH/PEH-cohort/pehenv/lib/python3.13/site-packages/pyarrow/pandas_compat.py\", line 625, in convert_column\n",
      "    raise e\n",
      "  File \"/Users/nayzawlin/Desktop/langara/ARC/PEH/PEH-cohort/pehenv/lib/python3.13/site-packages/pyarrow/pandas_compat.py\", line 619, in convert_column\n",
      "    result = pa.array(col, type=type_, from_pandas=True, safe=safe)\n",
      "  File \"pyarrow/array.pxi\", line 365, in pyarrow.lib.array\n",
      "  File \"pyarrow/array.pxi\", line 91, in pyarrow.lib._ndarray_to_array\n",
      "  File \"pyarrow/error.pxi\", line 92, in pyarrow.lib.check_status\n",
      "pyarrow.lib.ArrowInvalid: (\"Could not convert dtype('int64') with type numpy.dtypes.Int64DType: did not recognize Python value type when inferring an Arrow data type\", 'Conversion failed for column 0 with type object')\n",
      "2025-08-21 15:10:25.320 Serialization of dataframe to Arrow table was unsuccessful. Applying automatic fixes for column types to make the dataframe Arrow-compatible.\n",
      "Traceback (most recent call last):\n",
      "  File \"/Users/nayzawlin/Desktop/langara/ARC/PEH/PEH-cohort/pehenv/lib/python3.13/site-packages/streamlit/dataframe_util.py\", line 821, in convert_pandas_df_to_arrow_bytes\n",
      "    table = pa.Table.from_pandas(df)\n",
      "  File \"pyarrow/table.pxi\", line 4795, in pyarrow.lib.Table.from_pandas\n",
      "  File \"/Users/nayzawlin/Desktop/langara/ARC/PEH/PEH-cohort/pehenv/lib/python3.13/site-packages/pyarrow/pandas_compat.py\", line 637, in dataframe_to_arrays\n",
      "    arrays = [convert_column(c, f)\n",
      "              ~~~~~~~~~~~~~~^^^^^^\n",
      "  File \"/Users/nayzawlin/Desktop/langara/ARC/PEH/PEH-cohort/pehenv/lib/python3.13/site-packages/pyarrow/pandas_compat.py\", line 625, in convert_column\n",
      "    raise e\n",
      "  File \"/Users/nayzawlin/Desktop/langara/ARC/PEH/PEH-cohort/pehenv/lib/python3.13/site-packages/pyarrow/pandas_compat.py\", line 619, in convert_column\n",
      "    result = pa.array(col, type=type_, from_pandas=True, safe=safe)\n",
      "  File \"pyarrow/array.pxi\", line 365, in pyarrow.lib.array\n",
      "  File \"pyarrow/array.pxi\", line 91, in pyarrow.lib._ndarray_to_array\n",
      "  File \"pyarrow/error.pxi\", line 92, in pyarrow.lib.check_status\n",
      "pyarrow.lib.ArrowInvalid: (\"Could not convert dtype('int64') with type numpy.dtypes.Int64DType: did not recognize Python value type when inferring an Arrow data type\", 'Conversion failed for column 0 with type object')\n",
      "2025-08-21 15:10:32.785 Serialization of dataframe to Arrow table was unsuccessful. Applying automatic fixes for column types to make the dataframe Arrow-compatible.\n",
      "Traceback (most recent call last):\n",
      "  File \"/Users/nayzawlin/Desktop/langara/ARC/PEH/PEH-cohort/pehenv/lib/python3.13/site-packages/streamlit/dataframe_util.py\", line 821, in convert_pandas_df_to_arrow_bytes\n",
      "    table = pa.Table.from_pandas(df)\n",
      "  File \"pyarrow/table.pxi\", line 4795, in pyarrow.lib.Table.from_pandas\n",
      "  File \"/Users/nayzawlin/Desktop/langara/ARC/PEH/PEH-cohort/pehenv/lib/python3.13/site-packages/pyarrow/pandas_compat.py\", line 637, in dataframe_to_arrays\n",
      "    arrays = [convert_column(c, f)\n",
      "              ~~~~~~~~~~~~~~^^^^^^\n",
      "  File \"/Users/nayzawlin/Desktop/langara/ARC/PEH/PEH-cohort/pehenv/lib/python3.13/site-packages/pyarrow/pandas_compat.py\", line 625, in convert_column\n",
      "    raise e\n",
      "  File \"/Users/nayzawlin/Desktop/langara/ARC/PEH/PEH-cohort/pehenv/lib/python3.13/site-packages/pyarrow/pandas_compat.py\", line 619, in convert_column\n",
      "    result = pa.array(col, type=type_, from_pandas=True, safe=safe)\n",
      "  File \"pyarrow/array.pxi\", line 365, in pyarrow.lib.array\n",
      "  File \"pyarrow/array.pxi\", line 91, in pyarrow.lib._ndarray_to_array\n",
      "  File \"pyarrow/error.pxi\", line 92, in pyarrow.lib.check_status\n",
      "pyarrow.lib.ArrowInvalid: (\"Could not convert dtype('int64') with type numpy.dtypes.Int64DType: did not recognize Python value type when inferring an Arrow data type\", 'Conversion failed for column 0 with type object')\n",
      "2025-08-21 15:10:39.728 Serialization of dataframe to Arrow table was unsuccessful. Applying automatic fixes for column types to make the dataframe Arrow-compatible.\n",
      "Traceback (most recent call last):\n",
      "  File \"/Users/nayzawlin/Desktop/langara/ARC/PEH/PEH-cohort/pehenv/lib/python3.13/site-packages/streamlit/dataframe_util.py\", line 821, in convert_pandas_df_to_arrow_bytes\n",
      "    table = pa.Table.from_pandas(df)\n",
      "  File \"pyarrow/table.pxi\", line 4795, in pyarrow.lib.Table.from_pandas\n",
      "  File \"/Users/nayzawlin/Desktop/langara/ARC/PEH/PEH-cohort/pehenv/lib/python3.13/site-packages/pyarrow/pandas_compat.py\", line 637, in dataframe_to_arrays\n",
      "    arrays = [convert_column(c, f)\n",
      "              ~~~~~~~~~~~~~~^^^^^^\n",
      "  File \"/Users/nayzawlin/Desktop/langara/ARC/PEH/PEH-cohort/pehenv/lib/python3.13/site-packages/pyarrow/pandas_compat.py\", line 625, in convert_column\n",
      "    raise e\n",
      "  File \"/Users/nayzawlin/Desktop/langara/ARC/PEH/PEH-cohort/pehenv/lib/python3.13/site-packages/pyarrow/pandas_compat.py\", line 619, in convert_column\n",
      "    result = pa.array(col, type=type_, from_pandas=True, safe=safe)\n",
      "  File \"pyarrow/array.pxi\", line 365, in pyarrow.lib.array\n",
      "  File \"pyarrow/array.pxi\", line 91, in pyarrow.lib._ndarray_to_array\n",
      "  File \"pyarrow/error.pxi\", line 92, in pyarrow.lib.check_status\n",
      "pyarrow.lib.ArrowInvalid: (\"Could not convert dtype('int64') with type numpy.dtypes.Int64DType: did not recognize Python value type when inferring an Arrow data type\", 'Conversion failed for column 0 with type object')\n",
      "2025-08-21 15:10:47.987 Serialization of dataframe to Arrow table was unsuccessful. Applying automatic fixes for column types to make the dataframe Arrow-compatible.\n",
      "Traceback (most recent call last):\n",
      "  File \"/Users/nayzawlin/Desktop/langara/ARC/PEH/PEH-cohort/pehenv/lib/python3.13/site-packages/streamlit/dataframe_util.py\", line 821, in convert_pandas_df_to_arrow_bytes\n",
      "    table = pa.Table.from_pandas(df)\n",
      "  File \"pyarrow/table.pxi\", line 4795, in pyarrow.lib.Table.from_pandas\n",
      "  File \"/Users/nayzawlin/Desktop/langara/ARC/PEH/PEH-cohort/pehenv/lib/python3.13/site-packages/pyarrow/pandas_compat.py\", line 637, in dataframe_to_arrays\n",
      "    arrays = [convert_column(c, f)\n",
      "              ~~~~~~~~~~~~~~^^^^^^\n",
      "  File \"/Users/nayzawlin/Desktop/langara/ARC/PEH/PEH-cohort/pehenv/lib/python3.13/site-packages/pyarrow/pandas_compat.py\", line 625, in convert_column\n",
      "    raise e\n",
      "  File \"/Users/nayzawlin/Desktop/langara/ARC/PEH/PEH-cohort/pehenv/lib/python3.13/site-packages/pyarrow/pandas_compat.py\", line 619, in convert_column\n",
      "    result = pa.array(col, type=type_, from_pandas=True, safe=safe)\n",
      "  File \"pyarrow/array.pxi\", line 365, in pyarrow.lib.array\n",
      "  File \"pyarrow/array.pxi\", line 91, in pyarrow.lib._ndarray_to_array\n",
      "  File \"pyarrow/error.pxi\", line 92, in pyarrow.lib.check_status\n",
      "pyarrow.lib.ArrowInvalid: (\"Could not convert dtype('int64') with type numpy.dtypes.Int64DType: did not recognize Python value type when inferring an Arrow data type\", 'Conversion failed for column 0 with type object')\n",
      "2025-08-21 15:10:50.084 Serialization of dataframe to Arrow table was unsuccessful. Applying automatic fixes for column types to make the dataframe Arrow-compatible.\n",
      "Traceback (most recent call last):\n",
      "  File \"/Users/nayzawlin/Desktop/langara/ARC/PEH/PEH-cohort/pehenv/lib/python3.13/site-packages/streamlit/dataframe_util.py\", line 821, in convert_pandas_df_to_arrow_bytes\n",
      "    table = pa.Table.from_pandas(df)\n",
      "  File \"pyarrow/table.pxi\", line 4795, in pyarrow.lib.Table.from_pandas\n",
      "  File \"/Users/nayzawlin/Desktop/langara/ARC/PEH/PEH-cohort/pehenv/lib/python3.13/site-packages/pyarrow/pandas_compat.py\", line 637, in dataframe_to_arrays\n",
      "    arrays = [convert_column(c, f)\n",
      "              ~~~~~~~~~~~~~~^^^^^^\n",
      "  File \"/Users/nayzawlin/Desktop/langara/ARC/PEH/PEH-cohort/pehenv/lib/python3.13/site-packages/pyarrow/pandas_compat.py\", line 625, in convert_column\n",
      "    raise e\n",
      "  File \"/Users/nayzawlin/Desktop/langara/ARC/PEH/PEH-cohort/pehenv/lib/python3.13/site-packages/pyarrow/pandas_compat.py\", line 619, in convert_column\n",
      "    result = pa.array(col, type=type_, from_pandas=True, safe=safe)\n",
      "  File \"pyarrow/array.pxi\", line 365, in pyarrow.lib.array\n",
      "  File \"pyarrow/array.pxi\", line 91, in pyarrow.lib._ndarray_to_array\n",
      "  File \"pyarrow/error.pxi\", line 92, in pyarrow.lib.check_status\n",
      "pyarrow.lib.ArrowInvalid: (\"Could not convert dtype('int64') with type numpy.dtypes.Int64DType: did not recognize Python value type when inferring an Arrow data type\", 'Conversion failed for column 0 with type object')\n",
      "2025-08-21 15:10:56.970 Serialization of dataframe to Arrow table was unsuccessful. Applying automatic fixes for column types to make the dataframe Arrow-compatible.\n",
      "Traceback (most recent call last):\n",
      "  File \"/Users/nayzawlin/Desktop/langara/ARC/PEH/PEH-cohort/pehenv/lib/python3.13/site-packages/streamlit/dataframe_util.py\", line 821, in convert_pandas_df_to_arrow_bytes\n",
      "    table = pa.Table.from_pandas(df)\n",
      "  File \"pyarrow/table.pxi\", line 4795, in pyarrow.lib.Table.from_pandas\n",
      "  File \"/Users/nayzawlin/Desktop/langara/ARC/PEH/PEH-cohort/pehenv/lib/python3.13/site-packages/pyarrow/pandas_compat.py\", line 637, in dataframe_to_arrays\n",
      "    arrays = [convert_column(c, f)\n",
      "              ~~~~~~~~~~~~~~^^^^^^\n",
      "  File \"/Users/nayzawlin/Desktop/langara/ARC/PEH/PEH-cohort/pehenv/lib/python3.13/site-packages/pyarrow/pandas_compat.py\", line 625, in convert_column\n",
      "    raise e\n",
      "  File \"/Users/nayzawlin/Desktop/langara/ARC/PEH/PEH-cohort/pehenv/lib/python3.13/site-packages/pyarrow/pandas_compat.py\", line 619, in convert_column\n",
      "    result = pa.array(col, type=type_, from_pandas=True, safe=safe)\n",
      "  File \"pyarrow/array.pxi\", line 365, in pyarrow.lib.array\n",
      "  File \"pyarrow/array.pxi\", line 91, in pyarrow.lib._ndarray_to_array\n",
      "  File \"pyarrow/error.pxi\", line 92, in pyarrow.lib.check_status\n",
      "pyarrow.lib.ArrowInvalid: (\"Could not convert dtype('int64') with type numpy.dtypes.Int64DType: did not recognize Python value type when inferring an Arrow data type\", 'Conversion failed for column 0 with type object')\n",
      "2025-08-21 15:10:58.586 Serialization of dataframe to Arrow table was unsuccessful. Applying automatic fixes for column types to make the dataframe Arrow-compatible.\n",
      "Traceback (most recent call last):\n",
      "  File \"/Users/nayzawlin/Desktop/langara/ARC/PEH/PEH-cohort/pehenv/lib/python3.13/site-packages/streamlit/dataframe_util.py\", line 821, in convert_pandas_df_to_arrow_bytes\n",
      "    table = pa.Table.from_pandas(df)\n",
      "  File \"pyarrow/table.pxi\", line 4795, in pyarrow.lib.Table.from_pandas\n",
      "  File \"/Users/nayzawlin/Desktop/langara/ARC/PEH/PEH-cohort/pehenv/lib/python3.13/site-packages/pyarrow/pandas_compat.py\", line 637, in dataframe_to_arrays\n",
      "    arrays = [convert_column(c, f)\n",
      "              ~~~~~~~~~~~~~~^^^^^^\n",
      "  File \"/Users/nayzawlin/Desktop/langara/ARC/PEH/PEH-cohort/pehenv/lib/python3.13/site-packages/pyarrow/pandas_compat.py\", line 625, in convert_column\n",
      "    raise e\n",
      "  File \"/Users/nayzawlin/Desktop/langara/ARC/PEH/PEH-cohort/pehenv/lib/python3.13/site-packages/pyarrow/pandas_compat.py\", line 619, in convert_column\n",
      "    result = pa.array(col, type=type_, from_pandas=True, safe=safe)\n",
      "  File \"pyarrow/array.pxi\", line 365, in pyarrow.lib.array\n",
      "  File \"pyarrow/array.pxi\", line 91, in pyarrow.lib._ndarray_to_array\n",
      "  File \"pyarrow/error.pxi\", line 92, in pyarrow.lib.check_status\n",
      "pyarrow.lib.ArrowInvalid: (\"Could not convert dtype('int64') with type numpy.dtypes.Int64DType: did not recognize Python value type when inferring an Arrow data type\", 'Conversion failed for column 0 with type object')\n",
      "2025-08-21 15:11:06.796 Serialization of dataframe to Arrow table was unsuccessful. Applying automatic fixes for column types to make the dataframe Arrow-compatible.\n",
      "Traceback (most recent call last):\n",
      "  File \"/Users/nayzawlin/Desktop/langara/ARC/PEH/PEH-cohort/pehenv/lib/python3.13/site-packages/streamlit/dataframe_util.py\", line 821, in convert_pandas_df_to_arrow_bytes\n",
      "    table = pa.Table.from_pandas(df)\n",
      "  File \"pyarrow/table.pxi\", line 4795, in pyarrow.lib.Table.from_pandas\n",
      "  File \"/Users/nayzawlin/Desktop/langara/ARC/PEH/PEH-cohort/pehenv/lib/python3.13/site-packages/pyarrow/pandas_compat.py\", line 637, in dataframe_to_arrays\n",
      "    arrays = [convert_column(c, f)\n",
      "              ~~~~~~~~~~~~~~^^^^^^\n",
      "  File \"/Users/nayzawlin/Desktop/langara/ARC/PEH/PEH-cohort/pehenv/lib/python3.13/site-packages/pyarrow/pandas_compat.py\", line 625, in convert_column\n",
      "    raise e\n",
      "  File \"/Users/nayzawlin/Desktop/langara/ARC/PEH/PEH-cohort/pehenv/lib/python3.13/site-packages/pyarrow/pandas_compat.py\", line 619, in convert_column\n",
      "    result = pa.array(col, type=type_, from_pandas=True, safe=safe)\n",
      "  File \"pyarrow/array.pxi\", line 365, in pyarrow.lib.array\n",
      "  File \"pyarrow/array.pxi\", line 91, in pyarrow.lib._ndarray_to_array\n",
      "  File \"pyarrow/error.pxi\", line 92, in pyarrow.lib.check_status\n",
      "pyarrow.lib.ArrowInvalid: (\"Could not convert dtype('int64') with type numpy.dtypes.Int64DType: did not recognize Python value type when inferring an Arrow data type\", 'Conversion failed for column 0 with type object')\n",
      "2025-08-21 15:11:12.557 Serialization of dataframe to Arrow table was unsuccessful. Applying automatic fixes for column types to make the dataframe Arrow-compatible.\n",
      "Traceback (most recent call last):\n",
      "  File \"/Users/nayzawlin/Desktop/langara/ARC/PEH/PEH-cohort/pehenv/lib/python3.13/site-packages/streamlit/dataframe_util.py\", line 821, in convert_pandas_df_to_arrow_bytes\n",
      "    table = pa.Table.from_pandas(df)\n",
      "  File \"pyarrow/table.pxi\", line 4795, in pyarrow.lib.Table.from_pandas\n",
      "  File \"/Users/nayzawlin/Desktop/langara/ARC/PEH/PEH-cohort/pehenv/lib/python3.13/site-packages/pyarrow/pandas_compat.py\", line 637, in dataframe_to_arrays\n",
      "    arrays = [convert_column(c, f)\n",
      "              ~~~~~~~~~~~~~~^^^^^^\n",
      "  File \"/Users/nayzawlin/Desktop/langara/ARC/PEH/PEH-cohort/pehenv/lib/python3.13/site-packages/pyarrow/pandas_compat.py\", line 625, in convert_column\n",
      "    raise e\n",
      "  File \"/Users/nayzawlin/Desktop/langara/ARC/PEH/PEH-cohort/pehenv/lib/python3.13/site-packages/pyarrow/pandas_compat.py\", line 619, in convert_column\n",
      "    result = pa.array(col, type=type_, from_pandas=True, safe=safe)\n",
      "  File \"pyarrow/array.pxi\", line 365, in pyarrow.lib.array\n",
      "  File \"pyarrow/array.pxi\", line 91, in pyarrow.lib._ndarray_to_array\n",
      "  File \"pyarrow/error.pxi\", line 92, in pyarrow.lib.check_status\n",
      "pyarrow.lib.ArrowInvalid: (\"Could not convert dtype('int64') with type numpy.dtypes.Int64DType: did not recognize Python value type when inferring an Arrow data type\", 'Conversion failed for column 0 with type object')\n",
      "2025-08-21 15:11:45.477 Serialization of dataframe to Arrow table was unsuccessful. Applying automatic fixes for column types to make the dataframe Arrow-compatible.\n",
      "Traceback (most recent call last):\n",
      "  File \"/Users/nayzawlin/Desktop/langara/ARC/PEH/PEH-cohort/pehenv/lib/python3.13/site-packages/streamlit/dataframe_util.py\", line 821, in convert_pandas_df_to_arrow_bytes\n",
      "    table = pa.Table.from_pandas(df)\n",
      "  File \"pyarrow/table.pxi\", line 4795, in pyarrow.lib.Table.from_pandas\n",
      "  File \"/Users/nayzawlin/Desktop/langara/ARC/PEH/PEH-cohort/pehenv/lib/python3.13/site-packages/pyarrow/pandas_compat.py\", line 637, in dataframe_to_arrays\n",
      "    arrays = [convert_column(c, f)\n",
      "              ~~~~~~~~~~~~~~^^^^^^\n",
      "  File \"/Users/nayzawlin/Desktop/langara/ARC/PEH/PEH-cohort/pehenv/lib/python3.13/site-packages/pyarrow/pandas_compat.py\", line 625, in convert_column\n",
      "    raise e\n",
      "  File \"/Users/nayzawlin/Desktop/langara/ARC/PEH/PEH-cohort/pehenv/lib/python3.13/site-packages/pyarrow/pandas_compat.py\", line 619, in convert_column\n",
      "    result = pa.array(col, type=type_, from_pandas=True, safe=safe)\n",
      "  File \"pyarrow/array.pxi\", line 365, in pyarrow.lib.array\n",
      "  File \"pyarrow/array.pxi\", line 91, in pyarrow.lib._ndarray_to_array\n",
      "  File \"pyarrow/error.pxi\", line 92, in pyarrow.lib.check_status\n",
      "pyarrow.lib.ArrowInvalid: (\"Could not convert dtype('int64') with type numpy.dtypes.Int64DType: did not recognize Python value type when inferring an Arrow data type\", 'Conversion failed for column 0 with type object')\n",
      "2025-08-21 15:11:56.053 Serialization of dataframe to Arrow table was unsuccessful. Applying automatic fixes for column types to make the dataframe Arrow-compatible.\n",
      "Traceback (most recent call last):\n",
      "  File \"/Users/nayzawlin/Desktop/langara/ARC/PEH/PEH-cohort/pehenv/lib/python3.13/site-packages/streamlit/dataframe_util.py\", line 821, in convert_pandas_df_to_arrow_bytes\n",
      "    table = pa.Table.from_pandas(df)\n",
      "  File \"pyarrow/table.pxi\", line 4795, in pyarrow.lib.Table.from_pandas\n",
      "  File \"/Users/nayzawlin/Desktop/langara/ARC/PEH/PEH-cohort/pehenv/lib/python3.13/site-packages/pyarrow/pandas_compat.py\", line 637, in dataframe_to_arrays\n",
      "    arrays = [convert_column(c, f)\n",
      "              ~~~~~~~~~~~~~~^^^^^^\n",
      "  File \"/Users/nayzawlin/Desktop/langara/ARC/PEH/PEH-cohort/pehenv/lib/python3.13/site-packages/pyarrow/pandas_compat.py\", line 625, in convert_column\n",
      "    raise e\n",
      "  File \"/Users/nayzawlin/Desktop/langara/ARC/PEH/PEH-cohort/pehenv/lib/python3.13/site-packages/pyarrow/pandas_compat.py\", line 619, in convert_column\n",
      "    result = pa.array(col, type=type_, from_pandas=True, safe=safe)\n",
      "  File \"pyarrow/array.pxi\", line 365, in pyarrow.lib.array\n",
      "  File \"pyarrow/array.pxi\", line 91, in pyarrow.lib._ndarray_to_array\n",
      "  File \"pyarrow/error.pxi\", line 92, in pyarrow.lib.check_status\n",
      "pyarrow.lib.ArrowInvalid: (\"Could not convert dtype('int64') with type numpy.dtypes.Int64DType: did not recognize Python value type when inferring an Arrow data type\", 'Conversion failed for column 0 with type object')\n",
      "/Users/nayzawlin/Desktop/langara/ARC/PEH/PEH-cohort/pehenv/lib/python3.13/site-packages/seaborn/matrix.py:202: RuntimeWarning: All-NaN slice encountered\n",
      "  vmin = np.nanmin(calc_data)\n",
      "/Users/nayzawlin/Desktop/langara/ARC/PEH/PEH-cohort/pehenv/lib/python3.13/site-packages/seaborn/matrix.py:207: RuntimeWarning: All-NaN slice encountered\n",
      "  vmax = np.nanmax(calc_data)\n",
      "2025-08-21 15:12:01.161 Serialization of dataframe to Arrow table was unsuccessful. Applying automatic fixes for column types to make the dataframe Arrow-compatible.\n",
      "Traceback (most recent call last):\n",
      "  File \"/Users/nayzawlin/Desktop/langara/ARC/PEH/PEH-cohort/pehenv/lib/python3.13/site-packages/streamlit/dataframe_util.py\", line 821, in convert_pandas_df_to_arrow_bytes\n",
      "    table = pa.Table.from_pandas(df)\n",
      "  File \"pyarrow/table.pxi\", line 4795, in pyarrow.lib.Table.from_pandas\n",
      "  File \"/Users/nayzawlin/Desktop/langara/ARC/PEH/PEH-cohort/pehenv/lib/python3.13/site-packages/pyarrow/pandas_compat.py\", line 637, in dataframe_to_arrays\n",
      "    arrays = [convert_column(c, f)\n",
      "              ~~~~~~~~~~~~~~^^^^^^\n",
      "  File \"/Users/nayzawlin/Desktop/langara/ARC/PEH/PEH-cohort/pehenv/lib/python3.13/site-packages/pyarrow/pandas_compat.py\", line 625, in convert_column\n",
      "    raise e\n",
      "  File \"/Users/nayzawlin/Desktop/langara/ARC/PEH/PEH-cohort/pehenv/lib/python3.13/site-packages/pyarrow/pandas_compat.py\", line 619, in convert_column\n",
      "    result = pa.array(col, type=type_, from_pandas=True, safe=safe)\n",
      "  File \"pyarrow/array.pxi\", line 365, in pyarrow.lib.array\n",
      "  File \"pyarrow/array.pxi\", line 91, in pyarrow.lib._ndarray_to_array\n",
      "  File \"pyarrow/error.pxi\", line 92, in pyarrow.lib.check_status\n",
      "pyarrow.lib.ArrowInvalid: (\"Could not convert dtype('int64') with type numpy.dtypes.Int64DType: did not recognize Python value type when inferring an Arrow data type\", 'Conversion failed for column 0 with type object')\n",
      "2025-08-21 15:12:04.414 Serialization of dataframe to Arrow table was unsuccessful. Applying automatic fixes for column types to make the dataframe Arrow-compatible.\n",
      "Traceback (most recent call last):\n",
      "  File \"/Users/nayzawlin/Desktop/langara/ARC/PEH/PEH-cohort/pehenv/lib/python3.13/site-packages/streamlit/dataframe_util.py\", line 821, in convert_pandas_df_to_arrow_bytes\n",
      "    table = pa.Table.from_pandas(df)\n",
      "  File \"pyarrow/table.pxi\", line 4795, in pyarrow.lib.Table.from_pandas\n",
      "  File \"/Users/nayzawlin/Desktop/langara/ARC/PEH/PEH-cohort/pehenv/lib/python3.13/site-packages/pyarrow/pandas_compat.py\", line 637, in dataframe_to_arrays\n",
      "    arrays = [convert_column(c, f)\n",
      "              ~~~~~~~~~~~~~~^^^^^^\n",
      "  File \"/Users/nayzawlin/Desktop/langara/ARC/PEH/PEH-cohort/pehenv/lib/python3.13/site-packages/pyarrow/pandas_compat.py\", line 625, in convert_column\n",
      "    raise e\n",
      "  File \"/Users/nayzawlin/Desktop/langara/ARC/PEH/PEH-cohort/pehenv/lib/python3.13/site-packages/pyarrow/pandas_compat.py\", line 619, in convert_column\n",
      "    result = pa.array(col, type=type_, from_pandas=True, safe=safe)\n",
      "  File \"pyarrow/array.pxi\", line 365, in pyarrow.lib.array\n",
      "  File \"pyarrow/array.pxi\", line 91, in pyarrow.lib._ndarray_to_array\n",
      "  File \"pyarrow/error.pxi\", line 92, in pyarrow.lib.check_status\n",
      "pyarrow.lib.ArrowInvalid: (\"Could not convert dtype('int64') with type numpy.dtypes.Int64DType: did not recognize Python value type when inferring an Arrow data type\", 'Conversion failed for column 0 with type object')\n",
      "2025-08-21 15:12:08.749 Serialization of dataframe to Arrow table was unsuccessful. Applying automatic fixes for column types to make the dataframe Arrow-compatible.\n",
      "Traceback (most recent call last):\n",
      "  File \"/Users/nayzawlin/Desktop/langara/ARC/PEH/PEH-cohort/pehenv/lib/python3.13/site-packages/streamlit/dataframe_util.py\", line 821, in convert_pandas_df_to_arrow_bytes\n",
      "    table = pa.Table.from_pandas(df)\n",
      "  File \"pyarrow/table.pxi\", line 4795, in pyarrow.lib.Table.from_pandas\n",
      "  File \"/Users/nayzawlin/Desktop/langara/ARC/PEH/PEH-cohort/pehenv/lib/python3.13/site-packages/pyarrow/pandas_compat.py\", line 637, in dataframe_to_arrays\n",
      "    arrays = [convert_column(c, f)\n",
      "              ~~~~~~~~~~~~~~^^^^^^\n",
      "  File \"/Users/nayzawlin/Desktop/langara/ARC/PEH/PEH-cohort/pehenv/lib/python3.13/site-packages/pyarrow/pandas_compat.py\", line 625, in convert_column\n",
      "    raise e\n",
      "  File \"/Users/nayzawlin/Desktop/langara/ARC/PEH/PEH-cohort/pehenv/lib/python3.13/site-packages/pyarrow/pandas_compat.py\", line 619, in convert_column\n",
      "    result = pa.array(col, type=type_, from_pandas=True, safe=safe)\n",
      "  File \"pyarrow/array.pxi\", line 365, in pyarrow.lib.array\n",
      "  File \"pyarrow/array.pxi\", line 91, in pyarrow.lib._ndarray_to_array\n",
      "  File \"pyarrow/error.pxi\", line 92, in pyarrow.lib.check_status\n",
      "pyarrow.lib.ArrowInvalid: (\"Could not convert dtype('int64') with type numpy.dtypes.Int64DType: did not recognize Python value type when inferring an Arrow data type\", 'Conversion failed for column 0 with type object')\n",
      "2025-08-21 15:12:21.061 Serialization of dataframe to Arrow table was unsuccessful. Applying automatic fixes for column types to make the dataframe Arrow-compatible.\n",
      "Traceback (most recent call last):\n",
      "  File \"/Users/nayzawlin/Desktop/langara/ARC/PEH/PEH-cohort/pehenv/lib/python3.13/site-packages/streamlit/dataframe_util.py\", line 821, in convert_pandas_df_to_arrow_bytes\n",
      "    table = pa.Table.from_pandas(df)\n",
      "  File \"pyarrow/table.pxi\", line 4795, in pyarrow.lib.Table.from_pandas\n",
      "  File \"/Users/nayzawlin/Desktop/langara/ARC/PEH/PEH-cohort/pehenv/lib/python3.13/site-packages/pyarrow/pandas_compat.py\", line 637, in dataframe_to_arrays\n",
      "    arrays = [convert_column(c, f)\n",
      "              ~~~~~~~~~~~~~~^^^^^^\n",
      "  File \"/Users/nayzawlin/Desktop/langara/ARC/PEH/PEH-cohort/pehenv/lib/python3.13/site-packages/pyarrow/pandas_compat.py\", line 625, in convert_column\n",
      "    raise e\n",
      "  File \"/Users/nayzawlin/Desktop/langara/ARC/PEH/PEH-cohort/pehenv/lib/python3.13/site-packages/pyarrow/pandas_compat.py\", line 619, in convert_column\n",
      "    result = pa.array(col, type=type_, from_pandas=True, safe=safe)\n",
      "  File \"pyarrow/array.pxi\", line 365, in pyarrow.lib.array\n",
      "  File \"pyarrow/array.pxi\", line 91, in pyarrow.lib._ndarray_to_array\n",
      "  File \"pyarrow/error.pxi\", line 92, in pyarrow.lib.check_status\n",
      "pyarrow.lib.ArrowInvalid: (\"Could not convert dtype('int64') with type numpy.dtypes.Int64DType: did not recognize Python value type when inferring an Arrow data type\", 'Conversion failed for column 0 with type object')\n",
      "2025-08-21 15:12:27.072 Serialization of dataframe to Arrow table was unsuccessful. Applying automatic fixes for column types to make the dataframe Arrow-compatible.\n",
      "Traceback (most recent call last):\n",
      "  File \"/Users/nayzawlin/Desktop/langara/ARC/PEH/PEH-cohort/pehenv/lib/python3.13/site-packages/streamlit/dataframe_util.py\", line 821, in convert_pandas_df_to_arrow_bytes\n",
      "    table = pa.Table.from_pandas(df)\n",
      "  File \"pyarrow/table.pxi\", line 4795, in pyarrow.lib.Table.from_pandas\n",
      "  File \"/Users/nayzawlin/Desktop/langara/ARC/PEH/PEH-cohort/pehenv/lib/python3.13/site-packages/pyarrow/pandas_compat.py\", line 637, in dataframe_to_arrays\n",
      "    arrays = [convert_column(c, f)\n",
      "              ~~~~~~~~~~~~~~^^^^^^\n",
      "  File \"/Users/nayzawlin/Desktop/langara/ARC/PEH/PEH-cohort/pehenv/lib/python3.13/site-packages/pyarrow/pandas_compat.py\", line 625, in convert_column\n",
      "    raise e\n",
      "  File \"/Users/nayzawlin/Desktop/langara/ARC/PEH/PEH-cohort/pehenv/lib/python3.13/site-packages/pyarrow/pandas_compat.py\", line 619, in convert_column\n",
      "    result = pa.array(col, type=type_, from_pandas=True, safe=safe)\n",
      "  File \"pyarrow/array.pxi\", line 365, in pyarrow.lib.array\n",
      "  File \"pyarrow/array.pxi\", line 91, in pyarrow.lib._ndarray_to_array\n",
      "  File \"pyarrow/error.pxi\", line 92, in pyarrow.lib.check_status\n",
      "pyarrow.lib.ArrowInvalid: (\"Could not convert dtype('int64') with type numpy.dtypes.Int64DType: did not recognize Python value type when inferring an Arrow data type\", 'Conversion failed for column 0 with type object')\n",
      "2025-08-21 15:12:31.162 Serialization of dataframe to Arrow table was unsuccessful. Applying automatic fixes for column types to make the dataframe Arrow-compatible.\n",
      "Traceback (most recent call last):\n",
      "  File \"/Users/nayzawlin/Desktop/langara/ARC/PEH/PEH-cohort/pehenv/lib/python3.13/site-packages/streamlit/dataframe_util.py\", line 821, in convert_pandas_df_to_arrow_bytes\n",
      "    table = pa.Table.from_pandas(df)\n",
      "  File \"pyarrow/table.pxi\", line 4795, in pyarrow.lib.Table.from_pandas\n",
      "  File \"/Users/nayzawlin/Desktop/langara/ARC/PEH/PEH-cohort/pehenv/lib/python3.13/site-packages/pyarrow/pandas_compat.py\", line 637, in dataframe_to_arrays\n",
      "    arrays = [convert_column(c, f)\n",
      "              ~~~~~~~~~~~~~~^^^^^^\n",
      "  File \"/Users/nayzawlin/Desktop/langara/ARC/PEH/PEH-cohort/pehenv/lib/python3.13/site-packages/pyarrow/pandas_compat.py\", line 625, in convert_column\n",
      "    raise e\n",
      "  File \"/Users/nayzawlin/Desktop/langara/ARC/PEH/PEH-cohort/pehenv/lib/python3.13/site-packages/pyarrow/pandas_compat.py\", line 619, in convert_column\n",
      "    result = pa.array(col, type=type_, from_pandas=True, safe=safe)\n",
      "  File \"pyarrow/array.pxi\", line 365, in pyarrow.lib.array\n",
      "  File \"pyarrow/array.pxi\", line 91, in pyarrow.lib._ndarray_to_array\n",
      "  File \"pyarrow/error.pxi\", line 92, in pyarrow.lib.check_status\n",
      "pyarrow.lib.ArrowInvalid: (\"Could not convert dtype('int64') with type numpy.dtypes.Int64DType: did not recognize Python value type when inferring an Arrow data type\", 'Conversion failed for column 0 with type object')\n",
      "2025-08-21 15:12:52.034 Serialization of dataframe to Arrow table was unsuccessful. Applying automatic fixes for column types to make the dataframe Arrow-compatible.\n",
      "Traceback (most recent call last):\n",
      "  File \"/Users/nayzawlin/Desktop/langara/ARC/PEH/PEH-cohort/pehenv/lib/python3.13/site-packages/streamlit/dataframe_util.py\", line 821, in convert_pandas_df_to_arrow_bytes\n",
      "    table = pa.Table.from_pandas(df)\n",
      "  File \"pyarrow/table.pxi\", line 4795, in pyarrow.lib.Table.from_pandas\n",
      "  File \"/Users/nayzawlin/Desktop/langara/ARC/PEH/PEH-cohort/pehenv/lib/python3.13/site-packages/pyarrow/pandas_compat.py\", line 637, in dataframe_to_arrays\n",
      "    arrays = [convert_column(c, f)\n",
      "              ~~~~~~~~~~~~~~^^^^^^\n",
      "  File \"/Users/nayzawlin/Desktop/langara/ARC/PEH/PEH-cohort/pehenv/lib/python3.13/site-packages/pyarrow/pandas_compat.py\", line 625, in convert_column\n",
      "    raise e\n",
      "  File \"/Users/nayzawlin/Desktop/langara/ARC/PEH/PEH-cohort/pehenv/lib/python3.13/site-packages/pyarrow/pandas_compat.py\", line 619, in convert_column\n",
      "    result = pa.array(col, type=type_, from_pandas=True, safe=safe)\n",
      "  File \"pyarrow/array.pxi\", line 365, in pyarrow.lib.array\n",
      "  File \"pyarrow/array.pxi\", line 91, in pyarrow.lib._ndarray_to_array\n",
      "  File \"pyarrow/error.pxi\", line 92, in pyarrow.lib.check_status\n",
      "pyarrow.lib.ArrowInvalid: (\"Could not convert dtype('int64') with type numpy.dtypes.Int64DType: did not recognize Python value type when inferring an Arrow data type\", 'Conversion failed for column 0 with type object')\n",
      "2025-08-21 15:12:52.574 Serialization of dataframe to Arrow table was unsuccessful. Applying automatic fixes for column types to make the dataframe Arrow-compatible.\n",
      "Traceback (most recent call last):\n",
      "  File \"/Users/nayzawlin/Desktop/langara/ARC/PEH/PEH-cohort/pehenv/lib/python3.13/site-packages/streamlit/dataframe_util.py\", line 821, in convert_pandas_df_to_arrow_bytes\n",
      "    table = pa.Table.from_pandas(df)\n",
      "  File \"pyarrow/table.pxi\", line 4795, in pyarrow.lib.Table.from_pandas\n",
      "  File \"/Users/nayzawlin/Desktop/langara/ARC/PEH/PEH-cohort/pehenv/lib/python3.13/site-packages/pyarrow/pandas_compat.py\", line 637, in dataframe_to_arrays\n",
      "    arrays = [convert_column(c, f)\n",
      "              ~~~~~~~~~~~~~~^^^^^^\n",
      "  File \"/Users/nayzawlin/Desktop/langara/ARC/PEH/PEH-cohort/pehenv/lib/python3.13/site-packages/pyarrow/pandas_compat.py\", line 625, in convert_column\n",
      "    raise e\n",
      "  File \"/Users/nayzawlin/Desktop/langara/ARC/PEH/PEH-cohort/pehenv/lib/python3.13/site-packages/pyarrow/pandas_compat.py\", line 619, in convert_column\n",
      "    result = pa.array(col, type=type_, from_pandas=True, safe=safe)\n",
      "  File \"pyarrow/array.pxi\", line 365, in pyarrow.lib.array\n",
      "  File \"pyarrow/array.pxi\", line 91, in pyarrow.lib._ndarray_to_array\n",
      "  File \"pyarrow/error.pxi\", line 92, in pyarrow.lib.check_status\n",
      "pyarrow.lib.ArrowInvalid: (\"Could not convert dtype('int64') with type numpy.dtypes.Int64DType: did not recognize Python value type when inferring an Arrow data type\", 'Conversion failed for column 0 with type object')\n",
      "2025-08-21 15:12:53.087 Serialization of dataframe to Arrow table was unsuccessful. Applying automatic fixes for column types to make the dataframe Arrow-compatible.\n",
      "Traceback (most recent call last):\n",
      "  File \"/Users/nayzawlin/Desktop/langara/ARC/PEH/PEH-cohort/pehenv/lib/python3.13/site-packages/streamlit/dataframe_util.py\", line 821, in convert_pandas_df_to_arrow_bytes\n",
      "    table = pa.Table.from_pandas(df)\n",
      "  File \"pyarrow/table.pxi\", line 4795, in pyarrow.lib.Table.from_pandas\n",
      "  File \"/Users/nayzawlin/Desktop/langara/ARC/PEH/PEH-cohort/pehenv/lib/python3.13/site-packages/pyarrow/pandas_compat.py\", line 637, in dataframe_to_arrays\n",
      "    arrays = [convert_column(c, f)\n",
      "              ~~~~~~~~~~~~~~^^^^^^\n",
      "  File \"/Users/nayzawlin/Desktop/langara/ARC/PEH/PEH-cohort/pehenv/lib/python3.13/site-packages/pyarrow/pandas_compat.py\", line 625, in convert_column\n",
      "    raise e\n",
      "  File \"/Users/nayzawlin/Desktop/langara/ARC/PEH/PEH-cohort/pehenv/lib/python3.13/site-packages/pyarrow/pandas_compat.py\", line 619, in convert_column\n",
      "    result = pa.array(col, type=type_, from_pandas=True, safe=safe)\n",
      "  File \"pyarrow/array.pxi\", line 365, in pyarrow.lib.array\n",
      "  File \"pyarrow/array.pxi\", line 91, in pyarrow.lib._ndarray_to_array\n",
      "  File \"pyarrow/error.pxi\", line 92, in pyarrow.lib.check_status\n",
      "pyarrow.lib.ArrowInvalid: (\"Could not convert dtype('int64') with type numpy.dtypes.Int64DType: did not recognize Python value type when inferring an Arrow data type\", 'Conversion failed for column 0 with type object')\n",
      "2025-08-21 15:12:53.773 Serialization of dataframe to Arrow table was unsuccessful. Applying automatic fixes for column types to make the dataframe Arrow-compatible.\n",
      "Traceback (most recent call last):\n",
      "  File \"/Users/nayzawlin/Desktop/langara/ARC/PEH/PEH-cohort/pehenv/lib/python3.13/site-packages/streamlit/dataframe_util.py\", line 821, in convert_pandas_df_to_arrow_bytes\n",
      "    table = pa.Table.from_pandas(df)\n",
      "  File \"pyarrow/table.pxi\", line 4795, in pyarrow.lib.Table.from_pandas\n",
      "  File \"/Users/nayzawlin/Desktop/langara/ARC/PEH/PEH-cohort/pehenv/lib/python3.13/site-packages/pyarrow/pandas_compat.py\", line 637, in dataframe_to_arrays\n",
      "    arrays = [convert_column(c, f)\n",
      "              ~~~~~~~~~~~~~~^^^^^^\n",
      "  File \"/Users/nayzawlin/Desktop/langara/ARC/PEH/PEH-cohort/pehenv/lib/python3.13/site-packages/pyarrow/pandas_compat.py\", line 625, in convert_column\n",
      "    raise e\n",
      "  File \"/Users/nayzawlin/Desktop/langara/ARC/PEH/PEH-cohort/pehenv/lib/python3.13/site-packages/pyarrow/pandas_compat.py\", line 619, in convert_column\n",
      "    result = pa.array(col, type=type_, from_pandas=True, safe=safe)\n",
      "  File \"pyarrow/array.pxi\", line 365, in pyarrow.lib.array\n",
      "  File \"pyarrow/array.pxi\", line 91, in pyarrow.lib._ndarray_to_array\n",
      "  File \"pyarrow/error.pxi\", line 92, in pyarrow.lib.check_status\n",
      "pyarrow.lib.ArrowInvalid: (\"Could not convert dtype('int64') with type numpy.dtypes.Int64DType: did not recognize Python value type when inferring an Arrow data type\", 'Conversion failed for column 0 with type object')\n",
      "2025-08-21 15:12:54.191 Serialization of dataframe to Arrow table was unsuccessful. Applying automatic fixes for column types to make the dataframe Arrow-compatible.\n",
      "Traceback (most recent call last):\n",
      "  File \"/Users/nayzawlin/Desktop/langara/ARC/PEH/PEH-cohort/pehenv/lib/python3.13/site-packages/streamlit/dataframe_util.py\", line 821, in convert_pandas_df_to_arrow_bytes\n",
      "    table = pa.Table.from_pandas(df)\n",
      "  File \"pyarrow/table.pxi\", line 4795, in pyarrow.lib.Table.from_pandas\n",
      "  File \"/Users/nayzawlin/Desktop/langara/ARC/PEH/PEH-cohort/pehenv/lib/python3.13/site-packages/pyarrow/pandas_compat.py\", line 637, in dataframe_to_arrays\n",
      "    arrays = [convert_column(c, f)\n",
      "              ~~~~~~~~~~~~~~^^^^^^\n",
      "  File \"/Users/nayzawlin/Desktop/langara/ARC/PEH/PEH-cohort/pehenv/lib/python3.13/site-packages/pyarrow/pandas_compat.py\", line 625, in convert_column\n",
      "    raise e\n",
      "  File \"/Users/nayzawlin/Desktop/langara/ARC/PEH/PEH-cohort/pehenv/lib/python3.13/site-packages/pyarrow/pandas_compat.py\", line 619, in convert_column\n",
      "    result = pa.array(col, type=type_, from_pandas=True, safe=safe)\n",
      "  File \"pyarrow/array.pxi\", line 365, in pyarrow.lib.array\n",
      "  File \"pyarrow/array.pxi\", line 91, in pyarrow.lib._ndarray_to_array\n",
      "  File \"pyarrow/error.pxi\", line 92, in pyarrow.lib.check_status\n",
      "pyarrow.lib.ArrowInvalid: (\"Could not convert dtype('int64') with type numpy.dtypes.Int64DType: did not recognize Python value type when inferring an Arrow data type\", 'Conversion failed for column 0 with type object')\n",
      "2025-08-21 15:13:02.076 Serialization of dataframe to Arrow table was unsuccessful. Applying automatic fixes for column types to make the dataframe Arrow-compatible.\n",
      "Traceback (most recent call last):\n",
      "  File \"/Users/nayzawlin/Desktop/langara/ARC/PEH/PEH-cohort/pehenv/lib/python3.13/site-packages/streamlit/dataframe_util.py\", line 821, in convert_pandas_df_to_arrow_bytes\n",
      "    table = pa.Table.from_pandas(df)\n",
      "  File \"pyarrow/table.pxi\", line 4795, in pyarrow.lib.Table.from_pandas\n",
      "  File \"/Users/nayzawlin/Desktop/langara/ARC/PEH/PEH-cohort/pehenv/lib/python3.13/site-packages/pyarrow/pandas_compat.py\", line 637, in dataframe_to_arrays\n",
      "    arrays = [convert_column(c, f)\n",
      "              ~~~~~~~~~~~~~~^^^^^^\n",
      "  File \"/Users/nayzawlin/Desktop/langara/ARC/PEH/PEH-cohort/pehenv/lib/python3.13/site-packages/pyarrow/pandas_compat.py\", line 625, in convert_column\n",
      "    raise e\n",
      "  File \"/Users/nayzawlin/Desktop/langara/ARC/PEH/PEH-cohort/pehenv/lib/python3.13/site-packages/pyarrow/pandas_compat.py\", line 619, in convert_column\n",
      "    result = pa.array(col, type=type_, from_pandas=True, safe=safe)\n",
      "  File \"pyarrow/array.pxi\", line 365, in pyarrow.lib.array\n",
      "  File \"pyarrow/array.pxi\", line 91, in pyarrow.lib._ndarray_to_array\n",
      "  File \"pyarrow/error.pxi\", line 92, in pyarrow.lib.check_status\n",
      "pyarrow.lib.ArrowInvalid: (\"Could not convert dtype('int64') with type numpy.dtypes.Int64DType: did not recognize Python value type when inferring an Arrow data type\", 'Conversion failed for column 0 with type object')\n",
      "2025-08-21 15:13:09.492 Serialization of dataframe to Arrow table was unsuccessful. Applying automatic fixes for column types to make the dataframe Arrow-compatible.\n",
      "Traceback (most recent call last):\n",
      "  File \"/Users/nayzawlin/Desktop/langara/ARC/PEH/PEH-cohort/pehenv/lib/python3.13/site-packages/streamlit/dataframe_util.py\", line 821, in convert_pandas_df_to_arrow_bytes\n",
      "    table = pa.Table.from_pandas(df)\n",
      "  File \"pyarrow/table.pxi\", line 4795, in pyarrow.lib.Table.from_pandas\n",
      "  File \"/Users/nayzawlin/Desktop/langara/ARC/PEH/PEH-cohort/pehenv/lib/python3.13/site-packages/pyarrow/pandas_compat.py\", line 637, in dataframe_to_arrays\n",
      "    arrays = [convert_column(c, f)\n",
      "              ~~~~~~~~~~~~~~^^^^^^\n",
      "  File \"/Users/nayzawlin/Desktop/langara/ARC/PEH/PEH-cohort/pehenv/lib/python3.13/site-packages/pyarrow/pandas_compat.py\", line 625, in convert_column\n",
      "    raise e\n",
      "  File \"/Users/nayzawlin/Desktop/langara/ARC/PEH/PEH-cohort/pehenv/lib/python3.13/site-packages/pyarrow/pandas_compat.py\", line 619, in convert_column\n",
      "    result = pa.array(col, type=type_, from_pandas=True, safe=safe)\n",
      "  File \"pyarrow/array.pxi\", line 365, in pyarrow.lib.array\n",
      "  File \"pyarrow/array.pxi\", line 91, in pyarrow.lib._ndarray_to_array\n",
      "  File \"pyarrow/error.pxi\", line 92, in pyarrow.lib.check_status\n",
      "pyarrow.lib.ArrowInvalid: (\"Could not convert dtype('int64') with type numpy.dtypes.Int64DType: did not recognize Python value type when inferring an Arrow data type\", 'Conversion failed for column 0 with type object')\n",
      "2025-08-21 15:13:10.535 Serialization of dataframe to Arrow table was unsuccessful. Applying automatic fixes for column types to make the dataframe Arrow-compatible.\n",
      "Traceback (most recent call last):\n",
      "  File \"/Users/nayzawlin/Desktop/langara/ARC/PEH/PEH-cohort/pehenv/lib/python3.13/site-packages/streamlit/dataframe_util.py\", line 821, in convert_pandas_df_to_arrow_bytes\n",
      "    table = pa.Table.from_pandas(df)\n",
      "  File \"pyarrow/table.pxi\", line 4795, in pyarrow.lib.Table.from_pandas\n",
      "  File \"/Users/nayzawlin/Desktop/langara/ARC/PEH/PEH-cohort/pehenv/lib/python3.13/site-packages/pyarrow/pandas_compat.py\", line 637, in dataframe_to_arrays\n",
      "    arrays = [convert_column(c, f)\n",
      "              ~~~~~~~~~~~~~~^^^^^^\n",
      "  File \"/Users/nayzawlin/Desktop/langara/ARC/PEH/PEH-cohort/pehenv/lib/python3.13/site-packages/pyarrow/pandas_compat.py\", line 625, in convert_column\n",
      "    raise e\n",
      "  File \"/Users/nayzawlin/Desktop/langara/ARC/PEH/PEH-cohort/pehenv/lib/python3.13/site-packages/pyarrow/pandas_compat.py\", line 619, in convert_column\n",
      "    result = pa.array(col, type=type_, from_pandas=True, safe=safe)\n",
      "  File \"pyarrow/array.pxi\", line 365, in pyarrow.lib.array\n",
      "  File \"pyarrow/array.pxi\", line 91, in pyarrow.lib._ndarray_to_array\n",
      "  File \"pyarrow/error.pxi\", line 92, in pyarrow.lib.check_status\n",
      "pyarrow.lib.ArrowInvalid: (\"Could not convert dtype('int64') with type numpy.dtypes.Int64DType: did not recognize Python value type when inferring an Arrow data type\", 'Conversion failed for column 0 with type object')\n",
      "2025-08-21 15:13:26.349 Serialization of dataframe to Arrow table was unsuccessful. Applying automatic fixes for column types to make the dataframe Arrow-compatible.\n",
      "Traceback (most recent call last):\n",
      "  File \"/Users/nayzawlin/Desktop/langara/ARC/PEH/PEH-cohort/pehenv/lib/python3.13/site-packages/streamlit/dataframe_util.py\", line 821, in convert_pandas_df_to_arrow_bytes\n",
      "    table = pa.Table.from_pandas(df)\n",
      "  File \"pyarrow/table.pxi\", line 4795, in pyarrow.lib.Table.from_pandas\n",
      "  File \"/Users/nayzawlin/Desktop/langara/ARC/PEH/PEH-cohort/pehenv/lib/python3.13/site-packages/pyarrow/pandas_compat.py\", line 637, in dataframe_to_arrays\n",
      "    arrays = [convert_column(c, f)\n",
      "              ~~~~~~~~~~~~~~^^^^^^\n",
      "  File \"/Users/nayzawlin/Desktop/langara/ARC/PEH/PEH-cohort/pehenv/lib/python3.13/site-packages/pyarrow/pandas_compat.py\", line 625, in convert_column\n",
      "    raise e\n",
      "  File \"/Users/nayzawlin/Desktop/langara/ARC/PEH/PEH-cohort/pehenv/lib/python3.13/site-packages/pyarrow/pandas_compat.py\", line 619, in convert_column\n",
      "    result = pa.array(col, type=type_, from_pandas=True, safe=safe)\n",
      "  File \"pyarrow/array.pxi\", line 365, in pyarrow.lib.array\n",
      "  File \"pyarrow/array.pxi\", line 91, in pyarrow.lib._ndarray_to_array\n",
      "  File \"pyarrow/error.pxi\", line 92, in pyarrow.lib.check_status\n",
      "pyarrow.lib.ArrowInvalid: (\"Could not convert dtype('int64') with type numpy.dtypes.Int64DType: did not recognize Python value type when inferring an Arrow data type\", 'Conversion failed for column 0 with type object')\n",
      "2025-08-21 15:13:52.825 Serialization of dataframe to Arrow table was unsuccessful. Applying automatic fixes for column types to make the dataframe Arrow-compatible.\n",
      "Traceback (most recent call last):\n",
      "  File \"/Users/nayzawlin/Desktop/langara/ARC/PEH/PEH-cohort/pehenv/lib/python3.13/site-packages/streamlit/dataframe_util.py\", line 821, in convert_pandas_df_to_arrow_bytes\n",
      "    table = pa.Table.from_pandas(df)\n",
      "  File \"pyarrow/table.pxi\", line 4795, in pyarrow.lib.Table.from_pandas\n",
      "  File \"/Users/nayzawlin/Desktop/langara/ARC/PEH/PEH-cohort/pehenv/lib/python3.13/site-packages/pyarrow/pandas_compat.py\", line 637, in dataframe_to_arrays\n",
      "    arrays = [convert_column(c, f)\n",
      "              ~~~~~~~~~~~~~~^^^^^^\n",
      "  File \"/Users/nayzawlin/Desktop/langara/ARC/PEH/PEH-cohort/pehenv/lib/python3.13/site-packages/pyarrow/pandas_compat.py\", line 625, in convert_column\n",
      "    raise e\n",
      "  File \"/Users/nayzawlin/Desktop/langara/ARC/PEH/PEH-cohort/pehenv/lib/python3.13/site-packages/pyarrow/pandas_compat.py\", line 619, in convert_column\n",
      "    result = pa.array(col, type=type_, from_pandas=True, safe=safe)\n",
      "  File \"pyarrow/array.pxi\", line 365, in pyarrow.lib.array\n",
      "  File \"pyarrow/array.pxi\", line 91, in pyarrow.lib._ndarray_to_array\n",
      "  File \"pyarrow/error.pxi\", line 92, in pyarrow.lib.check_status\n",
      "pyarrow.lib.ArrowInvalid: (\"Could not convert dtype('int64') with type numpy.dtypes.Int64DType: did not recognize Python value type when inferring an Arrow data type\", 'Conversion failed for column 0 with type object')\n",
      "2025-08-21 15:13:57.847 Serialization of dataframe to Arrow table was unsuccessful. Applying automatic fixes for column types to make the dataframe Arrow-compatible.\n",
      "Traceback (most recent call last):\n",
      "  File \"/Users/nayzawlin/Desktop/langara/ARC/PEH/PEH-cohort/pehenv/lib/python3.13/site-packages/streamlit/dataframe_util.py\", line 821, in convert_pandas_df_to_arrow_bytes\n",
      "    table = pa.Table.from_pandas(df)\n",
      "  File \"pyarrow/table.pxi\", line 4795, in pyarrow.lib.Table.from_pandas\n",
      "  File \"/Users/nayzawlin/Desktop/langara/ARC/PEH/PEH-cohort/pehenv/lib/python3.13/site-packages/pyarrow/pandas_compat.py\", line 637, in dataframe_to_arrays\n",
      "    arrays = [convert_column(c, f)\n",
      "              ~~~~~~~~~~~~~~^^^^^^\n",
      "  File \"/Users/nayzawlin/Desktop/langara/ARC/PEH/PEH-cohort/pehenv/lib/python3.13/site-packages/pyarrow/pandas_compat.py\", line 625, in convert_column\n",
      "    raise e\n",
      "  File \"/Users/nayzawlin/Desktop/langara/ARC/PEH/PEH-cohort/pehenv/lib/python3.13/site-packages/pyarrow/pandas_compat.py\", line 619, in convert_column\n",
      "    result = pa.array(col, type=type_, from_pandas=True, safe=safe)\n",
      "  File \"pyarrow/array.pxi\", line 365, in pyarrow.lib.array\n",
      "  File \"pyarrow/array.pxi\", line 91, in pyarrow.lib._ndarray_to_array\n",
      "  File \"pyarrow/error.pxi\", line 92, in pyarrow.lib.check_status\n",
      "pyarrow.lib.ArrowInvalid: (\"Could not convert dtype('int64') with type numpy.dtypes.Int64DType: did not recognize Python value type when inferring an Arrow data type\", 'Conversion failed for column 0 with type object')\n",
      "2025-08-21 15:13:58.397 Serialization of dataframe to Arrow table was unsuccessful. Applying automatic fixes for column types to make the dataframe Arrow-compatible.\n",
      "Traceback (most recent call last):\n",
      "  File \"/Users/nayzawlin/Desktop/langara/ARC/PEH/PEH-cohort/pehenv/lib/python3.13/site-packages/streamlit/dataframe_util.py\", line 821, in convert_pandas_df_to_arrow_bytes\n",
      "    table = pa.Table.from_pandas(df)\n",
      "  File \"pyarrow/table.pxi\", line 4795, in pyarrow.lib.Table.from_pandas\n",
      "  File \"/Users/nayzawlin/Desktop/langara/ARC/PEH/PEH-cohort/pehenv/lib/python3.13/site-packages/pyarrow/pandas_compat.py\", line 637, in dataframe_to_arrays\n",
      "    arrays = [convert_column(c, f)\n",
      "              ~~~~~~~~~~~~~~^^^^^^\n",
      "  File \"/Users/nayzawlin/Desktop/langara/ARC/PEH/PEH-cohort/pehenv/lib/python3.13/site-packages/pyarrow/pandas_compat.py\", line 625, in convert_column\n",
      "    raise e\n",
      "  File \"/Users/nayzawlin/Desktop/langara/ARC/PEH/PEH-cohort/pehenv/lib/python3.13/site-packages/pyarrow/pandas_compat.py\", line 619, in convert_column\n",
      "    result = pa.array(col, type=type_, from_pandas=True, safe=safe)\n",
      "  File \"pyarrow/array.pxi\", line 365, in pyarrow.lib.array\n",
      "  File \"pyarrow/array.pxi\", line 91, in pyarrow.lib._ndarray_to_array\n",
      "  File \"pyarrow/error.pxi\", line 92, in pyarrow.lib.check_status\n",
      "pyarrow.lib.ArrowInvalid: (\"Could not convert dtype('int64') with type numpy.dtypes.Int64DType: did not recognize Python value type when inferring an Arrow data type\", 'Conversion failed for column 0 with type object')\n",
      "2025-08-21 15:13:58.973 Serialization of dataframe to Arrow table was unsuccessful. Applying automatic fixes for column types to make the dataframe Arrow-compatible.\n",
      "Traceback (most recent call last):\n",
      "  File \"/Users/nayzawlin/Desktop/langara/ARC/PEH/PEH-cohort/pehenv/lib/python3.13/site-packages/streamlit/dataframe_util.py\", line 821, in convert_pandas_df_to_arrow_bytes\n",
      "    table = pa.Table.from_pandas(df)\n",
      "  File \"pyarrow/table.pxi\", line 4795, in pyarrow.lib.Table.from_pandas\n",
      "  File \"/Users/nayzawlin/Desktop/langara/ARC/PEH/PEH-cohort/pehenv/lib/python3.13/site-packages/pyarrow/pandas_compat.py\", line 637, in dataframe_to_arrays\n",
      "    arrays = [convert_column(c, f)\n",
      "              ~~~~~~~~~~~~~~^^^^^^\n",
      "  File \"/Users/nayzawlin/Desktop/langara/ARC/PEH/PEH-cohort/pehenv/lib/python3.13/site-packages/pyarrow/pandas_compat.py\", line 625, in convert_column\n",
      "    raise e\n",
      "  File \"/Users/nayzawlin/Desktop/langara/ARC/PEH/PEH-cohort/pehenv/lib/python3.13/site-packages/pyarrow/pandas_compat.py\", line 619, in convert_column\n",
      "    result = pa.array(col, type=type_, from_pandas=True, safe=safe)\n",
      "  File \"pyarrow/array.pxi\", line 365, in pyarrow.lib.array\n",
      "  File \"pyarrow/array.pxi\", line 91, in pyarrow.lib._ndarray_to_array\n",
      "  File \"pyarrow/error.pxi\", line 92, in pyarrow.lib.check_status\n",
      "pyarrow.lib.ArrowInvalid: (\"Could not convert dtype('int64') with type numpy.dtypes.Int64DType: did not recognize Python value type when inferring an Arrow data type\", 'Conversion failed for column 0 with type object')\n",
      "2025-08-21 15:13:59.597 Serialization of dataframe to Arrow table was unsuccessful. Applying automatic fixes for column types to make the dataframe Arrow-compatible.\n",
      "Traceback (most recent call last):\n",
      "  File \"/Users/nayzawlin/Desktop/langara/ARC/PEH/PEH-cohort/pehenv/lib/python3.13/site-packages/streamlit/dataframe_util.py\", line 821, in convert_pandas_df_to_arrow_bytes\n",
      "    table = pa.Table.from_pandas(df)\n",
      "  File \"pyarrow/table.pxi\", line 4795, in pyarrow.lib.Table.from_pandas\n",
      "  File \"/Users/nayzawlin/Desktop/langara/ARC/PEH/PEH-cohort/pehenv/lib/python3.13/site-packages/pyarrow/pandas_compat.py\", line 637, in dataframe_to_arrays\n",
      "    arrays = [convert_column(c, f)\n",
      "              ~~~~~~~~~~~~~~^^^^^^\n",
      "  File \"/Users/nayzawlin/Desktop/langara/ARC/PEH/PEH-cohort/pehenv/lib/python3.13/site-packages/pyarrow/pandas_compat.py\", line 625, in convert_column\n",
      "    raise e\n",
      "  File \"/Users/nayzawlin/Desktop/langara/ARC/PEH/PEH-cohort/pehenv/lib/python3.13/site-packages/pyarrow/pandas_compat.py\", line 619, in convert_column\n",
      "    result = pa.array(col, type=type_, from_pandas=True, safe=safe)\n",
      "  File \"pyarrow/array.pxi\", line 365, in pyarrow.lib.array\n",
      "  File \"pyarrow/array.pxi\", line 91, in pyarrow.lib._ndarray_to_array\n",
      "  File \"pyarrow/error.pxi\", line 92, in pyarrow.lib.check_status\n",
      "pyarrow.lib.ArrowInvalid: (\"Could not convert dtype('int64') with type numpy.dtypes.Int64DType: did not recognize Python value type when inferring an Arrow data type\", 'Conversion failed for column 0 with type object')\n",
      "2025-08-21 15:14:04.054 Serialization of dataframe to Arrow table was unsuccessful. Applying automatic fixes for column types to make the dataframe Arrow-compatible.\n",
      "Traceback (most recent call last):\n",
      "  File \"/Users/nayzawlin/Desktop/langara/ARC/PEH/PEH-cohort/pehenv/lib/python3.13/site-packages/streamlit/dataframe_util.py\", line 821, in convert_pandas_df_to_arrow_bytes\n",
      "    table = pa.Table.from_pandas(df)\n",
      "  File \"pyarrow/table.pxi\", line 4795, in pyarrow.lib.Table.from_pandas\n",
      "  File \"/Users/nayzawlin/Desktop/langara/ARC/PEH/PEH-cohort/pehenv/lib/python3.13/site-packages/pyarrow/pandas_compat.py\", line 637, in dataframe_to_arrays\n",
      "    arrays = [convert_column(c, f)\n",
      "              ~~~~~~~~~~~~~~^^^^^^\n",
      "  File \"/Users/nayzawlin/Desktop/langara/ARC/PEH/PEH-cohort/pehenv/lib/python3.13/site-packages/pyarrow/pandas_compat.py\", line 625, in convert_column\n",
      "    raise e\n",
      "  File \"/Users/nayzawlin/Desktop/langara/ARC/PEH/PEH-cohort/pehenv/lib/python3.13/site-packages/pyarrow/pandas_compat.py\", line 619, in convert_column\n",
      "    result = pa.array(col, type=type_, from_pandas=True, safe=safe)\n",
      "  File \"pyarrow/array.pxi\", line 365, in pyarrow.lib.array\n",
      "  File \"pyarrow/array.pxi\", line 91, in pyarrow.lib._ndarray_to_array\n",
      "  File \"pyarrow/error.pxi\", line 92, in pyarrow.lib.check_status\n",
      "pyarrow.lib.ArrowInvalid: (\"Could not convert dtype('int64') with type numpy.dtypes.Int64DType: did not recognize Python value type when inferring an Arrow data type\", 'Conversion failed for column 0 with type object')\n",
      "2025-08-21 15:14:16.667 Serialization of dataframe to Arrow table was unsuccessful. Applying automatic fixes for column types to make the dataframe Arrow-compatible.\n",
      "Traceback (most recent call last):\n",
      "  File \"/Users/nayzawlin/Desktop/langara/ARC/PEH/PEH-cohort/pehenv/lib/python3.13/site-packages/streamlit/dataframe_util.py\", line 821, in convert_pandas_df_to_arrow_bytes\n",
      "    table = pa.Table.from_pandas(df)\n",
      "  File \"pyarrow/table.pxi\", line 4795, in pyarrow.lib.Table.from_pandas\n",
      "  File \"/Users/nayzawlin/Desktop/langara/ARC/PEH/PEH-cohort/pehenv/lib/python3.13/site-packages/pyarrow/pandas_compat.py\", line 637, in dataframe_to_arrays\n",
      "    arrays = [convert_column(c, f)\n",
      "              ~~~~~~~~~~~~~~^^^^^^\n",
      "  File \"/Users/nayzawlin/Desktop/langara/ARC/PEH/PEH-cohort/pehenv/lib/python3.13/site-packages/pyarrow/pandas_compat.py\", line 625, in convert_column\n",
      "    raise e\n",
      "  File \"/Users/nayzawlin/Desktop/langara/ARC/PEH/PEH-cohort/pehenv/lib/python3.13/site-packages/pyarrow/pandas_compat.py\", line 619, in convert_column\n",
      "    result = pa.array(col, type=type_, from_pandas=True, safe=safe)\n",
      "  File \"pyarrow/array.pxi\", line 365, in pyarrow.lib.array\n",
      "  File \"pyarrow/array.pxi\", line 91, in pyarrow.lib._ndarray_to_array\n",
      "  File \"pyarrow/error.pxi\", line 92, in pyarrow.lib.check_status\n",
      "pyarrow.lib.ArrowInvalid: (\"Could not convert dtype('int64') with type numpy.dtypes.Int64DType: did not recognize Python value type when inferring an Arrow data type\", 'Conversion failed for column 0 with type object')\n",
      "2025-08-21 15:14:21.708 Serialization of dataframe to Arrow table was unsuccessful. Applying automatic fixes for column types to make the dataframe Arrow-compatible.\n",
      "Traceback (most recent call last):\n",
      "  File \"/Users/nayzawlin/Desktop/langara/ARC/PEH/PEH-cohort/pehenv/lib/python3.13/site-packages/streamlit/dataframe_util.py\", line 821, in convert_pandas_df_to_arrow_bytes\n",
      "    table = pa.Table.from_pandas(df)\n",
      "  File \"pyarrow/table.pxi\", line 4795, in pyarrow.lib.Table.from_pandas\n",
      "  File \"/Users/nayzawlin/Desktop/langara/ARC/PEH/PEH-cohort/pehenv/lib/python3.13/site-packages/pyarrow/pandas_compat.py\", line 637, in dataframe_to_arrays\n",
      "    arrays = [convert_column(c, f)\n",
      "              ~~~~~~~~~~~~~~^^^^^^\n",
      "  File \"/Users/nayzawlin/Desktop/langara/ARC/PEH/PEH-cohort/pehenv/lib/python3.13/site-packages/pyarrow/pandas_compat.py\", line 625, in convert_column\n",
      "    raise e\n",
      "  File \"/Users/nayzawlin/Desktop/langara/ARC/PEH/PEH-cohort/pehenv/lib/python3.13/site-packages/pyarrow/pandas_compat.py\", line 619, in convert_column\n",
      "    result = pa.array(col, type=type_, from_pandas=True, safe=safe)\n",
      "  File \"pyarrow/array.pxi\", line 365, in pyarrow.lib.array\n",
      "  File \"pyarrow/array.pxi\", line 91, in pyarrow.lib._ndarray_to_array\n",
      "  File \"pyarrow/error.pxi\", line 92, in pyarrow.lib.check_status\n",
      "pyarrow.lib.ArrowInvalid: (\"Could not convert dtype('int64') with type numpy.dtypes.Int64DType: did not recognize Python value type when inferring an Arrow data type\", 'Conversion failed for column 0 with type object')\n",
      "2025-08-21 15:14:27.211 Serialization of dataframe to Arrow table was unsuccessful. Applying automatic fixes for column types to make the dataframe Arrow-compatible.\n",
      "Traceback (most recent call last):\n",
      "  File \"/Users/nayzawlin/Desktop/langara/ARC/PEH/PEH-cohort/pehenv/lib/python3.13/site-packages/streamlit/dataframe_util.py\", line 821, in convert_pandas_df_to_arrow_bytes\n",
      "    table = pa.Table.from_pandas(df)\n",
      "  File \"pyarrow/table.pxi\", line 4795, in pyarrow.lib.Table.from_pandas\n",
      "  File \"/Users/nayzawlin/Desktop/langara/ARC/PEH/PEH-cohort/pehenv/lib/python3.13/site-packages/pyarrow/pandas_compat.py\", line 637, in dataframe_to_arrays\n",
      "    arrays = [convert_column(c, f)\n",
      "              ~~~~~~~~~~~~~~^^^^^^\n",
      "  File \"/Users/nayzawlin/Desktop/langara/ARC/PEH/PEH-cohort/pehenv/lib/python3.13/site-packages/pyarrow/pandas_compat.py\", line 625, in convert_column\n",
      "    raise e\n",
      "  File \"/Users/nayzawlin/Desktop/langara/ARC/PEH/PEH-cohort/pehenv/lib/python3.13/site-packages/pyarrow/pandas_compat.py\", line 619, in convert_column\n",
      "    result = pa.array(col, type=type_, from_pandas=True, safe=safe)\n",
      "  File \"pyarrow/array.pxi\", line 365, in pyarrow.lib.array\n",
      "  File \"pyarrow/array.pxi\", line 91, in pyarrow.lib._ndarray_to_array\n",
      "  File \"pyarrow/error.pxi\", line 92, in pyarrow.lib.check_status\n",
      "pyarrow.lib.ArrowInvalid: (\"Could not convert dtype('int64') with type numpy.dtypes.Int64DType: did not recognize Python value type when inferring an Arrow data type\", 'Conversion failed for column 0 with type object')\n",
      "2025-08-21 15:14:39.932 Serialization of dataframe to Arrow table was unsuccessful. Applying automatic fixes for column types to make the dataframe Arrow-compatible.\n",
      "Traceback (most recent call last):\n",
      "  File \"/Users/nayzawlin/Desktop/langara/ARC/PEH/PEH-cohort/pehenv/lib/python3.13/site-packages/streamlit/dataframe_util.py\", line 821, in convert_pandas_df_to_arrow_bytes\n",
      "    table = pa.Table.from_pandas(df)\n",
      "  File \"pyarrow/table.pxi\", line 4795, in pyarrow.lib.Table.from_pandas\n",
      "  File \"/Users/nayzawlin/Desktop/langara/ARC/PEH/PEH-cohort/pehenv/lib/python3.13/site-packages/pyarrow/pandas_compat.py\", line 637, in dataframe_to_arrays\n",
      "    arrays = [convert_column(c, f)\n",
      "              ~~~~~~~~~~~~~~^^^^^^\n",
      "  File \"/Users/nayzawlin/Desktop/langara/ARC/PEH/PEH-cohort/pehenv/lib/python3.13/site-packages/pyarrow/pandas_compat.py\", line 625, in convert_column\n",
      "    raise e\n",
      "  File \"/Users/nayzawlin/Desktop/langara/ARC/PEH/PEH-cohort/pehenv/lib/python3.13/site-packages/pyarrow/pandas_compat.py\", line 619, in convert_column\n",
      "    result = pa.array(col, type=type_, from_pandas=True, safe=safe)\n",
      "  File \"pyarrow/array.pxi\", line 365, in pyarrow.lib.array\n",
      "  File \"pyarrow/array.pxi\", line 91, in pyarrow.lib._ndarray_to_array\n",
      "  File \"pyarrow/error.pxi\", line 92, in pyarrow.lib.check_status\n",
      "pyarrow.lib.ArrowInvalid: (\"Could not convert dtype('int64') with type numpy.dtypes.Int64DType: did not recognize Python value type when inferring an Arrow data type\", 'Conversion failed for column 0 with type object')\n",
      "2025-08-21 15:14:51.519 Serialization of dataframe to Arrow table was unsuccessful. Applying automatic fixes for column types to make the dataframe Arrow-compatible.\n",
      "Traceback (most recent call last):\n",
      "  File \"/Users/nayzawlin/Desktop/langara/ARC/PEH/PEH-cohort/pehenv/lib/python3.13/site-packages/streamlit/dataframe_util.py\", line 821, in convert_pandas_df_to_arrow_bytes\n",
      "    table = pa.Table.from_pandas(df)\n",
      "  File \"pyarrow/table.pxi\", line 4795, in pyarrow.lib.Table.from_pandas\n",
      "  File \"/Users/nayzawlin/Desktop/langara/ARC/PEH/PEH-cohort/pehenv/lib/python3.13/site-packages/pyarrow/pandas_compat.py\", line 637, in dataframe_to_arrays\n",
      "    arrays = [convert_column(c, f)\n",
      "              ~~~~~~~~~~~~~~^^^^^^\n",
      "  File \"/Users/nayzawlin/Desktop/langara/ARC/PEH/PEH-cohort/pehenv/lib/python3.13/site-packages/pyarrow/pandas_compat.py\", line 625, in convert_column\n",
      "    raise e\n",
      "  File \"/Users/nayzawlin/Desktop/langara/ARC/PEH/PEH-cohort/pehenv/lib/python3.13/site-packages/pyarrow/pandas_compat.py\", line 619, in convert_column\n",
      "    result = pa.array(col, type=type_, from_pandas=True, safe=safe)\n",
      "  File \"pyarrow/array.pxi\", line 365, in pyarrow.lib.array\n",
      "  File \"pyarrow/array.pxi\", line 91, in pyarrow.lib._ndarray_to_array\n",
      "  File \"pyarrow/error.pxi\", line 92, in pyarrow.lib.check_status\n",
      "pyarrow.lib.ArrowInvalid: (\"Could not convert dtype('int64') with type numpy.dtypes.Int64DType: did not recognize Python value type when inferring an Arrow data type\", 'Conversion failed for column 0 with type object')\n",
      "2025-08-21 15:14:57.109 Serialization of dataframe to Arrow table was unsuccessful. Applying automatic fixes for column types to make the dataframe Arrow-compatible.\n",
      "Traceback (most recent call last):\n",
      "  File \"/Users/nayzawlin/Desktop/langara/ARC/PEH/PEH-cohort/pehenv/lib/python3.13/site-packages/streamlit/dataframe_util.py\", line 821, in convert_pandas_df_to_arrow_bytes\n",
      "    table = pa.Table.from_pandas(df)\n",
      "  File \"pyarrow/table.pxi\", line 4795, in pyarrow.lib.Table.from_pandas\n",
      "  File \"/Users/nayzawlin/Desktop/langara/ARC/PEH/PEH-cohort/pehenv/lib/python3.13/site-packages/pyarrow/pandas_compat.py\", line 637, in dataframe_to_arrays\n",
      "    arrays = [convert_column(c, f)\n",
      "              ~~~~~~~~~~~~~~^^^^^^\n",
      "  File \"/Users/nayzawlin/Desktop/langara/ARC/PEH/PEH-cohort/pehenv/lib/python3.13/site-packages/pyarrow/pandas_compat.py\", line 625, in convert_column\n",
      "    raise e\n",
      "  File \"/Users/nayzawlin/Desktop/langara/ARC/PEH/PEH-cohort/pehenv/lib/python3.13/site-packages/pyarrow/pandas_compat.py\", line 619, in convert_column\n",
      "    result = pa.array(col, type=type_, from_pandas=True, safe=safe)\n",
      "  File \"pyarrow/array.pxi\", line 365, in pyarrow.lib.array\n",
      "  File \"pyarrow/array.pxi\", line 91, in pyarrow.lib._ndarray_to_array\n",
      "  File \"pyarrow/error.pxi\", line 92, in pyarrow.lib.check_status\n",
      "pyarrow.lib.ArrowInvalid: (\"Could not convert dtype('int64') with type numpy.dtypes.Int64DType: did not recognize Python value type when inferring an Arrow data type\", 'Conversion failed for column 0 with type object')\n",
      "2025-08-21 15:14:58.913 Serialization of dataframe to Arrow table was unsuccessful. Applying automatic fixes for column types to make the dataframe Arrow-compatible.\n",
      "Traceback (most recent call last):\n",
      "  File \"/Users/nayzawlin/Desktop/langara/ARC/PEH/PEH-cohort/pehenv/lib/python3.13/site-packages/streamlit/dataframe_util.py\", line 821, in convert_pandas_df_to_arrow_bytes\n",
      "    table = pa.Table.from_pandas(df)\n",
      "  File \"pyarrow/table.pxi\", line 4795, in pyarrow.lib.Table.from_pandas\n",
      "  File \"/Users/nayzawlin/Desktop/langara/ARC/PEH/PEH-cohort/pehenv/lib/python3.13/site-packages/pyarrow/pandas_compat.py\", line 637, in dataframe_to_arrays\n",
      "    arrays = [convert_column(c, f)\n",
      "              ~~~~~~~~~~~~~~^^^^^^\n",
      "  File \"/Users/nayzawlin/Desktop/langara/ARC/PEH/PEH-cohort/pehenv/lib/python3.13/site-packages/pyarrow/pandas_compat.py\", line 625, in convert_column\n",
      "    raise e\n",
      "  File \"/Users/nayzawlin/Desktop/langara/ARC/PEH/PEH-cohort/pehenv/lib/python3.13/site-packages/pyarrow/pandas_compat.py\", line 619, in convert_column\n",
      "    result = pa.array(col, type=type_, from_pandas=True, safe=safe)\n",
      "  File \"pyarrow/array.pxi\", line 365, in pyarrow.lib.array\n",
      "  File \"pyarrow/array.pxi\", line 91, in pyarrow.lib._ndarray_to_array\n",
      "  File \"pyarrow/error.pxi\", line 92, in pyarrow.lib.check_status\n",
      "pyarrow.lib.ArrowInvalid: (\"Could not convert dtype('int64') with type numpy.dtypes.Int64DType: did not recognize Python value type when inferring an Arrow data type\", 'Conversion failed for column 0 with type object')\n",
      "2025-08-21 15:15:02.460 Serialization of dataframe to Arrow table was unsuccessful. Applying automatic fixes for column types to make the dataframe Arrow-compatible.\n",
      "Traceback (most recent call last):\n",
      "  File \"/Users/nayzawlin/Desktop/langara/ARC/PEH/PEH-cohort/pehenv/lib/python3.13/site-packages/streamlit/dataframe_util.py\", line 821, in convert_pandas_df_to_arrow_bytes\n",
      "    table = pa.Table.from_pandas(df)\n",
      "  File \"pyarrow/table.pxi\", line 4795, in pyarrow.lib.Table.from_pandas\n",
      "  File \"/Users/nayzawlin/Desktop/langara/ARC/PEH/PEH-cohort/pehenv/lib/python3.13/site-packages/pyarrow/pandas_compat.py\", line 637, in dataframe_to_arrays\n",
      "    arrays = [convert_column(c, f)\n",
      "              ~~~~~~~~~~~~~~^^^^^^\n",
      "  File \"/Users/nayzawlin/Desktop/langara/ARC/PEH/PEH-cohort/pehenv/lib/python3.13/site-packages/pyarrow/pandas_compat.py\", line 625, in convert_column\n",
      "    raise e\n",
      "  File \"/Users/nayzawlin/Desktop/langara/ARC/PEH/PEH-cohort/pehenv/lib/python3.13/site-packages/pyarrow/pandas_compat.py\", line 619, in convert_column\n",
      "    result = pa.array(col, type=type_, from_pandas=True, safe=safe)\n",
      "  File \"pyarrow/array.pxi\", line 365, in pyarrow.lib.array\n",
      "  File \"pyarrow/array.pxi\", line 91, in pyarrow.lib._ndarray_to_array\n",
      "  File \"pyarrow/error.pxi\", line 92, in pyarrow.lib.check_status\n",
      "pyarrow.lib.ArrowInvalid: (\"Could not convert dtype('int64') with type numpy.dtypes.Int64DType: did not recognize Python value type when inferring an Arrow data type\", 'Conversion failed for column 0 with type object')\n",
      "2025-08-21 15:16:10.886 Serialization of dataframe to Arrow table was unsuccessful. Applying automatic fixes for column types to make the dataframe Arrow-compatible.\n",
      "Traceback (most recent call last):\n",
      "  File \"/Users/nayzawlin/Desktop/langara/ARC/PEH/PEH-cohort/pehenv/lib/python3.13/site-packages/streamlit/dataframe_util.py\", line 821, in convert_pandas_df_to_arrow_bytes\n",
      "    table = pa.Table.from_pandas(df)\n",
      "  File \"pyarrow/table.pxi\", line 4795, in pyarrow.lib.Table.from_pandas\n",
      "  File \"/Users/nayzawlin/Desktop/langara/ARC/PEH/PEH-cohort/pehenv/lib/python3.13/site-packages/pyarrow/pandas_compat.py\", line 637, in dataframe_to_arrays\n",
      "    arrays = [convert_column(c, f)\n",
      "              ~~~~~~~~~~~~~~^^^^^^\n",
      "  File \"/Users/nayzawlin/Desktop/langara/ARC/PEH/PEH-cohort/pehenv/lib/python3.13/site-packages/pyarrow/pandas_compat.py\", line 625, in convert_column\n",
      "    raise e\n",
      "  File \"/Users/nayzawlin/Desktop/langara/ARC/PEH/PEH-cohort/pehenv/lib/python3.13/site-packages/pyarrow/pandas_compat.py\", line 619, in convert_column\n",
      "    result = pa.array(col, type=type_, from_pandas=True, safe=safe)\n",
      "  File \"pyarrow/array.pxi\", line 365, in pyarrow.lib.array\n",
      "  File \"pyarrow/array.pxi\", line 91, in pyarrow.lib._ndarray_to_array\n",
      "  File \"pyarrow/error.pxi\", line 92, in pyarrow.lib.check_status\n",
      "pyarrow.lib.ArrowInvalid: (\"Could not convert dtype('int64') with type numpy.dtypes.Int64DType: did not recognize Python value type when inferring an Arrow data type\", 'Conversion failed for column 0 with type object')\n",
      "2025-08-21 15:16:11.690 Serialization of dataframe to Arrow table was unsuccessful. Applying automatic fixes for column types to make the dataframe Arrow-compatible.\n",
      "Traceback (most recent call last):\n",
      "  File \"/Users/nayzawlin/Desktop/langara/ARC/PEH/PEH-cohort/pehenv/lib/python3.13/site-packages/streamlit/dataframe_util.py\", line 821, in convert_pandas_df_to_arrow_bytes\n",
      "    table = pa.Table.from_pandas(df)\n",
      "  File \"pyarrow/table.pxi\", line 4795, in pyarrow.lib.Table.from_pandas\n",
      "  File \"/Users/nayzawlin/Desktop/langara/ARC/PEH/PEH-cohort/pehenv/lib/python3.13/site-packages/pyarrow/pandas_compat.py\", line 637, in dataframe_to_arrays\n",
      "    arrays = [convert_column(c, f)\n",
      "              ~~~~~~~~~~~~~~^^^^^^\n",
      "  File \"/Users/nayzawlin/Desktop/langara/ARC/PEH/PEH-cohort/pehenv/lib/python3.13/site-packages/pyarrow/pandas_compat.py\", line 625, in convert_column\n",
      "    raise e\n",
      "  File \"/Users/nayzawlin/Desktop/langara/ARC/PEH/PEH-cohort/pehenv/lib/python3.13/site-packages/pyarrow/pandas_compat.py\", line 619, in convert_column\n",
      "    result = pa.array(col, type=type_, from_pandas=True, safe=safe)\n",
      "  File \"pyarrow/array.pxi\", line 365, in pyarrow.lib.array\n",
      "  File \"pyarrow/array.pxi\", line 91, in pyarrow.lib._ndarray_to_array\n",
      "  File \"pyarrow/error.pxi\", line 92, in pyarrow.lib.check_status\n",
      "pyarrow.lib.ArrowInvalid: (\"Could not convert dtype('int64') with type numpy.dtypes.Int64DType: did not recognize Python value type when inferring an Arrow data type\", 'Conversion failed for column 0 with type object')\n",
      "2025-08-21 15:16:12.312 Serialization of dataframe to Arrow table was unsuccessful. Applying automatic fixes for column types to make the dataframe Arrow-compatible.\n",
      "Traceback (most recent call last):\n",
      "  File \"/Users/nayzawlin/Desktop/langara/ARC/PEH/PEH-cohort/pehenv/lib/python3.13/site-packages/streamlit/dataframe_util.py\", line 821, in convert_pandas_df_to_arrow_bytes\n",
      "    table = pa.Table.from_pandas(df)\n",
      "  File \"pyarrow/table.pxi\", line 4795, in pyarrow.lib.Table.from_pandas\n",
      "  File \"/Users/nayzawlin/Desktop/langara/ARC/PEH/PEH-cohort/pehenv/lib/python3.13/site-packages/pyarrow/pandas_compat.py\", line 637, in dataframe_to_arrays\n",
      "    arrays = [convert_column(c, f)\n",
      "              ~~~~~~~~~~~~~~^^^^^^\n",
      "  File \"/Users/nayzawlin/Desktop/langara/ARC/PEH/PEH-cohort/pehenv/lib/python3.13/site-packages/pyarrow/pandas_compat.py\", line 625, in convert_column\n",
      "    raise e\n",
      "  File \"/Users/nayzawlin/Desktop/langara/ARC/PEH/PEH-cohort/pehenv/lib/python3.13/site-packages/pyarrow/pandas_compat.py\", line 619, in convert_column\n",
      "    result = pa.array(col, type=type_, from_pandas=True, safe=safe)\n",
      "  File \"pyarrow/array.pxi\", line 365, in pyarrow.lib.array\n",
      "  File \"pyarrow/array.pxi\", line 91, in pyarrow.lib._ndarray_to_array\n",
      "  File \"pyarrow/error.pxi\", line 92, in pyarrow.lib.check_status\n",
      "pyarrow.lib.ArrowInvalid: (\"Could not convert dtype('int64') with type numpy.dtypes.Int64DType: did not recognize Python value type when inferring an Arrow data type\", 'Conversion failed for column 0 with type object')\n",
      "2025-08-21 15:16:24.604 Serialization of dataframe to Arrow table was unsuccessful. Applying automatic fixes for column types to make the dataframe Arrow-compatible.\n",
      "Traceback (most recent call last):\n",
      "  File \"/Users/nayzawlin/Desktop/langara/ARC/PEH/PEH-cohort/pehenv/lib/python3.13/site-packages/streamlit/dataframe_util.py\", line 821, in convert_pandas_df_to_arrow_bytes\n",
      "    table = pa.Table.from_pandas(df)\n",
      "  File \"pyarrow/table.pxi\", line 4795, in pyarrow.lib.Table.from_pandas\n",
      "  File \"/Users/nayzawlin/Desktop/langara/ARC/PEH/PEH-cohort/pehenv/lib/python3.13/site-packages/pyarrow/pandas_compat.py\", line 637, in dataframe_to_arrays\n",
      "    arrays = [convert_column(c, f)\n",
      "              ~~~~~~~~~~~~~~^^^^^^\n",
      "  File \"/Users/nayzawlin/Desktop/langara/ARC/PEH/PEH-cohort/pehenv/lib/python3.13/site-packages/pyarrow/pandas_compat.py\", line 625, in convert_column\n",
      "    raise e\n",
      "  File \"/Users/nayzawlin/Desktop/langara/ARC/PEH/PEH-cohort/pehenv/lib/python3.13/site-packages/pyarrow/pandas_compat.py\", line 619, in convert_column\n",
      "    result = pa.array(col, type=type_, from_pandas=True, safe=safe)\n",
      "  File \"pyarrow/array.pxi\", line 365, in pyarrow.lib.array\n",
      "  File \"pyarrow/array.pxi\", line 91, in pyarrow.lib._ndarray_to_array\n",
      "  File \"pyarrow/error.pxi\", line 92, in pyarrow.lib.check_status\n",
      "pyarrow.lib.ArrowInvalid: (\"Could not convert dtype('int64') with type numpy.dtypes.Int64DType: did not recognize Python value type when inferring an Arrow data type\", 'Conversion failed for column 0 with type object')\n",
      "2025-08-21 15:16:31.671 Serialization of dataframe to Arrow table was unsuccessful. Applying automatic fixes for column types to make the dataframe Arrow-compatible.\n",
      "Traceback (most recent call last):\n",
      "  File \"/Users/nayzawlin/Desktop/langara/ARC/PEH/PEH-cohort/pehenv/lib/python3.13/site-packages/streamlit/dataframe_util.py\", line 821, in convert_pandas_df_to_arrow_bytes\n",
      "    table = pa.Table.from_pandas(df)\n",
      "  File \"pyarrow/table.pxi\", line 4795, in pyarrow.lib.Table.from_pandas\n",
      "  File \"/Users/nayzawlin/Desktop/langara/ARC/PEH/PEH-cohort/pehenv/lib/python3.13/site-packages/pyarrow/pandas_compat.py\", line 637, in dataframe_to_arrays\n",
      "    arrays = [convert_column(c, f)\n",
      "              ~~~~~~~~~~~~~~^^^^^^\n",
      "  File \"/Users/nayzawlin/Desktop/langara/ARC/PEH/PEH-cohort/pehenv/lib/python3.13/site-packages/pyarrow/pandas_compat.py\", line 625, in convert_column\n",
      "    raise e\n",
      "  File \"/Users/nayzawlin/Desktop/langara/ARC/PEH/PEH-cohort/pehenv/lib/python3.13/site-packages/pyarrow/pandas_compat.py\", line 619, in convert_column\n",
      "    result = pa.array(col, type=type_, from_pandas=True, safe=safe)\n",
      "  File \"pyarrow/array.pxi\", line 365, in pyarrow.lib.array\n",
      "  File \"pyarrow/array.pxi\", line 91, in pyarrow.lib._ndarray_to_array\n",
      "  File \"pyarrow/error.pxi\", line 92, in pyarrow.lib.check_status\n",
      "pyarrow.lib.ArrowInvalid: (\"Could not convert dtype('int64') with type numpy.dtypes.Int64DType: did not recognize Python value type when inferring an Arrow data type\", 'Conversion failed for column 0 with type object')\n",
      "2025-08-21 15:16:34.971 Serialization of dataframe to Arrow table was unsuccessful. Applying automatic fixes for column types to make the dataframe Arrow-compatible.\n",
      "Traceback (most recent call last):\n",
      "  File \"/Users/nayzawlin/Desktop/langara/ARC/PEH/PEH-cohort/pehenv/lib/python3.13/site-packages/streamlit/dataframe_util.py\", line 821, in convert_pandas_df_to_arrow_bytes\n",
      "    table = pa.Table.from_pandas(df)\n",
      "  File \"pyarrow/table.pxi\", line 4795, in pyarrow.lib.Table.from_pandas\n",
      "  File \"/Users/nayzawlin/Desktop/langara/ARC/PEH/PEH-cohort/pehenv/lib/python3.13/site-packages/pyarrow/pandas_compat.py\", line 637, in dataframe_to_arrays\n",
      "    arrays = [convert_column(c, f)\n",
      "              ~~~~~~~~~~~~~~^^^^^^\n",
      "  File \"/Users/nayzawlin/Desktop/langara/ARC/PEH/PEH-cohort/pehenv/lib/python3.13/site-packages/pyarrow/pandas_compat.py\", line 625, in convert_column\n",
      "    raise e\n",
      "  File \"/Users/nayzawlin/Desktop/langara/ARC/PEH/PEH-cohort/pehenv/lib/python3.13/site-packages/pyarrow/pandas_compat.py\", line 619, in convert_column\n",
      "    result = pa.array(col, type=type_, from_pandas=True, safe=safe)\n",
      "  File \"pyarrow/array.pxi\", line 365, in pyarrow.lib.array\n",
      "  File \"pyarrow/array.pxi\", line 91, in pyarrow.lib._ndarray_to_array\n",
      "  File \"pyarrow/error.pxi\", line 92, in pyarrow.lib.check_status\n",
      "pyarrow.lib.ArrowInvalid: (\"Could not convert dtype('int64') with type numpy.dtypes.Int64DType: did not recognize Python value type when inferring an Arrow data type\", 'Conversion failed for column 0 with type object')\n",
      "2025-08-21 15:16:47.888 Serialization of dataframe to Arrow table was unsuccessful. Applying automatic fixes for column types to make the dataframe Arrow-compatible.\n",
      "Traceback (most recent call last):\n",
      "  File \"/Users/nayzawlin/Desktop/langara/ARC/PEH/PEH-cohort/pehenv/lib/python3.13/site-packages/streamlit/dataframe_util.py\", line 821, in convert_pandas_df_to_arrow_bytes\n",
      "    table = pa.Table.from_pandas(df)\n",
      "  File \"pyarrow/table.pxi\", line 4795, in pyarrow.lib.Table.from_pandas\n",
      "  File \"/Users/nayzawlin/Desktop/langara/ARC/PEH/PEH-cohort/pehenv/lib/python3.13/site-packages/pyarrow/pandas_compat.py\", line 637, in dataframe_to_arrays\n",
      "    arrays = [convert_column(c, f)\n",
      "              ~~~~~~~~~~~~~~^^^^^^\n",
      "  File \"/Users/nayzawlin/Desktop/langara/ARC/PEH/PEH-cohort/pehenv/lib/python3.13/site-packages/pyarrow/pandas_compat.py\", line 625, in convert_column\n",
      "    raise e\n",
      "  File \"/Users/nayzawlin/Desktop/langara/ARC/PEH/PEH-cohort/pehenv/lib/python3.13/site-packages/pyarrow/pandas_compat.py\", line 619, in convert_column\n",
      "    result = pa.array(col, type=type_, from_pandas=True, safe=safe)\n",
      "  File \"pyarrow/array.pxi\", line 365, in pyarrow.lib.array\n",
      "  File \"pyarrow/array.pxi\", line 91, in pyarrow.lib._ndarray_to_array\n",
      "  File \"pyarrow/error.pxi\", line 92, in pyarrow.lib.check_status\n",
      "pyarrow.lib.ArrowInvalid: (\"Could not convert dtype('int64') with type numpy.dtypes.Int64DType: did not recognize Python value type when inferring an Arrow data type\", 'Conversion failed for column 0 with type object')\n",
      "2025-08-21 15:16:56.024 Serialization of dataframe to Arrow table was unsuccessful. Applying automatic fixes for column types to make the dataframe Arrow-compatible.\n",
      "Traceback (most recent call last):\n",
      "  File \"/Users/nayzawlin/Desktop/langara/ARC/PEH/PEH-cohort/pehenv/lib/python3.13/site-packages/streamlit/dataframe_util.py\", line 821, in convert_pandas_df_to_arrow_bytes\n",
      "    table = pa.Table.from_pandas(df)\n",
      "  File \"pyarrow/table.pxi\", line 4795, in pyarrow.lib.Table.from_pandas\n",
      "  File \"/Users/nayzawlin/Desktop/langara/ARC/PEH/PEH-cohort/pehenv/lib/python3.13/site-packages/pyarrow/pandas_compat.py\", line 637, in dataframe_to_arrays\n",
      "    arrays = [convert_column(c, f)\n",
      "              ~~~~~~~~~~~~~~^^^^^^\n",
      "  File \"/Users/nayzawlin/Desktop/langara/ARC/PEH/PEH-cohort/pehenv/lib/python3.13/site-packages/pyarrow/pandas_compat.py\", line 625, in convert_column\n",
      "    raise e\n",
      "  File \"/Users/nayzawlin/Desktop/langara/ARC/PEH/PEH-cohort/pehenv/lib/python3.13/site-packages/pyarrow/pandas_compat.py\", line 619, in convert_column\n",
      "    result = pa.array(col, type=type_, from_pandas=True, safe=safe)\n",
      "  File \"pyarrow/array.pxi\", line 365, in pyarrow.lib.array\n",
      "  File \"pyarrow/array.pxi\", line 91, in pyarrow.lib._ndarray_to_array\n",
      "  File \"pyarrow/error.pxi\", line 92, in pyarrow.lib.check_status\n",
      "pyarrow.lib.ArrowInvalid: (\"Could not convert dtype('int64') with type numpy.dtypes.Int64DType: did not recognize Python value type when inferring an Arrow data type\", 'Conversion failed for column 0 with type object')\n",
      "2025-08-21 15:17:09.860 Serialization of dataframe to Arrow table was unsuccessful. Applying automatic fixes for column types to make the dataframe Arrow-compatible.\n",
      "Traceback (most recent call last):\n",
      "  File \"/Users/nayzawlin/Desktop/langara/ARC/PEH/PEH-cohort/pehenv/lib/python3.13/site-packages/streamlit/dataframe_util.py\", line 821, in convert_pandas_df_to_arrow_bytes\n",
      "    table = pa.Table.from_pandas(df)\n",
      "  File \"pyarrow/table.pxi\", line 4795, in pyarrow.lib.Table.from_pandas\n",
      "  File \"/Users/nayzawlin/Desktop/langara/ARC/PEH/PEH-cohort/pehenv/lib/python3.13/site-packages/pyarrow/pandas_compat.py\", line 637, in dataframe_to_arrays\n",
      "    arrays = [convert_column(c, f)\n",
      "              ~~~~~~~~~~~~~~^^^^^^\n",
      "  File \"/Users/nayzawlin/Desktop/langara/ARC/PEH/PEH-cohort/pehenv/lib/python3.13/site-packages/pyarrow/pandas_compat.py\", line 625, in convert_column\n",
      "    raise e\n",
      "  File \"/Users/nayzawlin/Desktop/langara/ARC/PEH/PEH-cohort/pehenv/lib/python3.13/site-packages/pyarrow/pandas_compat.py\", line 619, in convert_column\n",
      "    result = pa.array(col, type=type_, from_pandas=True, safe=safe)\n",
      "  File \"pyarrow/array.pxi\", line 365, in pyarrow.lib.array\n",
      "  File \"pyarrow/array.pxi\", line 91, in pyarrow.lib._ndarray_to_array\n",
      "  File \"pyarrow/error.pxi\", line 92, in pyarrow.lib.check_status\n",
      "pyarrow.lib.ArrowInvalid: (\"Could not convert dtype('int64') with type numpy.dtypes.Int64DType: did not recognize Python value type when inferring an Arrow data type\", 'Conversion failed for column 0 with type object')\n",
      "2025-08-21 15:17:12.508 Serialization of dataframe to Arrow table was unsuccessful. Applying automatic fixes for column types to make the dataframe Arrow-compatible.\n",
      "Traceback (most recent call last):\n",
      "  File \"/Users/nayzawlin/Desktop/langara/ARC/PEH/PEH-cohort/pehenv/lib/python3.13/site-packages/streamlit/dataframe_util.py\", line 821, in convert_pandas_df_to_arrow_bytes\n",
      "    table = pa.Table.from_pandas(df)\n",
      "  File \"pyarrow/table.pxi\", line 4795, in pyarrow.lib.Table.from_pandas\n",
      "  File \"/Users/nayzawlin/Desktop/langara/ARC/PEH/PEH-cohort/pehenv/lib/python3.13/site-packages/pyarrow/pandas_compat.py\", line 637, in dataframe_to_arrays\n",
      "    arrays = [convert_column(c, f)\n",
      "              ~~~~~~~~~~~~~~^^^^^^\n",
      "  File \"/Users/nayzawlin/Desktop/langara/ARC/PEH/PEH-cohort/pehenv/lib/python3.13/site-packages/pyarrow/pandas_compat.py\", line 625, in convert_column\n",
      "    raise e\n",
      "  File \"/Users/nayzawlin/Desktop/langara/ARC/PEH/PEH-cohort/pehenv/lib/python3.13/site-packages/pyarrow/pandas_compat.py\", line 619, in convert_column\n",
      "    result = pa.array(col, type=type_, from_pandas=True, safe=safe)\n",
      "  File \"pyarrow/array.pxi\", line 365, in pyarrow.lib.array\n",
      "  File \"pyarrow/array.pxi\", line 91, in pyarrow.lib._ndarray_to_array\n",
      "  File \"pyarrow/error.pxi\", line 92, in pyarrow.lib.check_status\n",
      "pyarrow.lib.ArrowInvalid: (\"Could not convert dtype('int64') with type numpy.dtypes.Int64DType: did not recognize Python value type when inferring an Arrow data type\", 'Conversion failed for column 0 with type object')\n",
      "2025-08-21 15:17:13.328 Serialization of dataframe to Arrow table was unsuccessful. Applying automatic fixes for column types to make the dataframe Arrow-compatible.\n",
      "Traceback (most recent call last):\n",
      "  File \"/Users/nayzawlin/Desktop/langara/ARC/PEH/PEH-cohort/pehenv/lib/python3.13/site-packages/streamlit/dataframe_util.py\", line 821, in convert_pandas_df_to_arrow_bytes\n",
      "    table = pa.Table.from_pandas(df)\n",
      "  File \"pyarrow/table.pxi\", line 4795, in pyarrow.lib.Table.from_pandas\n",
      "  File \"/Users/nayzawlin/Desktop/langara/ARC/PEH/PEH-cohort/pehenv/lib/python3.13/site-packages/pyarrow/pandas_compat.py\", line 637, in dataframe_to_arrays\n",
      "    arrays = [convert_column(c, f)\n",
      "              ~~~~~~~~~~~~~~^^^^^^\n",
      "  File \"/Users/nayzawlin/Desktop/langara/ARC/PEH/PEH-cohort/pehenv/lib/python3.13/site-packages/pyarrow/pandas_compat.py\", line 625, in convert_column\n",
      "    raise e\n",
      "  File \"/Users/nayzawlin/Desktop/langara/ARC/PEH/PEH-cohort/pehenv/lib/python3.13/site-packages/pyarrow/pandas_compat.py\", line 619, in convert_column\n",
      "    result = pa.array(col, type=type_, from_pandas=True, safe=safe)\n",
      "  File \"pyarrow/array.pxi\", line 365, in pyarrow.lib.array\n",
      "  File \"pyarrow/array.pxi\", line 91, in pyarrow.lib._ndarray_to_array\n",
      "  File \"pyarrow/error.pxi\", line 92, in pyarrow.lib.check_status\n",
      "pyarrow.lib.ArrowInvalid: (\"Could not convert dtype('int64') with type numpy.dtypes.Int64DType: did not recognize Python value type when inferring an Arrow data type\", 'Conversion failed for column 0 with type object')\n",
      "2025-08-21 15:17:26.945 Serialization of dataframe to Arrow table was unsuccessful. Applying automatic fixes for column types to make the dataframe Arrow-compatible.\n",
      "Traceback (most recent call last):\n",
      "  File \"/Users/nayzawlin/Desktop/langara/ARC/PEH/PEH-cohort/pehenv/lib/python3.13/site-packages/streamlit/dataframe_util.py\", line 821, in convert_pandas_df_to_arrow_bytes\n",
      "    table = pa.Table.from_pandas(df)\n",
      "  File \"pyarrow/table.pxi\", line 4795, in pyarrow.lib.Table.from_pandas\n",
      "  File \"/Users/nayzawlin/Desktop/langara/ARC/PEH/PEH-cohort/pehenv/lib/python3.13/site-packages/pyarrow/pandas_compat.py\", line 637, in dataframe_to_arrays\n",
      "    arrays = [convert_column(c, f)\n",
      "              ~~~~~~~~~~~~~~^^^^^^\n",
      "  File \"/Users/nayzawlin/Desktop/langara/ARC/PEH/PEH-cohort/pehenv/lib/python3.13/site-packages/pyarrow/pandas_compat.py\", line 625, in convert_column\n",
      "    raise e\n",
      "  File \"/Users/nayzawlin/Desktop/langara/ARC/PEH/PEH-cohort/pehenv/lib/python3.13/site-packages/pyarrow/pandas_compat.py\", line 619, in convert_column\n",
      "    result = pa.array(col, type=type_, from_pandas=True, safe=safe)\n",
      "  File \"pyarrow/array.pxi\", line 365, in pyarrow.lib.array\n",
      "  File \"pyarrow/array.pxi\", line 91, in pyarrow.lib._ndarray_to_array\n",
      "  File \"pyarrow/error.pxi\", line 92, in pyarrow.lib.check_status\n",
      "pyarrow.lib.ArrowInvalid: (\"Could not convert dtype('int64') with type numpy.dtypes.Int64DType: did not recognize Python value type when inferring an Arrow data type\", 'Conversion failed for column 0 with type object')\n",
      "2025-08-21 15:17:30.927 Serialization of dataframe to Arrow table was unsuccessful. Applying automatic fixes for column types to make the dataframe Arrow-compatible.\n",
      "Traceback (most recent call last):\n",
      "  File \"/Users/nayzawlin/Desktop/langara/ARC/PEH/PEH-cohort/pehenv/lib/python3.13/site-packages/streamlit/dataframe_util.py\", line 821, in convert_pandas_df_to_arrow_bytes\n",
      "    table = pa.Table.from_pandas(df)\n",
      "  File \"pyarrow/table.pxi\", line 4795, in pyarrow.lib.Table.from_pandas\n",
      "  File \"/Users/nayzawlin/Desktop/langara/ARC/PEH/PEH-cohort/pehenv/lib/python3.13/site-packages/pyarrow/pandas_compat.py\", line 637, in dataframe_to_arrays\n",
      "    arrays = [convert_column(c, f)\n",
      "              ~~~~~~~~~~~~~~^^^^^^\n",
      "  File \"/Users/nayzawlin/Desktop/langara/ARC/PEH/PEH-cohort/pehenv/lib/python3.13/site-packages/pyarrow/pandas_compat.py\", line 625, in convert_column\n",
      "    raise e\n",
      "  File \"/Users/nayzawlin/Desktop/langara/ARC/PEH/PEH-cohort/pehenv/lib/python3.13/site-packages/pyarrow/pandas_compat.py\", line 619, in convert_column\n",
      "    result = pa.array(col, type=type_, from_pandas=True, safe=safe)\n",
      "  File \"pyarrow/array.pxi\", line 365, in pyarrow.lib.array\n",
      "  File \"pyarrow/array.pxi\", line 91, in pyarrow.lib._ndarray_to_array\n",
      "  File \"pyarrow/error.pxi\", line 92, in pyarrow.lib.check_status\n",
      "pyarrow.lib.ArrowInvalid: (\"Could not convert dtype('int64') with type numpy.dtypes.Int64DType: did not recognize Python value type when inferring an Arrow data type\", 'Conversion failed for column 0 with type object')\n",
      "2025-08-21 15:17:33.538 Serialization of dataframe to Arrow table was unsuccessful. Applying automatic fixes for column types to make the dataframe Arrow-compatible.\n",
      "Traceback (most recent call last):\n",
      "  File \"/Users/nayzawlin/Desktop/langara/ARC/PEH/PEH-cohort/pehenv/lib/python3.13/site-packages/streamlit/dataframe_util.py\", line 821, in convert_pandas_df_to_arrow_bytes\n",
      "    table = pa.Table.from_pandas(df)\n",
      "  File \"pyarrow/table.pxi\", line 4795, in pyarrow.lib.Table.from_pandas\n",
      "  File \"/Users/nayzawlin/Desktop/langara/ARC/PEH/PEH-cohort/pehenv/lib/python3.13/site-packages/pyarrow/pandas_compat.py\", line 637, in dataframe_to_arrays\n",
      "    arrays = [convert_column(c, f)\n",
      "              ~~~~~~~~~~~~~~^^^^^^\n",
      "  File \"/Users/nayzawlin/Desktop/langara/ARC/PEH/PEH-cohort/pehenv/lib/python3.13/site-packages/pyarrow/pandas_compat.py\", line 625, in convert_column\n",
      "    raise e\n",
      "  File \"/Users/nayzawlin/Desktop/langara/ARC/PEH/PEH-cohort/pehenv/lib/python3.13/site-packages/pyarrow/pandas_compat.py\", line 619, in convert_column\n",
      "    result = pa.array(col, type=type_, from_pandas=True, safe=safe)\n",
      "  File \"pyarrow/array.pxi\", line 365, in pyarrow.lib.array\n",
      "  File \"pyarrow/array.pxi\", line 91, in pyarrow.lib._ndarray_to_array\n",
      "  File \"pyarrow/error.pxi\", line 92, in pyarrow.lib.check_status\n",
      "pyarrow.lib.ArrowInvalid: (\"Could not convert dtype('int64') with type numpy.dtypes.Int64DType: did not recognize Python value type when inferring an Arrow data type\", 'Conversion failed for column 0 with type object')\n",
      "2025-08-21 15:17:37.697 Serialization of dataframe to Arrow table was unsuccessful. Applying automatic fixes for column types to make the dataframe Arrow-compatible.\n",
      "Traceback (most recent call last):\n",
      "  File \"/Users/nayzawlin/Desktop/langara/ARC/PEH/PEH-cohort/pehenv/lib/python3.13/site-packages/streamlit/dataframe_util.py\", line 821, in convert_pandas_df_to_arrow_bytes\n",
      "    table = pa.Table.from_pandas(df)\n",
      "  File \"pyarrow/table.pxi\", line 4795, in pyarrow.lib.Table.from_pandas\n",
      "  File \"/Users/nayzawlin/Desktop/langara/ARC/PEH/PEH-cohort/pehenv/lib/python3.13/site-packages/pyarrow/pandas_compat.py\", line 637, in dataframe_to_arrays\n",
      "    arrays = [convert_column(c, f)\n",
      "              ~~~~~~~~~~~~~~^^^^^^\n",
      "  File \"/Users/nayzawlin/Desktop/langara/ARC/PEH/PEH-cohort/pehenv/lib/python3.13/site-packages/pyarrow/pandas_compat.py\", line 625, in convert_column\n",
      "    raise e\n",
      "  File \"/Users/nayzawlin/Desktop/langara/ARC/PEH/PEH-cohort/pehenv/lib/python3.13/site-packages/pyarrow/pandas_compat.py\", line 619, in convert_column\n",
      "    result = pa.array(col, type=type_, from_pandas=True, safe=safe)\n",
      "  File \"pyarrow/array.pxi\", line 365, in pyarrow.lib.array\n",
      "  File \"pyarrow/array.pxi\", line 91, in pyarrow.lib._ndarray_to_array\n",
      "  File \"pyarrow/error.pxi\", line 92, in pyarrow.lib.check_status\n",
      "pyarrow.lib.ArrowInvalid: (\"Could not convert dtype('int64') with type numpy.dtypes.Int64DType: did not recognize Python value type when inferring an Arrow data type\", 'Conversion failed for column 0 with type object')\n",
      "2025-08-21 15:18:07.956 Serialization of dataframe to Arrow table was unsuccessful. Applying automatic fixes for column types to make the dataframe Arrow-compatible.\n",
      "Traceback (most recent call last):\n",
      "  File \"/Users/nayzawlin/Desktop/langara/ARC/PEH/PEH-cohort/pehenv/lib/python3.13/site-packages/streamlit/dataframe_util.py\", line 821, in convert_pandas_df_to_arrow_bytes\n",
      "    table = pa.Table.from_pandas(df)\n",
      "  File \"pyarrow/table.pxi\", line 4795, in pyarrow.lib.Table.from_pandas\n",
      "  File \"/Users/nayzawlin/Desktop/langara/ARC/PEH/PEH-cohort/pehenv/lib/python3.13/site-packages/pyarrow/pandas_compat.py\", line 637, in dataframe_to_arrays\n",
      "    arrays = [convert_column(c, f)\n",
      "              ~~~~~~~~~~~~~~^^^^^^\n",
      "  File \"/Users/nayzawlin/Desktop/langara/ARC/PEH/PEH-cohort/pehenv/lib/python3.13/site-packages/pyarrow/pandas_compat.py\", line 625, in convert_column\n",
      "    raise e\n",
      "  File \"/Users/nayzawlin/Desktop/langara/ARC/PEH/PEH-cohort/pehenv/lib/python3.13/site-packages/pyarrow/pandas_compat.py\", line 619, in convert_column\n",
      "    result = pa.array(col, type=type_, from_pandas=True, safe=safe)\n",
      "  File \"pyarrow/array.pxi\", line 365, in pyarrow.lib.array\n",
      "  File \"pyarrow/array.pxi\", line 91, in pyarrow.lib._ndarray_to_array\n",
      "  File \"pyarrow/error.pxi\", line 92, in pyarrow.lib.check_status\n",
      "pyarrow.lib.ArrowInvalid: (\"Could not convert dtype('int64') with type numpy.dtypes.Int64DType: did not recognize Python value type when inferring an Arrow data type\", 'Conversion failed for column 0 with type object')\n",
      "2025-08-21 15:18:11.628 Serialization of dataframe to Arrow table was unsuccessful. Applying automatic fixes for column types to make the dataframe Arrow-compatible.\n",
      "Traceback (most recent call last):\n",
      "  File \"/Users/nayzawlin/Desktop/langara/ARC/PEH/PEH-cohort/pehenv/lib/python3.13/site-packages/streamlit/dataframe_util.py\", line 821, in convert_pandas_df_to_arrow_bytes\n",
      "    table = pa.Table.from_pandas(df)\n",
      "  File \"pyarrow/table.pxi\", line 4795, in pyarrow.lib.Table.from_pandas\n",
      "  File \"/Users/nayzawlin/Desktop/langara/ARC/PEH/PEH-cohort/pehenv/lib/python3.13/site-packages/pyarrow/pandas_compat.py\", line 637, in dataframe_to_arrays\n",
      "    arrays = [convert_column(c, f)\n",
      "              ~~~~~~~~~~~~~~^^^^^^\n",
      "  File \"/Users/nayzawlin/Desktop/langara/ARC/PEH/PEH-cohort/pehenv/lib/python3.13/site-packages/pyarrow/pandas_compat.py\", line 625, in convert_column\n",
      "    raise e\n",
      "  File \"/Users/nayzawlin/Desktop/langara/ARC/PEH/PEH-cohort/pehenv/lib/python3.13/site-packages/pyarrow/pandas_compat.py\", line 619, in convert_column\n",
      "    result = pa.array(col, type=type_, from_pandas=True, safe=safe)\n",
      "  File \"pyarrow/array.pxi\", line 365, in pyarrow.lib.array\n",
      "  File \"pyarrow/array.pxi\", line 91, in pyarrow.lib._ndarray_to_array\n",
      "  File \"pyarrow/error.pxi\", line 92, in pyarrow.lib.check_status\n",
      "pyarrow.lib.ArrowInvalid: (\"Could not convert dtype('int64') with type numpy.dtypes.Int64DType: did not recognize Python value type when inferring an Arrow data type\", 'Conversion failed for column 0 with type object')\n",
      "2025-08-21 15:18:12.705 Serialization of dataframe to Arrow table was unsuccessful. Applying automatic fixes for column types to make the dataframe Arrow-compatible.\n",
      "Traceback (most recent call last):\n",
      "  File \"/Users/nayzawlin/Desktop/langara/ARC/PEH/PEH-cohort/pehenv/lib/python3.13/site-packages/streamlit/dataframe_util.py\", line 821, in convert_pandas_df_to_arrow_bytes\n",
      "    table = pa.Table.from_pandas(df)\n",
      "  File \"pyarrow/table.pxi\", line 4795, in pyarrow.lib.Table.from_pandas\n",
      "  File \"/Users/nayzawlin/Desktop/langara/ARC/PEH/PEH-cohort/pehenv/lib/python3.13/site-packages/pyarrow/pandas_compat.py\", line 637, in dataframe_to_arrays\n",
      "    arrays = [convert_column(c, f)\n",
      "              ~~~~~~~~~~~~~~^^^^^^\n",
      "  File \"/Users/nayzawlin/Desktop/langara/ARC/PEH/PEH-cohort/pehenv/lib/python3.13/site-packages/pyarrow/pandas_compat.py\", line 625, in convert_column\n",
      "    raise e\n",
      "  File \"/Users/nayzawlin/Desktop/langara/ARC/PEH/PEH-cohort/pehenv/lib/python3.13/site-packages/pyarrow/pandas_compat.py\", line 619, in convert_column\n",
      "    result = pa.array(col, type=type_, from_pandas=True, safe=safe)\n",
      "  File \"pyarrow/array.pxi\", line 365, in pyarrow.lib.array\n",
      "  File \"pyarrow/array.pxi\", line 91, in pyarrow.lib._ndarray_to_array\n",
      "  File \"pyarrow/error.pxi\", line 92, in pyarrow.lib.check_status\n",
      "pyarrow.lib.ArrowInvalid: (\"Could not convert dtype('bool') with type numpy.dtypes.BoolDType: did not recognize Python value type when inferring an Arrow data type\", 'Conversion failed for column 0 with type object')\n",
      "2025-08-21 15:21:14.139 Serialization of dataframe to Arrow table was unsuccessful. Applying automatic fixes for column types to make the dataframe Arrow-compatible.\n",
      "Traceback (most recent call last):\n",
      "  File \"/Users/nayzawlin/Desktop/langara/ARC/PEH/PEH-cohort/pehenv/lib/python3.13/site-packages/streamlit/dataframe_util.py\", line 821, in convert_pandas_df_to_arrow_bytes\n",
      "    table = pa.Table.from_pandas(df)\n",
      "  File \"pyarrow/table.pxi\", line 4795, in pyarrow.lib.Table.from_pandas\n",
      "  File \"/Users/nayzawlin/Desktop/langara/ARC/PEH/PEH-cohort/pehenv/lib/python3.13/site-packages/pyarrow/pandas_compat.py\", line 637, in dataframe_to_arrays\n",
      "    arrays = [convert_column(c, f)\n",
      "              ~~~~~~~~~~~~~~^^^^^^\n",
      "  File \"/Users/nayzawlin/Desktop/langara/ARC/PEH/PEH-cohort/pehenv/lib/python3.13/site-packages/pyarrow/pandas_compat.py\", line 625, in convert_column\n",
      "    raise e\n",
      "  File \"/Users/nayzawlin/Desktop/langara/ARC/PEH/PEH-cohort/pehenv/lib/python3.13/site-packages/pyarrow/pandas_compat.py\", line 619, in convert_column\n",
      "    result = pa.array(col, type=type_, from_pandas=True, safe=safe)\n",
      "  File \"pyarrow/array.pxi\", line 365, in pyarrow.lib.array\n",
      "  File \"pyarrow/array.pxi\", line 91, in pyarrow.lib._ndarray_to_array\n",
      "  File \"pyarrow/error.pxi\", line 92, in pyarrow.lib.check_status\n",
      "pyarrow.lib.ArrowInvalid: (\"Could not convert dtype('O') with type numpy.dtypes.ObjectDType: did not recognize Python value type when inferring an Arrow data type\", 'Conversion failed for column 0 with type object')\n",
      "2025-08-21 15:21:27.691 Serialization of dataframe to Arrow table was unsuccessful. Applying automatic fixes for column types to make the dataframe Arrow-compatible.\n",
      "Traceback (most recent call last):\n",
      "  File \"/Users/nayzawlin/Desktop/langara/ARC/PEH/PEH-cohort/pehenv/lib/python3.13/site-packages/streamlit/dataframe_util.py\", line 821, in convert_pandas_df_to_arrow_bytes\n",
      "    table = pa.Table.from_pandas(df)\n",
      "  File \"pyarrow/table.pxi\", line 4795, in pyarrow.lib.Table.from_pandas\n",
      "  File \"/Users/nayzawlin/Desktop/langara/ARC/PEH/PEH-cohort/pehenv/lib/python3.13/site-packages/pyarrow/pandas_compat.py\", line 637, in dataframe_to_arrays\n",
      "    arrays = [convert_column(c, f)\n",
      "              ~~~~~~~~~~~~~~^^^^^^\n",
      "  File \"/Users/nayzawlin/Desktop/langara/ARC/PEH/PEH-cohort/pehenv/lib/python3.13/site-packages/pyarrow/pandas_compat.py\", line 625, in convert_column\n",
      "    raise e\n",
      "  File \"/Users/nayzawlin/Desktop/langara/ARC/PEH/PEH-cohort/pehenv/lib/python3.13/site-packages/pyarrow/pandas_compat.py\", line 619, in convert_column\n",
      "    result = pa.array(col, type=type_, from_pandas=True, safe=safe)\n",
      "  File \"pyarrow/array.pxi\", line 365, in pyarrow.lib.array\n",
      "  File \"pyarrow/array.pxi\", line 91, in pyarrow.lib._ndarray_to_array\n",
      "  File \"pyarrow/error.pxi\", line 92, in pyarrow.lib.check_status\n",
      "pyarrow.lib.ArrowInvalid: (\"Could not convert dtype('O') with type numpy.dtypes.ObjectDType: did not recognize Python value type when inferring an Arrow data type\", 'Conversion failed for column 0 with type object')\n",
      "2025-08-21 15:21:32.241 Serialization of dataframe to Arrow table was unsuccessful. Applying automatic fixes for column types to make the dataframe Arrow-compatible.\n",
      "Traceback (most recent call last):\n",
      "  File \"/Users/nayzawlin/Desktop/langara/ARC/PEH/PEH-cohort/pehenv/lib/python3.13/site-packages/streamlit/dataframe_util.py\", line 821, in convert_pandas_df_to_arrow_bytes\n",
      "    table = pa.Table.from_pandas(df)\n",
      "  File \"pyarrow/table.pxi\", line 4795, in pyarrow.lib.Table.from_pandas\n",
      "  File \"/Users/nayzawlin/Desktop/langara/ARC/PEH/PEH-cohort/pehenv/lib/python3.13/site-packages/pyarrow/pandas_compat.py\", line 637, in dataframe_to_arrays\n",
      "    arrays = [convert_column(c, f)\n",
      "              ~~~~~~~~~~~~~~^^^^^^\n",
      "  File \"/Users/nayzawlin/Desktop/langara/ARC/PEH/PEH-cohort/pehenv/lib/python3.13/site-packages/pyarrow/pandas_compat.py\", line 625, in convert_column\n",
      "    raise e\n",
      "  File \"/Users/nayzawlin/Desktop/langara/ARC/PEH/PEH-cohort/pehenv/lib/python3.13/site-packages/pyarrow/pandas_compat.py\", line 619, in convert_column\n",
      "    result = pa.array(col, type=type_, from_pandas=True, safe=safe)\n",
      "  File \"pyarrow/array.pxi\", line 365, in pyarrow.lib.array\n",
      "  File \"pyarrow/array.pxi\", line 91, in pyarrow.lib._ndarray_to_array\n",
      "  File \"pyarrow/error.pxi\", line 92, in pyarrow.lib.check_status\n",
      "pyarrow.lib.ArrowInvalid: (\"Could not convert dtype('O') with type numpy.dtypes.ObjectDType: did not recognize Python value type when inferring an Arrow data type\", 'Conversion failed for column 0 with type object')\n",
      "2025-08-21 15:21:51.940 Serialization of dataframe to Arrow table was unsuccessful. Applying automatic fixes for column types to make the dataframe Arrow-compatible.\n",
      "Traceback (most recent call last):\n",
      "  File \"/Users/nayzawlin/Desktop/langara/ARC/PEH/PEH-cohort/pehenv/lib/python3.13/site-packages/streamlit/dataframe_util.py\", line 821, in convert_pandas_df_to_arrow_bytes\n",
      "    table = pa.Table.from_pandas(df)\n",
      "  File \"pyarrow/table.pxi\", line 4795, in pyarrow.lib.Table.from_pandas\n",
      "  File \"/Users/nayzawlin/Desktop/langara/ARC/PEH/PEH-cohort/pehenv/lib/python3.13/site-packages/pyarrow/pandas_compat.py\", line 637, in dataframe_to_arrays\n",
      "    arrays = [convert_column(c, f)\n",
      "              ~~~~~~~~~~~~~~^^^^^^\n",
      "  File \"/Users/nayzawlin/Desktop/langara/ARC/PEH/PEH-cohort/pehenv/lib/python3.13/site-packages/pyarrow/pandas_compat.py\", line 625, in convert_column\n",
      "    raise e\n",
      "  File \"/Users/nayzawlin/Desktop/langara/ARC/PEH/PEH-cohort/pehenv/lib/python3.13/site-packages/pyarrow/pandas_compat.py\", line 619, in convert_column\n",
      "    result = pa.array(col, type=type_, from_pandas=True, safe=safe)\n",
      "  File \"pyarrow/array.pxi\", line 365, in pyarrow.lib.array\n",
      "  File \"pyarrow/array.pxi\", line 91, in pyarrow.lib._ndarray_to_array\n",
      "  File \"pyarrow/error.pxi\", line 92, in pyarrow.lib.check_status\n",
      "pyarrow.lib.ArrowInvalid: (\"Could not convert dtype('O') with type numpy.dtypes.ObjectDType: did not recognize Python value type when inferring an Arrow data type\", 'Conversion failed for column 0 with type object')\n",
      "/Users/nayzawlin/.npm/_npx/75ac80b86e83d4a2/node_modules/localtunnel/bin/lt.js:81\n",
      "    throw err;\n",
      "    ^\n",
      "\n",
      "Error: connection refused: localtunnel.me:31009 (check your firewall settings)\n",
      "    at Socket.<anonymous> (/Users/nayzawlin/.npm/_npx/75ac80b86e83d4a2/node_modules/\u001b[4mlocaltunnel\u001b[24m/lib/TunnelCluster.js:52:11)\n",
      "\u001b[90m    at Socket.emit (node:events:507:28)\u001b[39m\n",
      "\u001b[90m    at emitErrorNT (node:internal/streams/destroy:170:8)\u001b[39m\n",
      "\u001b[90m    at emitErrorCloseNT (node:internal/streams/destroy:129:3)\u001b[39m\n",
      "\u001b[90m    at process.processTicksAndRejections (node:internal/process/task_queues:90:21)\u001b[39m\n",
      "\n",
      "Node.js v24.3.0\n",
      "\u001b[1G\u001b[0K⠙\u001b[1G\u001b[0K"
     ]
    }
   ],
   "source": [
    "!streamlit run bc_addresses_analysis.py & npx localtunnel --port 8502"
   ]
  }
 ],
 "metadata": {
  "kernelspec": {
   "display_name": "pehenv",
   "language": "python",
   "name": "python3"
  },
  "language_info": {
   "codemirror_mode": {
    "name": "ipython",
    "version": 3
   },
   "file_extension": ".py",
   "mimetype": "text/x-python",
   "name": "python",
   "nbconvert_exporter": "python",
   "pygments_lexer": "ipython3",
   "version": "3.13.3"
  }
 },
 "nbformat": 4,
 "nbformat_minor": 5
}
